Workbook

Sheet Dashboard
I3: C&A ($CEAB3)
A7: Páginas
A8: Dashboard
A9: WACC | E9: Ticker | F9: CEAB3 | H9: WACC | I9: =I10-0.5% -> 0.15529878 | J9: =(NPV($I9,'DRE + DCF'!$M$47,'DRE + DCF'!$O$47:$T$47)+('DRE + DCF'!$U$47*(1+J$18)/(($I9-J$18)*(1+$I9)^COUNT('DRE + DCF'!$N$36:$T$36)))+SUM($F$13:$F$14)-$F$12)/$F$10 -> 4.9404396 | K9: =(NPV($I9,'DRE + DCF'!$M$47,'DRE + DCF'!$O$47:$T$47)+('DRE + DCF'!$U$47*(1+K$18)/(($I9-K$18)*(1+$I9)^COUNT('DRE + DCF'!$N$36:$T$36)))+SUM($F$13:$F$14)-$F$12)/$F$10 -> 5.2433816 | L9: =(NPV($I9,'DRE + DCF'!$M$47,'DRE + DCF'!$O$47:$T$47)+('DRE + DCF'!$U$47*(1+L$18)/(($I9-L$18)*(1+$I9)^COUNT('DRE + DCF'!$N$36:$T$36)))+SUM($F$13:$F$14)-$F$12)/$F$10 -> 5.5651869 | M9: =(NPV($I9,'DRE + DCF'!$M$47,'DRE + DCF'!$O$47:$T$47)+('DRE + DCF'!$U$47*(1+M$18)/(($I9-M$18)*(1+$I9)^COUNT('DRE + DCF'!$N$36:$T$36)))+SUM($F$13:$F$14)-$F$12)/$F$10 -> 5.9076741 | N9: =(NPV($I9,'DRE + DCF'!$M$47,'DRE + DCF'!$O$47:$T$47)+('DRE + DCF'!$U$47*(1+N$18)/(($I9-N$18)*(1+$I9)^COUNT('DRE + DCF'!$N$36:$T$36)))+SUM($F$13:$F$14)-$F$12)/$F$10 -> 6.2729032 | O9: =(NPV($I9,'DRE + DCF'!$M$47,'DRE + DCF'!$O$47:$T$47)+('DRE + DCF'!$U$47*(1+O$18)/(($I9-O$18)*(1+$I9)^COUNT('DRE + DCF'!$N$36:$T$36)))+SUM($F$13:$F$14)-$F$12)/$F$10 -> 6.6632172 | P9: =(NPV($I9,'DRE + DCF'!$M$47,'DRE + DCF'!$O$47:$T$47)+('DRE + DCF'!$U$47*(1+P$18)/(($I9-P$18)*(1+$I9)^COUNT('DRE + DCF'!$N$36:$T$36)))+SUM($F$13:$F$14)-$F$12)/$F$10 -> 7.0812922 | Q9: =(NPV($I9,'DRE + DCF'!$M$47,'DRE + DCF'!$O$47:$T$47)+('DRE + DCF'!$U$47*(1+Q$18)/(($I9-Q$18)*(1+$I9)^COUNT('DRE + DCF'!$N$36:$T$36)))+SUM($F$13:$F$14)-$F$12)/$F$10 -> 7.5301993 | ... S9: =(NPV($I9,'DRE + DCF'!$M$47,'DRE + DCF'!$O$47:$T$47)+('DRE + DCF'!$U$47*(1+S$18)/(($I9-S$18)*(1+$I9)^COUNT('DRE + DCF'!$N$36:$T$36)))+SUM($F$13:$F$14)-$F$12)/$F$10 -> 8.5352386
A10: DRE + DCF | E10: Ações Emitidas (mil) | F10: 308245.07 | I10: =I11-0.5% -> 0.16029878 | J10: =(NPV($I10,'DRE + DCF'!$M$47,'DRE + DCF'!$O$47:$T$47)+('DRE + DCF'!$U$47*(1+J$18)/(($I10-J$18)*(1+$I10)^COUNT('DRE + DCF'!$N$36:$T$36)))+SUM($F$13:$F$14)-$F$12)/$F$10 -> 4.0851241 | K10: =(NPV($I10,'DRE + DCF'!$M$47,'DRE + DCF'!$O$47:$T$47)+('DRE + DCF'!$U$47*(1+K$18)/(($I10-K$18)*(1+$I10)^COUNT('DRE + DCF'!$N$36:$T$36)))+SUM($F$13:$F$14)-$F$12)/$F$10 -> 4.3480919 | L10: =(NPV($I10,'DRE + DCF'!$M$47,'DRE + DCF'!$O$47:$T$47)+('DRE + DCF'!$U$47*(1+L$18)/(($I10-L$18)*(1+$I10)^COUNT('DRE + DCF'!$N$36:$T$36)))+SUM($F$13:$F$14)-$F$12)/$F$10 -> 4.6264743 | M10: =(NPV($I10,'DRE + DCF'!$M$47,'DRE + DCF'!$O$47:$T$47)+('DRE + DCF'!$U$47*(1+M$18)/(($I10-M$18)*(1+$I10)^COUNT('DRE + DCF'!$N$36:$T$36)))+SUM($F$13:$F$14)-$F$12)/$F$10 -> 4.9216674 | N10: =(NPV($I10,'DRE + DCF'!$M$47,'DRE + DCF'!$O$47:$T$47)+('DRE + DCF'!$U$47*(1+N$18)/(($I10-N$18)*(1+$I10)^COUNT('DRE + DCF'!$N$36:$T$36)))+SUM($F$13:$F$14)-$F$12)/$F$10 -> 5.2352414 | O10: =(NPV($I10,'DRE + DCF'!$M$47,'DRE + DCF'!$O$47:$T$47)+('DRE + DCF'!$U$47*(1+O$18)/(($I10-O$18)*(1+$I10)^COUNT('DRE + DCF'!$N$36:$T$36)))+SUM($F$13:$F$14)-$F$12)/$F$10 -> 5.5689684 | P10: =(NPV($I10,'DRE + DCF'!$M$47,'DRE + DCF'!$O$47:$T$47)+('DRE + DCF'!$U$47*(1+P$18)/(($I10-P$18)*(1+$I10)^COUNT('DRE + DCF'!$N$36:$T$36)))+SUM($F$13:$F$14)-$F$12)/$F$10 -> 5.9248555 | Q10: =(NPV($I10,'DRE + DCF'!$M$47,'DRE + DCF'!$O$47:$T$47)+('DRE + DCF'!$U$47*(1+Q$18)/(($I10-Q$18)*(1+$I10)^COUNT('DRE + DCF'!$N$36:$T$36)))+SUM($F$13:$F$14)-$F$12)/$F$10 -> 6.3051858 | ... S10: =(NPV($I10,'DRE + DCF'!$M$47,'DRE + DCF'!$O$47:$T$47)+('DRE + DCF'!$U$47*(1+S$18)/(($I10-S$18)*(1+$I10)^COUNT('DRE + DCF'!$N$36:$T$36)))+SUM($F$13:$F$14)-$F$12)/$F$10 -> 7.1499918
A11: Balanço Patrimonial | E11: Valor da Empresa (mil) | F11: =NPV(WACC!$K$20,'DRE + DCF'!M47,'DRE + DCF'!$O$47:$T$47)+(('DRE + DCF'!$U$47*(1+'DRE + DCF'!$W$37))/(WACC!$K$20-'DRE + DCF'!$W$37)*(1/(1+WACC!$K$20)^COUNT('DRE + DCF'!$N$36:$T$36))) -> 2974586.1 | I11: =I12-0.5% -> 0.16529878 | J11: =(NPV($I11,'DRE + DCF'!$M$47,'DRE + DCF'!$O$47:$T$47)+('DRE + DCF'!$U$47*(1+J$18)/(($I11-J$18)*(1+$I11)^COUNT('DRE + DCF'!$N$36:$T$36)))+SUM($F$13:$F$14)-$F$12)/$F$10 -> 3.3221661 | K11: =(NPV($I11,'DRE + DCF'!$M$47,'DRE + DCF'!$O$47:$T$47)+('DRE + DCF'!$U$47*(1+K$18)/(($I11-K$18)*(1+$I11)^COUNT('DRE + DCF'!$N$36:$T$36)))+SUM($F$13:$F$14)-$F$12)/$F$10 -> 3.5519071 | L11: =(NPV($I11,'DRE + DCF'!$M$47,'DRE + DCF'!$O$47:$T$47)+('DRE + DCF'!$U$47*(1+L$18)/(($I11-L$18)*(1+$I11)^COUNT('DRE + DCF'!$N$36:$T$36)))+SUM($F$13:$F$14)-$F$12)/$F$10 -> 3.7943694 | M11: =(NPV($I11,'DRE + DCF'!$M$47,'DRE + DCF'!$O$47:$T$47)+('DRE + DCF'!$U$47*(1+M$18)/(($I11-M$18)*(1+$I11)^COUNT('DRE + DCF'!$N$36:$T$36)))+SUM($F$13:$F$14)-$F$12)/$F$10 -> 4.0506395 | N11: =(NPV($I11,'DRE + DCF'!$M$47,'DRE + DCF'!$O$47:$T$47)+('DRE + DCF'!$U$47*(1+N$18)/(($I11-N$18)*(1+$I11)^COUNT('DRE + DCF'!$N$36:$T$36)))+SUM($F$13:$F$14)-$F$12)/$F$10 -> 4.3219314 | O11: =(NPV($I11,'DRE + DCF'!$M$47,'DRE + DCF'!$O$47:$T$47)+('DRE + DCF'!$U$47*(1+O$18)/(($I11-O$18)*(1+$I11)^COUNT('DRE + DCF'!$N$36:$T$36)))+SUM($F$13:$F$14)-$F$12)/$F$10 -> 4.609606 | P11: =(NPV($I11,'DRE + DCF'!$M$47,'DRE + DCF'!$O$47:$T$47)+('DRE + DCF'!$U$47*(1+P$18)/(($I11-P$18)*(1+$I11)^COUNT('DRE + DCF'!$N$36:$T$36)))+SUM($F$13:$F$14)-$F$12)/$F$10 -> 4.9151934 | Q11: =(NPV($I11,'DRE + DCF'!$M$47,'DRE + DCF'!$O$47:$T$47)+('DRE + DCF'!$U$47*(1+Q$18)/(($I11-Q$18)*(1+$I11)^COUNT('DRE + DCF'!$N$36:$T$36)))+SUM($F$13:$F$14)-$F$12)/$F$10 -> 5.2404203 | ... S11: =(NPV($I11,'DRE + DCF'!$M$47,'DRE + DCF'!$O$47:$T$47)+('DRE + DCF'!$U$47*(1+S$18)/(($I11-S$18)*(1+$I11)^COUNT('DRE + DCF'!$N$36:$T$36)))+SUM($F$13:$F$14)-$F$12)/$F$10 -> 5.9578864
A12: Projeções | E12: Dívida (mil) | F12: =WACC!K19 -> 3471349 | I12: =I13-0.5% -> 0.17029878 | J12: =(NPV($I12,'DRE + DCF'!$M$47,'DRE + DCF'!$O$47:$T$47)+('DRE + DCF'!$U$47*(1+J$18)/(($I12-J$18)*(1+$I12)^COUNT('DRE + DCF'!$N$36:$T$36)))+SUM($F$13:$F$14)-$F$12)/$F$10 -> 2.637741 | K12: =(NPV($I12,'DRE + DCF'!$M$47,'DRE + DCF'!$O$47:$T$47)+('DRE + DCF'!$U$47*(1+K$18)/(($I12-K$18)*(1+$I12)^COUNT('DRE + DCF'!$N$36:$T$36)))+SUM($F$13:$F$14)-$F$12)/$F$10 -> 2.8396159 | L12: =(NPV($I12,'DRE + DCF'!$M$47,'DRE + DCF'!$O$47:$T$47)+('DRE + DCF'!$U$47*(1+L$18)/(($I12-L$18)*(1+$I12)^COUNT('DRE + DCF'!$N$36:$T$36)))+SUM($F$13:$F$14)-$F$12)/$F$10 -> 3.0520825 | M12: =(NPV($I12,'DRE + DCF'!$M$47,'DRE + DCF'!$O$47:$T$47)+('DRE + DCF'!$U$47*(1+M$18)/(($I12-M$18)*(1+$I12)^COUNT('DRE + DCF'!$N$36:$T$36)))+SUM($F$13:$F$14)-$F$12)/$F$10 -> 3.2759969 | N12: =(NPV($I12,'DRE + DCF'!$M$47,'DRE + DCF'!$O$47:$T$47)+('DRE + DCF'!$U$47*(1+N$18)/(($I12-N$18)*(1+$I12)^COUNT('DRE + DCF'!$N$36:$T$36)))+SUM($F$13:$F$14)-$F$12)/$F$10 -> 3.5123097 | O12: =(NPV($I12,'DRE + DCF'!$M$47,'DRE + DCF'!$O$47:$T$47)+('DRE + DCF'!$U$47*(1+O$18)/(($I12-O$18)*(1+$I12)^COUNT('DRE + DCF'!$N$36:$T$36)))+SUM($F$13:$F$14)-$F$12)/$F$10 -> 3.7620802 | P12: =(NPV($I12,'DRE + DCF'!$M$47,'DRE + DCF'!$O$47:$T$47)+('DRE + DCF'!$U$47*(1+P$18)/(($I12-P$18)*(1+$I12)^COUNT('DRE + DCF'!$N$36:$T$36)))+SUM($F$13:$F$14)-$F$12)/$F$10 -> 4.0264916 | Q12: =(NPV($I12,'DRE + DCF'!$M$47,'DRE + DCF'!$O$47:$T$47)+('DRE + DCF'!$U$47*(1+Q$18)/(($I12-Q$18)*(1+$I12)^COUNT('DRE + DCF'!$N$36:$T$36)))+SUM($F$13:$F$14)-$F$12)/$F$10 -> 4.3068701 | ... S12: =(NPV($I12,'DRE + DCF'!$M$47,'DRE + DCF'!$O$47:$T$47)+('DRE + DCF'!$U$47*(1+S$18)/(($I12-S$18)*(1+$I12)^COUNT('DRE + DCF'!$N$36:$T$36)))+SUM($F$13:$F$14)-$F$12)/$F$10 -> 4.9216856
A13: Lojas | E13: Ativos Não-Operacionais | F13: ='Balanço Patrimonial'!L14+'Balanço Patrimonial'!L27 -> 528474.76 | I13: =WACC!K20 -> 0.17529878 | J13: =(NPV($I13,'DRE + DCF'!$M$47,'DRE + DCF'!$O$47:$T$47)+('DRE + DCF'!$U$47*(1+J$18)/(($I13-J$18)*(1+$I13)^COUNT('DRE + DCF'!$N$36:$T$36)))+SUM($F$13:$F$14)-$F$12)/$F$10 -> 2.0206484 | K13: =(NPV($I13,'DRE + DCF'!$M$47,'DRE + DCF'!$O$47:$T$47)+('DRE + DCF'!$U$47*(1+K$18)/(($I13-K$18)*(1+$I13)^COUNT('DRE + DCF'!$N$36:$T$36)))+SUM($F$13:$F$14)-$F$12)/$F$10 -> 2.1989647 | L13: =(NPV($I13,'DRE + DCF'!$M$47,'DRE + DCF'!$O$47:$T$47)+('DRE + DCF'!$U$47*(1+L$18)/(($I13-L$18)*(1+$I13)^COUNT('DRE + DCF'!$N$36:$T$36)))+SUM($F$13:$F$14)-$F$12)/$F$10 -> 2.3861703 | M13: =(NPV($I13,'DRE + DCF'!$M$47,'DRE + DCF'!$O$47:$T$47)+('DRE + DCF'!$U$47*(1+M$18)/(($I13-M$18)*(1+$I13)^COUNT('DRE + DCF'!$N$36:$T$36)))+SUM($F$13:$F$14)-$F$12)/$F$10 -> 2.5829467 | N13: =(NPV($I13,'DRE + DCF'!$M$47,'DRE + DCF'!$O$47:$T$47)+('DRE + DCF'!$U$47*(1+N$18)/(($I13-N$18)*(1+$I13)^COUNT('DRE + DCF'!$N$36:$T$36)))+SUM($F$13:$F$14)-$F$12)/$F$10 -> 2.7900474 | O13: =(NPV($I13,'DRE + DCF'!$M$47,'DRE + DCF'!$O$47:$T$47)+('DRE + DCF'!$U$47*(1+O$18)/(($I13-O$18)*(1+$I13)^COUNT('DRE + DCF'!$N$36:$T$36)))+SUM($F$13:$F$14)-$F$12)/$F$10 -> 3.0083067 | P13: =(NPV($I13,'DRE + DCF'!$M$47,'DRE + DCF'!$O$47:$T$47)+('DRE + DCF'!$U$47*(1+P$18)/(($I13-P$18)*(1+$I13)^COUNT('DRE + DCF'!$N$36:$T$36)))+SUM($F$13:$F$14)-$F$12)/$F$10 -> 3.2386514 | Q13: =(NPV($I13,'DRE + DCF'!$M$47,'DRE + DCF'!$O$47:$T$47)+('DRE + DCF'!$U$47*(1+Q$18)/(($I13-Q$18)*(1+$I13)^COUNT('DRE + DCF'!$N$36:$T$36)))+SUM($F$13:$F$14)-$F$12)/$F$10 -> 3.4821138 | ... S13: =(NPV($I13,'DRE + DCF'!$M$47,'DRE + DCF'!$O$47:$T$47)+('DRE + DCF'!$U$47*(1+S$18)/(($I13-S$18)*(1+$I13)^COUNT('DRE + DCF'!$N$36:$T$36)))+SUM($F$13:$F$14)-$F$12)/$F$10 -> 4.0131448
E14: Créditos Fiscais | F14: =1656613*50% -> 828306.5 | I14: =I13+0.5% -> 0.18029878 | J14: =(NPV($I14,'DRE + DCF'!$M$47,'DRE + DCF'!$O$47:$T$47)+('DRE + DCF'!$U$47*(1+J$18)/(($I14-J$18)*(1+$I14)^COUNT('DRE + DCF'!$N$36:$T$36)))+SUM($F$13:$F$14)-$F$12)/$F$10 -> 1.4617178 | K14: =(NPV($I14,'DRE + DCF'!$M$47,'DRE + DCF'!$O$47:$T$47)+('DRE + DCF'!$U$47*(1+K$18)/(($I14-K$18)*(1+$I14)^COUNT('DRE + DCF'!$N$36:$T$36)))+SUM($F$13:$F$14)-$F$12)/$F$10 -> 1.6199722 | L14: =(NPV($I14,'DRE + DCF'!$M$47,'DRE + DCF'!$O$47:$T$47)+('DRE + DCF'!$U$47*(1+L$18)/(($I14-L$18)*(1+$I14)^COUNT('DRE + DCF'!$N$36:$T$36)))+SUM($F$13:$F$14)-$F$12)/$F$10 -> 1.7857411 | M14: =(NPV($I14,'DRE + DCF'!$M$47,'DRE + DCF'!$O$47:$T$47)+('DRE + DCF'!$U$47*(1+M$18)/(($I14-M$18)*(1+$I14)^COUNT('DRE + DCF'!$N$36:$T$36)))+SUM($F$13:$F$14)-$F$12)/$F$10 -> 1.9595728 | N14: =(NPV($I14,'DRE + DCF'!$M$47,'DRE + DCF'!$O$47:$T$47)+('DRE + DCF'!$U$47*(1+N$18)/(($I14-N$18)*(1+$I14)^COUNT('DRE + DCF'!$N$36:$T$36)))+SUM($F$13:$F$14)-$F$12)/$F$10 -> 2.1420702 | O14: =(NPV($I14,'DRE + DCF'!$M$47,'DRE + DCF'!$O$47:$T$47)+('DRE + DCF'!$U$47*(1+O$18)/(($I14-O$18)*(1+$I14)^COUNT('DRE + DCF'!$N$36:$T$36)))+SUM($F$13:$F$14)-$F$12)/$F$10 -> 2.3338978 | P14: =(NPV($I14,'DRE + DCF'!$M$47,'DRE + DCF'!$O$47:$T$47)+('DRE + DCF'!$U$47*(1+P$18)/(($I14-P$18)*(1+$I14)^COUNT('DRE + DCF'!$N$36:$T$36)))+SUM($F$13:$F$14)-$F$12)/$F$10 -> 2.53579 | Q14: =(NPV($I14,'DRE + DCF'!$M$47,'DRE + DCF'!$O$47:$T$47)+('DRE + DCF'!$U$47*(1+Q$18)/(($I14-Q$18)*(1+$I14)^COUNT('DRE + DCF'!$N$36:$T$36)))+SUM($F$13:$F$14)-$F$12)/$F$10 -> 2.7485601 | ... S14: =(NPV($I14,'DRE + DCF'!$M$47,'DRE + DCF'!$O$47:$T$47)+('DRE + DCF'!$U$47*(1+S$18)/(($I14-S$18)*(1+$I14)^COUNT('DRE + DCF'!$N$36:$T$36)))+SUM($F$13:$F$14)-$F$12)/$F$10 -> 3.2104511
E15: Valor da Ação | F15: =(F11-F12+F13+F14)/F10 -> 2.7900474 | I15: =I14+0.5% -> 0.18529878 | J15: =(NPV($I15,'DRE + DCF'!$M$47,'DRE + DCF'!$O$47:$T$47)+('DRE + DCF'!$U$47*(1+J$18)/(($I15-J$18)*(1+$I15)^COUNT('DRE + DCF'!$N$36:$T$36)))+SUM($F$13:$F$14)-$F$12)/$F$10 -> 0.95336811 | K15: =(NPV($I15,'DRE + DCF'!$M$47,'DRE + DCF'!$O$47:$T$47)+('DRE + DCF'!$U$47*(1+K$18)/(($I15-K$18)*(1+$I15)^COUNT('DRE + DCF'!$N$36:$T$36)))+SUM($F$13:$F$14)-$F$12)/$F$10 -> 1.0944255 | L15: =(NPV($I15,'DRE + DCF'!$M$47,'DRE + DCF'!$O$47:$T$47)+('DRE + DCF'!$U$47*(1+L$18)/(($I15-L$18)*(1+$I15)^COUNT('DRE + DCF'!$N$36:$T$36)))+SUM($F$13:$F$14)-$F$12)/$F$10 -> 1.2418772 | M15: =(NPV($I15,'DRE + DCF'!$M$47,'DRE + DCF'!$O$47:$T$47)+('DRE + DCF'!$U$47*(1+M$18)/(($I15-M$18)*(1+$I15)^COUNT('DRE + DCF'!$N$36:$T$36)))+SUM($F$13:$F$14)-$F$12)/$F$10 -> 1.3961682 | N15: =(NPV($I15,'DRE + DCF'!$M$47,'DRE + DCF'!$O$47:$T$47)+('DRE + DCF'!$U$47*(1+N$18)/(($I15-N$18)*(1+$I15)^COUNT('DRE + DCF'!$N$36:$T$36)))+SUM($F$13:$F$14)-$F$12)/$F$10 -> 1.5577855 | O15: =(NPV($I15,'DRE + DCF'!$M$47,'DRE + DCF'!$O$47:$T$47)+('DRE + DCF'!$U$47*(1+O$18)/(($I15-O$18)*(1+$I15)^COUNT('DRE + DCF'!$N$36:$T$36)))+SUM($F$13:$F$14)-$F$12)/$F$10 -> 1.7272636 | P15: =(NPV($I15,'DRE + DCF'!$M$47,'DRE + DCF'!$O$47:$T$47)+('DRE + DCF'!$U$47*(1+P$18)/(($I15-P$18)*(1+$I15)^COUNT('DRE + DCF'!$N$36:$T$36)))+SUM($F$13:$F$14)-$F$12)/$F$10 -> 1.9051904 | Q15: =(NPV($I15,'DRE + DCF'!$M$47,'DRE + DCF'!$O$47:$T$47)+('DRE + DCF'!$U$47*(1+Q$18)/(($I15-Q$18)*(1+$I15)^COUNT('DRE + DCF'!$N$36:$T$36)))+SUM($F$13:$F$14)-$F$12)/$F$10 -> 2.0922138 | ... S15: =(NPV($I15,'DRE + DCF'!$M$47,'DRE + DCF'!$O$47:$T$47)+('DRE + DCF'!$U$47*(1+S$18)/(($I15-S$18)*(1+$I15)^COUNT('DRE + DCF'!$N$36:$T$36)))+SUM($F$13:$F$14)-$F$12)/$F$10 -> 2.496491
E16: Cotação | F16: 2.79 | I16: =I15+0.5% -> 0.19029878 | J16: =(NPV($I16,'DRE + DCF'!$M$47,'DRE + DCF'!$O$47:$T$47)+('DRE + DCF'!$U$47*(1+J$18)/(($I16-J$18)*(1+$I16)^COUNT('DRE + DCF'!$N$36:$T$36)))+SUM($F$13:$F$14)-$F$12)/$F$10 -> 0.48927769 | K16: =(NPV($I16,'DRE + DCF'!$M$47,'DRE + DCF'!$O$47:$T$47)+('DRE + DCF'!$U$47*(1+K$18)/(($I16-K$18)*(1+$I16)^COUNT('DRE + DCF'!$N$36:$T$36)))+SUM($F$13:$F$14)-$F$12)/$F$10 -> 0.61550521 | L16: =(NPV($I16,'DRE + DCF'!$M$47,'DRE + DCF'!$O$47:$T$47)+('DRE + DCF'!$U$47*(1+L$18)/(($I16-L$18)*(1+$I16)^COUNT('DRE + DCF'!$N$36:$T$36)))+SUM($F$13:$F$14)-$F$12)/$F$10 -> 0.74720667 | M16: =(NPV($I16,'DRE + DCF'!$M$47,'DRE + DCF'!$O$47:$T$47)+('DRE + DCF'!$U$47*(1+M$18)/(($I16-M$18)*(1+$I16)^COUNT('DRE + DCF'!$N$36:$T$36)))+SUM($F$13:$F$14)-$F$12)/$F$10 -> 0.88474602 | N16: =(NPV($I16,'DRE + DCF'!$M$47,'DRE + DCF'!$O$47:$T$47)+('DRE + DCF'!$U$47*(1+N$18)/(($I16-N$18)*(1+$I16)^COUNT('DRE + DCF'!$N$36:$T$36)))+SUM($F$13:$F$14)-$F$12)/$F$10 -> 1.0285202 | O16: =(NPV($I16,'DRE + DCF'!$M$47,'DRE + DCF'!$O$47:$T$47)+('DRE + DCF'!$U$47*(1+O$18)/(($I16-O$18)*(1+$I16)^COUNT('DRE + DCF'!$N$36:$T$36)))+SUM($F$13:$F$14)-$F$12)/$F$10 -> 1.1789631 | P16: =(NPV($I16,'DRE + DCF'!$M$47,'DRE + DCF'!$O$47:$T$47)+('DRE + DCF'!$U$47*(1+P$18)/(($I16-P$18)*(1+$I16)^COUNT('DRE + DCF'!$N$36:$T$36)))+SUM($F$13:$F$14)-$F$12)/$F$10 -> 1.3365495 | Q16: =(NPV($I16,'DRE + DCF'!$M$47,'DRE + DCF'!$O$47:$T$47)+('DRE + DCF'!$U$47*(1+Q$18)/(($I16-Q$18)*(1+$I16)^COUNT('DRE + DCF'!$N$36:$T$36)))+SUM($F$13:$F$14)-$F$12)/$F$10 -> 1.5018008 | ... S16: =(NPV($I16,'DRE + DCF'!$M$47,'DRE + DCF'!$O$47:$T$47)+('DRE + DCF'!$U$47*(1+S$18)/(($I16-S$18)*(1+$I16)^COUNT('DRE + DCF'!$N$36:$T$36)))+SUM($F$13:$F$14)-$F$12)/$F$10 -> 1.8576489
E17: =IFERROR(IF(F17=0,"",IF(F17>0,"Upside","Downside")),"") -> Upside | F17: =IFERROR(F15/F16-1,"") -> 1.6999272e-05 | I17: =I16+0.5% -> 0.19529878 | J17: =(NPV($I17,'DRE + DCF'!$M$47,'DRE + DCF'!$O$47:$T$47)+('DRE + DCF'!$U$47*(1+J$18)/(($I17-J$18)*(1+$I17)^COUNT('DRE + DCF'!$N$36:$T$36)))+SUM($F$13:$F$14)-$F$12)/$F$10 -> 0.064133143 | K17: =(NPV($I17,'DRE + DCF'!$M$47,'DRE + DCF'!$O$47:$T$47)+('DRE + DCF'!$U$47*(1+K$18)/(($I17-K$18)*(1+$I17)^COUNT('DRE + DCF'!$N$36:$T$36)))+SUM($F$13:$F$14)-$F$12)/$F$10 -> 0.17750161 | L17: =(NPV($I17,'DRE + DCF'!$M$47,'DRE + DCF'!$O$47:$T$47)+('DRE + DCF'!$U$47*(1+L$18)/(($I17-L$18)*(1+$I17)^COUNT('DRE + DCF'!$N$36:$T$36)))+SUM($F$13:$F$14)-$F$12)/$F$10 -> 0.29558203 | M17: =(NPV($I17,'DRE + DCF'!$M$47,'DRE + DCF'!$O$47:$T$47)+('DRE + DCF'!$U$47*(1+M$18)/(($I17-M$18)*(1+$I17)^COUNT('DRE + DCF'!$N$36:$T$36)))+SUM($F$13:$F$14)-$F$12)/$F$10 -> 0.4186744 | N17: =(NPV($I17,'DRE + DCF'!$M$47,'DRE + DCF'!$O$47:$T$47)+('DRE + DCF'!$U$47*(1+N$18)/(($I17-N$18)*(1+$I17)^COUNT('DRE + DCF'!$N$36:$T$36)))+SUM($F$13:$F$14)-$F$12)/$F$10 -> 0.54710475 | O17: =(NPV($I17,'DRE + DCF'!$M$47,'DRE + DCF'!$O$47:$T$47)+('DRE + DCF'!$U$47*(1+O$18)/(($I17-O$18)*(1+$I17)^COUNT('DRE + DCF'!$N$36:$T$36)))+SUM($F$13:$F$14)-$F$12)/$F$10 -> 0.68122799 | P17: =(NPV($I17,'DRE + DCF'!$M$47,'DRE + DCF'!$O$47:$T$47)+('DRE + DCF'!$U$47*(1+P$18)/(($I17-P$18)*(1+$I17)^COUNT('DRE + DCF'!$N$36:$T$36)))+SUM($F$13:$F$14)-$F$12)/$F$10 -> 0.82143123 | Q17: =(NPV($I17,'DRE + DCF'!$M$47,'DRE + DCF'!$O$47:$T$47)+('DRE + DCF'!$U$47*(1+Q$18)/(($I17-Q$18)*(1+$I17)^COUNT('DRE + DCF'!$N$36:$T$36)))+SUM($F$13:$F$14)-$F$12)/$F$10 -> 0.96813748 | ... S17: =(NPV($I17,'DRE + DCF'!$M$47,'DRE + DCF'!$O$47:$T$47)+('DRE + DCF'!$U$47*(1+S$18)/(($I17-S$18)*(1+$I17)^COUNT('DRE + DCF'!$N$36:$T$36)))+SUM($F$13:$F$14)-$F$12)/$F$10 -> 1.2829568
E18: TIR | J18: =K18-0.25% -> 0.07 | K18: =L18-0.25% -> 0.0725 | L18: =M18-0.25% -> 0.075 | M18: =N18-0.25% -> 0.0775 | N18: ='DRE + DCF'!W37 -> 0.08 | O18: =N18+0.25% -> 0.0825 | P18: =O18+0.25% -> 0.085 | Q18: =P18+0.25% -> 0.0875 | R18: =Q18+0.25% -> 0.09 | S18: =R18+0.25% -> 0.0925
J19: Growth

Sheet WACC
I5: C&A ($CEAB3)
A7: Páginas
A8: Dashboard
A9: WACC
A10: DRE + DCF | K10: Valor | N10: Descrição
A11: Balanço Patrimonial | E11: DI | K11: 0.1342 | N11: A ponto de partida para encontrar a taxa livre de risco no Brasil é pegar o título pós-fixado sem pagamentos períodicos emitido pelo governo de prazo mais longo.
A12: Projeções | E12: CDS | K12: 0.032 | N12: Credit Default Swap (CDS). Dados: bit.ly/cdsbrasil Como alternativa, usar último dado disponível do EMBI+:bit.ly/2u4NtEm
A13: Lojas | E13: Taxa Livre de Risco | K13: =K11-K12 -> 0.1022
E14: Beta | K14: 2
E15: Prêmio de Risco | K15: 0.065 | N15: Dados Alternativos FGV: https://goo.gl/bBfwGq
E16: Custo de Capital Próprio (Ke) | K16: 0.29675103
E17: Valor de Mercado | K17: 866000 | N17: Número de ações vezes a cotação da ação no último pregão.
E18: Custo de Capital de Terceiros (Kd) | K18: 0.145 | N18: Yield to Maturity da debênture de prazo mais longo da companhia negociada no mercado secundário.
E19: Dívida Bruta | K19: ='Balanço Patrimonial'!L52+'Balanço Patrimonial'!L63 -> 3471349
E20: WACC | K20: =(K16*K17+K18*K19)/SUM(K17,K19) -> 0.17529878

Sheet DRE + DCF
J5: C&A ($CEAB3)
A7: Páginas
A8: Dashboard
A9: WACC
A10: DRE + DCF | F10: 2016 | G10: 2017 | H10: 2018 | I10: 2019 | J10: 2020 | K10: 2021 | L10: 1T2022 | M10: YTG 2022E | N10: 2022 | O10: 2023 | P10: 2024 | Q10: 2025 | R10: =Q10+1 -> 2026 | S10: =R10+1 -> 2027 | T10: =S10+1 -> 2028
A11: Balanço Patrimonial | E11: Receita Líquida | F11: 4780694 | G11: 5035610 | H11: 5139114 | I11: 5285176 | J11: 4085486 | K11: 5153205 | L11: 1197024 | M11: =N11-L11 -> 4397145.6 | N11: ='Projeções - Receita'!L10 -> 5594169.6 | O11: ='Projeções - Receita'!M10 -> 6643601.4 | P11: ='Projeções - Receita'!N10 -> 7910445.7 | Q11: ='Projeções - Receita'!O10 -> 9223569.7 | R11: ='Projeções - Receita'!P10 -> 10319264 | S11: ='Projeções - Receita'!Q10 -> 11455213 | T11: ='Projeções - Receita'!R10 -> 12401748
A12: Projeções | E12: Crescimento da Receita (YoY)¹ | G12: =G11/F11-1 -> 0.053321965 | H12: =H11/G11-1 -> 0.020554411 | I12: =I11/H11-1 -> 0.028421631 | J12: =J11/I11-1 -> -0.22699149 | K12: =K11/J11-1 -> 0.26134443 | N12: =N11/K11-1 -> 0.085570943 | O12: =O11/N11-1 -> 0.18759385 | P12: =P11/O11-1 -> 0.19068637 | Q12: =Q11/P11-1 -> 0.16599874 | R12: =R11/Q11-1 -> 0.11879289 | S12: =S11/R11-1 -> 0.11008039 | T12: =T11/S11-1 -> 0.082629221
A13: Lojas | E13: Custos das Vendas e Serviços | F13: -2775856 | G13: -2614085 | H13: -2589971 | I13: -2717065 | J13: -2188859 | K13: -2755897 | L13: -629605
E14: Lucro Bruto | F14: =F11+F13 -> 2004838 | G14: =G11+G13 -> 2421525 | H14: =H11+H13 -> 2549143 | I14: =I11+I13 -> 2568111 | J14: =J11+J13 -> 1896627 | K14: =K11+K13 -> 2397308 | L14: =L11+L13 -> 567419
E15: Margem Bruta | F15: =F14/F11 -> 0.41936129 | G15: =G14/G11 -> 0.48088017 | H15: =H14/H11 -> 0.49602772 | I15: =I14/I11 -> 0.48590832 | J15: =J14/J11 -> 0.46423534 | K15: =K14/K11 -> 0.46520719 | L15: =L14/L11 -> 0.47402475
E16: Despesas/ Receitas Operacionais | F16: =F17+F18+F19 -> -2012392 | G16: =G17+G18+G19 -> -2124825 | H16: =H17+H18+H19 -> -2192922 | I16: =I17+I18+I19 -> -1535027 | J16: =J17+J18+J19 -> -2060865 | K16: =K17+K18+K19 -> -2304510 | L16: =L17+L18+L19 -> -738362
E17: Despesas com Vendas | F17: -1536151 | G17: -1596848 | H17: -1699883 | I17: -1755337 | J17: -1648437 | K17: -2025632 | L17: -559936
E18: Despesas Gerais e Administrativas | F18: -481679 | G18: -509821 | H18: -482233 | I18: -498019 | J18: -491704 | K18: -487881 | L18: -175828
E19: Resultado Operacional Outros | F19: 5438 | G19: -18156 | H19: -10806 | I19: =SUM(I20:I21) -> 718329 | J19: =SUM(J20:J21) -> 79276 | K19: =SUM(K20:K21) -> 209003 | L19: =SUM(L20:L21) -> -2598
E20: Outras Receitas Operacionais | F20: 0 | G20: 20964 | H20: 2106 | I20: 773960 | J20: 170721 | K20: 234525 | L20: 10197
E21: Outras Despesas Operacionais | F21: 0 | G21: -39120 | H21: -12912 | I21: -55631 | J21: -91445 | K21: -25522 | L21: -12795
E22: EBIT | F22: =F14+F16 -> -7554 | G22: =G14+G16 -> 296700 | H22: =H14+H16 -> 356221 | I22: =I14+I16 -> 1033084 | J22: =J14+J16 -> -164238 | K22: =K14+K16 -> 92798 | L22: =L14+L16 -> -170943
E23: Margem EBIT | F23: =F22/F11 -> -0.0015801053 | G23: =G22/G11 -> 0.058920369 | H23: =H22/H11 -> 0.069315645 | I23: =I22/I11 -> 0.19546823 | J23: =J22/J11 -> -0.040200358 | K23: =K22/K11 -> 0.018007822 | L23: =L22/L11 -> -0.14280666
E24: Eventos não recorrentes | F24: ='DRE - Contas Abertas'!F58 -> 0 | G24: ='DRE - Contas Abertas'!G58 -> 0 | H24: ='DRE - Contas Abertas'!H58 -> 0 | I24: ='DRE - Contas Abertas'!I58 -> 717165 | J24: ='DRE - Contas Abertas'!J58 -> 94779 | K24: ='DRE - Contas Abertas'!K58 -> 210451
E25: EBIT Recorrente | F25: ='DRE - Contas Abertas'!F59 -> -7554 | G25: ='DRE - Contas Abertas'!G59 -> 296700 | H25: ='DRE - Contas Abertas'!H59 -> 356221 | I25: ='DRE - Contas Abertas'!I59 -> 315919 | J25: ='DRE - Contas Abertas'!J59 -> -259017 | K25: ='DRE - Contas Abertas'!K59 -> -117653 | L25: =L22-L24 -> -170943 | M25: =N25-L25 -> -228503.67 | N25: ='Projeções - EBIT'!K10 -> -399446.67 | O25: ='Projeções - EBIT'!L10 -> -379456.58 | P25: ='Projeções - EBIT'!M10 -> -283298.24 | Q25: ='Projeções - EBIT'!N10 -> 365925.88 | R25: ='Projeções - EBIT'!O10 -> 604135.52 | S25: ='Projeções - EBIT'!P10 -> 900051.54 | T25: ='Projeções - EBIT'!Q10 -> 1090351.8
E26: Margem EBIT Recorrente | F26: ='DRE - Contas Abertas'!F60 -> -0.0015801053 | G26: ='DRE - Contas Abertas'!G60 -> 0.058920369 | H26: ='DRE - Contas Abertas'!H60 -> 0.069315645 | I26: ='DRE - Contas Abertas'!I60 -> 0.059774547 | J26: ='DRE - Contas Abertas'!J60 -> -0.063399312 | K26: =K22/K11 -> 0.018007822 | L26: =L22/L11 -> -0.14280666 | M26: =M22/M11 -> 0 | N26: =N25/N11 -> -0.071404104 | O26: =O25/O11 -> -0.057116097 | P26: =P25/P11 -> -0.035813183 | Q26: =Q25/Q11 -> 0.039672913 | R26: =R25/R11 -> 0.058544438 | S26: =S25/S11 -> 0.078571351 | T26: =T25/T11 -> 0.087919206
E27: Resultado Financeiro | F27: =SUM(F28:F29) -> -197360 | G27: =SUM(G28:G29) -> -155153 | H27: =SUM(H28:H29) -> -130671 | I27: =SUM(I28:I29) -> 388942 | J27: =SUM(J28:J29) -> -91435 | K27: =SUM(K28:K29) -> -91807 | L27: =SUM(L28:L29) -> -68568
E28: Receitas Financeiras | F28: 514398 | G28: 168253 | H28: 186189 | I28: 670833 | J28: 134345 | K28: 176189 | L28: 41764
E29: Despesas Financeiras | F29: -711758 | G29: -323406 | H29: -316860 | I29: -281891 | J29: -225780 | K29: -267996 | L29: -110332
E30: Resultado Antes dos Tributos Sobre o Lucro | F30: =F22+F27 -> -204914 | G30: =G22+G27 -> 141547 | H30: =H22+H27 -> 225550 | I30: =I22+I27 -> 1422026 | J30: =J22+J27 -> -255673 | K30: =K22+K27 -> 991 | L30: =L22+L27 -> -239511
E31: Imposto de Renda e CSLL | F31: 63642 | G31: -44667 | H31: -51914 | I31: -450033 | J31: 89341 | K31: 328018 | L31: 86781
E32: Lucro Líquido | F32: =F30+F31 -> -141272 | G32: =G30+G31 -> 96880 | H32: =H30+H31 -> 173636 | I32: =I30+I31 -> 971993 | J32: =J30+J31 -> -166332 | K32: =K30+K31 -> 329009 | L32: =L30+L31 -> -152730
E33: Margem Líquida | F33: =F32/F11 -> -0.029550521 | G33: =G32/G11 -> 0.01923898 | H33: =H32/H11 -> 0.033787147 | I33: =I32/I11 -> 0.1839093 | J33: =J32/J11 -> -0.040712904 | K33: =K32/K11 -> 0.06384551 | L33: =L32/L11 -> -0.12759143
F36: 2016 | G36: 2017 | H36: 2018 | I36: 2019 | J36: 2020 | K36: 2021 | L36: 1T2022 | M36: YTG 2022E | N36: 2022 | O36: 2023 | P36: 2024 | Q36: 2025 | R36: =Q36+1 -> 2026 | S36: =R36+1 -> 2027 | T36: =S36+1 -> 2028 | U36: Perpetuidade | V36: ROIC Perp. | W36: Growth
E37: Alíquota Efetiva | F37: =IFERROR(IF(F22>0,-F31/F22,"-"),"-") -> - | G37: =IFERROR(IF(G22>0,-G31/G22,"-"),"-") -> 0.15054601 | H37: =IFERROR(IF(H22>0,-H31/H22,"-"),"-") -> 0.14573537 | I37: =IFERROR(IF(I22>0,-I31/I22,"-"),"-") -> 0.43562092 | J37: =IFERROR(IF(J22>0,-J31/J22,"-"),"-") -> - | K37: =IFERROR(IF(K22>0,"-","-"),"-") -> - | L37: =IFERROR(IF(L22>0,"-","-"),"-") -> - | Q37: 0.0851 | R37: 0.0851 | S37: 0.0851 | T37: 0.0851 | U37: 0.34 | V37: 0.133 | W37: 0.08
E38: D&A do Arrendamento | F38: ='Projeções - Capex + CG'!F27 -> 0 | G38: ='Projeções - Capex + CG'!G27 -> 0 | H38: ='Projeções - Capex + CG'!H27 -> 0 | I38: ='Projeções - Capex + CG'!I27 -> 295675 | J38: ='Projeções - Capex + CG'!J27 -> 306443 | K38: ='Projeções - Capex + CG'!K27 -> 338325 | L38: 94542 | M38: =N38-L38 -> 290876.88 | N38: =N39*N11 -> 385418.88 | O38: =O39*O11 -> 457721.09 | P38: =P39*P11 -> 545002.26 | Q38: =Q39*Q11 -> 635471.95 | R38: =R39*R11 -> 710961.5 | S38: =S39*S11 -> 789224.42 | T38: =T39*T11 -> 854437.42 | U38: =U39*T11 -> 854437.42
E39: (%) da Receita Líquida | F39: =F38/F11 -> 0 | G39: =G38/G11 -> 0 | H39: =H38/H11 -> 0 | I39: =I38/I11 -> 0.055944211 | J39: =J38/J11 -> 0.075007722 | K39: =K38/K11 -> 0.065653317 | L39: =L38/L11 -> 0.078980873 | M39: =AVERAGE(I39:L39) -> 0.068896531 | N39: =M39 -> 0.068896531 | O39: =N39 -> 0.068896531 | P39: =O39 -> 0.068896531 | Q39: =P39 -> 0.068896531 | R39: =Q39 -> 0.068896531 | S39: =R39 -> 0.068896531 | T39: =S39 -> 0.068896531 | U39: =T39 -> 0.068896531
E40: NOPAT | F40: =F22+F31+F38 -> 56088 | G40: =G22+G31+G38 -> 252033 | H40: =H22+H31+H38 -> 304307 | I40: =(I22-'DRE - Contas Abertas'!I58*(1-N37))+I38 -> 611594 | J40: =J22+J31+J38 -> 231546 | K40: =K22+K31+K38 -> 759141 | L40: =L22+L31+L38 -> 10380 | M40: =N40-L40 -> -24407.788 | N40: =N25*(1-N37)+N38 -> -14027.788 | O40: =O25*(1-O37)+O38 -> 78264.509 | P40: =P25*(1-P37)+P38 -> 261704.02 | Q40: =Q25*(1-Q37)+Q38 -> 970257.54 | R40: =R25*(1-R37)+R38 -> 1263685.1 | S40: =S25*(1-S37)+S38 -> 1612681.6 | T40: =T25*(1-T37)+T38 -> 1852000.3 | U40: =T25*(1-U37)+U38 -> 1574069.6
E41: Taxa de Reinvestimento | F41: =IFERROR(SUM(F42,F46)/(F40),0) -> -1.6489089 | G41: =IFERROR(SUM(G42,G46)/(G40),0) -> -0.84268766 | H41: =IFERROR(SUM(H42,H46)/(H40),0) -> 0.42887479 | I41: =IFERROR(SUM(I42,I46)/(I40),0) -> -0.0041194812 | J41: =IFERROR(SUM(J42,J46)/(J40),0) -> -0.93123721 | K41: =IFERROR(SUM(K42,K46)/(K40),0) -> 0.55574126 | L41: =IFERROR(SUM(L42,L46)/(L40),0) -> 56.059163 | M41: =IFERROR(SUM(M42,M46)/(M40),0) -> 6.1872878 | ... T41: =IFERROR(SUM(T42,T46)/(T40),0) -> 0.45068205 | U41: =W37/V37 -> 0.60150376
E42: CAPEX Líquido | F42: =F43-F44 -> -92484 | G42: =G43-G44 -> -98997 | H42: =H43-H44 -> 34609 | I42: =I43-I44 -> 85658 | J42: =J43-J44 -> 56178 | K42: =K43-K44 -> 435445 | L42: =L43-L44 -> -25315 | M42: =N42-L42 -> 149763.77 | N42: =IF((N43-N44)>0,N43-N44,0) -> 124448.77 | O42: =IF((O43-O44)>0,O43-O44,0) -> 582096.09 | P42: =IF((P43-P44)>0,P43-P44,0) -> 77606.101 | Q42: =IF((Q43-Q44)>0,Q43-Q44,Q44) -> 532985.48 | R42: =IF((R43-R44)>0,R43-R44,R44) -> 596300.36 | S42: =IF((S43-S44)>0,S43-S44,S44) -> 661941.33 | T42: =IF((T43-T44)>0,T43-T44,T44) -> 716637.03
E43: CAPEX | F43: ='Projeções - Capex + CG'!F14 -> 110200 | G43: ='Projeções - Capex + CG'!G14 -> 98900 | H43: ='Projeções - Capex + CG'!H14 -> 239700 | I43: ='Projeções - Capex + CG'!I14 -> 318700 | J43: ='Projeções - Capex + CG'!J14 -> 302500 | K43: ='Projeções - Capex + CG'!K14 -> 682100 | L43: 55500 | M43: =N43-L43 -> 392208.77 | N43: ='Projeções - Capex + CG'!L14 -> 447708.77 | O43: ='Projeções - Capex + CG'!M14 -> 965997.68 | P43: ='Projeções - Capex + CG'!N14 -> 534712.49 | Q43: ='Projeções - Capex + CG'!O14 -> 517013.57 | R43: ='Projeções - Capex + CG'!P14 -> 327645.23 | S43: ='Projeções - Capex + CG'!Q14 -> 363130.11 | T43: ='Projeções - Capex + CG'!R14 -> 401381.77
E44: Depreciação & Amortização | F44: ='Projeções - Capex + CG'!F25 -> 202684 | G44: ='Projeções - Capex + CG'!G25 -> 197897 | H44: ='Projeções - Capex + CG'!H25 -> 205091 | I44: ='Projeções - Capex + CG'!I25 -> 233042 | J44: ='Projeções - Capex + CG'!J25 -> 246322 | K44: ='Projeções - Capex + CG'!K25 -> 246655 | L44: 80815 | M44: =N44-L44 -> 242445 | N44: =L44*4 -> 323260 | O44: =O45*O11 -> 383901.59 | P44: =P45*P11 -> 457106.39 | Q44: =Q45*Q11 -> 532985.48 | R44: =R45*R11 -> 596300.36 | S44: =S45*S11 -> 661941.33 | T44: =T45*T11 -> 716637.03
E45: (%) da Receita Líquida | F45: =F44/F11 -> 0.042396355 | G45: =G44/G11 -> 0.039299509 | H45: =H44/H11 -> 0.039907852 | I45: =I44/I11 -> 0.044093517 | J45: =J44/J11 -> 0.06029197 | K45: =K44/K11 -> 0.047864387 | L45: =L44/L11 -> 0.067513266 | M45: =M44/M11 -> 0.055136905 | N45: =N44/N11 -> 0.057785162 | O45: =N45 -> 0.057785162 | P45: =O45 -> 0.057785162 | Q45: =P45 -> 0.057785162 | R45: =Q45 -> 0.057785162 | S45: =R45 -> 0.057785162 | T45: =S45 -> 0.057785162
E46: ∆ Capital de Giro | G46: ='Projeções - Capex + CG'!G11-'Projeções - Capex + CG'!F11 -> -113388.1 | H46: ='Projeções - Capex + CG'!H11-'Projeções - Capex + CG'!G11 -> 95900.6 | I46: ='Projeções - Capex + CG'!I11-'Projeções - Capex + CG'!H11 -> -88177.45 | J46: ='Projeções - Capex + CG'!J11-'Projeções - Capex + CG'!I11 -> -271802.25 | K46: ='Projeções - Capex + CG'!K11-'Projeções - Capex + CG'!J11 -> -13559.025 | L46: ='Balanço Patrimonial'!L9-'Balanço Patrimonial'!K9 -> 607209.12 | M46: =N46-L46 -> -300781.78 | N46: ='Projeções - Capex + CG'!L11-'Projeções - Capex + CG'!K11 -> 306427.33 | O46: ='Projeções - Capex + CG'!M11-'Projeções - Capex + CG'!L11 -> 130856.74 | P46: ='Projeções - Capex + CG'!N11-'Projeções - Capex + CG'!M11 -> 157966.53 | Q46: ='Projeções - Capex + CG'!O11-'Projeções - Capex + CG'!N11 -> 163737.3 | R46: ='Projeções - Capex + CG'!P11-'Projeções - Capex + CG'!O11 -> 136625.36 | S46: ='Projeções - Capex + CG'!Q11-'Projeções - Capex + CG'!P11 -> 141644.77 | T46: ='Projeções - Capex + CG'!R11-'Projeções - Capex + CG'!Q11 -> 118026.27
E47: FCFF | F47: =(F40)*(1-F41) -> 148572 | G47: =(G40)*(1-G41) -> 464418.1 | H47: =(H40)*(1-H41) -> 173797.4 | I47: =(I40)*(1-I41) -> 614113.45 | J47: =(J40)*(1-J41) -> 447170.25 | K47: =(K40)*(1-K41) -> 337255.02 | L47: =(L40)*(1-L41) -> -571514.12 | M47: =(M40)*(1-M41) -> 126610.22 | ... U47: =(U40)*(1-U41) -> 627260.83
...

Sheet DRE - Contas Abertas
A7: Páginas
A8: Dashboard
A9: WACC | F9: 2016 | G9: 2017 | H9: 2018 | I9: 2019 | J9: 2020 | K9: 2021
A10: DRE + DCF | E10: Pessoal | F10: -585593 | G10: -585653 | H10: -556853 | I10: -579633 | J10: -488088 | K10: -598914
A11: Balanço Patrimonial | E11: Material/Serviços de terceiros | F11: -147630 | G11: -143144 | H11: -208540 | I11: -203002 | J11: -275228 | K11: -324160
A12: Projeções | E12: Depreciação de direito de uso | F12: 0 | G12: 0 | H12: 0 | I12: -248687 | J12: -257798 | K12: -285667
A13: Lojas | E13: Depreciação e amortização | F13: -141898 | G13: -135358 | H13: -142604 | I13: -155499 | J13: -163352 | K13: -144330
E14: Ocupação | F14: -445775 | G14: -494621 | H14: -526073 | I14: -280085 | J14: -148137 | K14: -294022
E15: Publicidade e Promoção | F15: -115738 | G15: -96180 | H15: -122219 | I15: -109993 | J15: -185169 | K15: -211744
E16: Perdas em créditos, líquidas | F16: 0 | G16: 0 | H16: 0 | I16: 0 | J16: 0 | K16: 0
E17: Outros | F17: -99517 | G17: -141892 | H17: -163916 | I17: -178438 | J17: -130665 | K17: -166795
E18: Total: | F18: =F10+F11+F12+F13+F14+F15+F17+F16 -> -1536151 | G18: =G10+G11+G12+G13+G14+G15+G17+G16 -> -1596848 | H18: =H10+H11+H12+H13+H14+H15+H17+H16 -> -1720205 | I18: =I10+I11+I12+I13+I14+I15+I17+I16 -> -1755337 | J18: =J10+J11+J12+J13+J14+J15+J17+J16 -> -1648437 | K18: =K10+K11+K12+K13+K14+K15+K17+K16 -> -2025632
F22: 2016 | G22: 2017 | H22: 2018 | I22: 2019 | J22: 2020 | K22: 2021
E23: Pessoal | F23: -217453 | G23: -240665 | H23: -265938 | I23: -271698 | J23: -263249 | K23: -254763
E24: Material/Serviços de terceiros | F24: -149311 | G24: -155498 | H24: -115322 | I24: -104330 | J24: -123492 | K24: -127569
E25: Depreciação de direito de uso | F25: 0 | G25: 0 | H25: 0 | I25: -77544 | J25: -82981 | K25: -102325
E26: Depreciação e amortização | F26: -59975 | G26: -62258 | H26: -62620 | I26: -20066 | J26: -20816 | K26: -22319
E27: Ocupação | F27: -32088 | G27: -33185 | H27: -31283 | I27: -6621 | J27: -1746 | K27: -5727
E28: Outros | F28: -22852 | G28: -18215 | H28: 13252 | I28: -17760 | J28: 580 | K28: 24822
E29: Total: | F29: =F23+F24+F25+F26+F27+F28 -> -481679 | G29: =G23+G24+G25+G26+G27+G28 -> -509821 | H29: =H23+H24+H25+H26+H27+H28 -> -461911 | I29: =I23+I24+I25+I26+I27+I28 -> -498019 | J29: =J23+J24+J25+J26+J27+J28 -> -491704 | K29: =K23+K24+K25+K26+K27+K28 -> -487881
F33: 2016 | G33: 2017 | H33: 2018 | I33: 2019 | J33: 2020 | K33: 2021
E34: Resultado na baixa de ativos | F34: -1661 | G34: -20964 | H34: -12912 | I34: -34133 | J34: -7592 | K34: -2529
E35: Reversão (provisão) impairment: | F35: =F36+F37 -> 0 | G35: =G36+G37 -> 0 | H35: =H36+H37 -> 0 | I35: =I36+I37 -> 26382 | J35: =J36+J37 -> 6151 | K35: =K36+K37 -> 3901
E36: Encerramento/reforma de lojas | F36: 0 | G36: 0 | H36: 0 | I36: 15118 | J36: 5147 | K36: -2220
E37: Teste de recuperabilidade | F37: 0 | H37: 0 | I37: 11264 | J37: 1004 | K37: 6121
E38: Recuperação de créditos fiscais: | F38: =F39+F40+F41+F42+F43+F44 -> 0 | G38: =G39+G40+G41+G42+G43+G44 -> 0 | H38: =H39+H40+H41+H42+H43+H44 -> 0 | I38: =I39+I40+I41+I42+I43+I44 -> 644893 | J38: =J39+J40+J41+J42+J43+J44 -> 150429 | K38: 228404
E39: ICMS na base de cálculo PIS/COFINS | F39: 0 | G39: 0 | H39: 0 | I39: 663538 | J39: 0 | K39: 0
E40: Ação Judicial ZFM e Reintegra | F40: 0 | G40: 0 | H40: 0 | I40: 0 | J40: 94902 | K40: 0
E41: PIS/COFINS importação base de cálculo | F41: 0 | G41: 0 | H41: 0 | I41: 0 | J41: 47654 | K41: 0
E42: Créditos previdenciários | F42: 0 | G42: 0 | H42: 0 | I42: 0 | J42: 22014 | K42: 0
E43: Outros créditos fiscais | F43: 0 | G43: 0 | H43: 0 | I43: 2853 | J43: 0 | K43: 0
E44: Despesas relacionadas aos créditos fiscais | F44: 0 | G44: 0 | H44: 0 | I44: -21498 | J44: -14141 | K44: 0
E45: Reversão (provisão) contingências tributárias | F45: 0 | G45: 0 | H45: 0 | I45: 72272 | J45: -25791 | K45: -13644
E46: Consultorias estratégicas | F46: 0 | G46: 0 | H46: 0 | I46: 0 | J46: -29859 | K46: -4309
E47: Depreciação e amortizção | F47: -811 | G47: -281 | H47: 0 | I47: 0 | J47: 0 | K47: 0
E48: Perdas de Créditos Líquidas | F48: 0 | G48: 0 | H48: 0 | I48: 0 | J48: 0 | K48: -492
E49: Outros | F49: 7910 | G49: 3089 | H49: 2106 | I49: 8915 | J49: -14062 | K49: -2328
E50: Total: | F50: =F34+F35+F38+F45+F46+F47+F49+F48 -> 5438 | G50: =G34+G35+G38+G45+G46+G47+G49+G48 -> -18156 | H50: =H34+H35+H38+H45+H46+H47+H49+H48 -> -10806 | I50: =I34+I35+I38+I45+I46+I47+I49+I48 -> 718329 | J50: =J34+J35+J38+J45+J46+J47+J49+J48 -> 79276 | K50: =K34+K35+K38+K45+K46+K47+K49+K48 -> 209003
F54: 2016 | G54: 2017 | H54: 2018 | I54: 2019 | J54: 2020 | K54: 2021
E55: Lucro Bruto | F55: ='DRE + DCF'!F14 -> 2004838 | G55: ='DRE + DCF'!G14 -> 2421525 | H55: ='DRE + DCF'!H14 -> 2549143 | I55: ='DRE + DCF'!I14 -> 2568111 | J55: ='DRE + DCF'!J14 -> 1896627 | K55: ='DRE + DCF'!K14 -> 2397308
...

Sheet Balanço Patrimonial
A7: Páginas
A8: Dashboard | F8: 2016 | G8: 2017 | H8: 2018 | I8: 2019 | J8: 2020 | K8: 2021 | L8: 1T22
A9: WACC | E9: Capital de Giro | F9: =F13+F15+F17+-F42-F44-F47 -> 782152.35 | G9: =G13+G15+G17+-G42-G44-G47 -> 668764.25 | H9: =H13+H15+H17+-H42-H44-H47 -> 764664.85 | I9: =I13+I15+I17+-I42-I44-I47 -> 676487.4 | J9: =J13+J15+J17+-J42-J44-J47 -> 404685.15 | K9: =K13+K15+K17+-K42-K44-K47 -> 391126.12 | L9: =L13+L15+L17+-L42-L44-L47+K72 -> 998335.24
A10: DRE + DCF | E10: Ativo Total | F10: =F11+F25 -> 3631176 | G10: =G11+G25 -> 3394299 | H10: =H11+H25 -> 3478337 | I10: =I11+I25 -> 6037092 | J10: =J11+J25 -> 7309647 | K10: =K11+K25 -> 8672626 | L10: =L11+L25 -> 8256189
A11: Balanço Patrimonial | E11: Ativo Circulante | F11: =F12+F15+F17+F18+F20 -> 2144643 | G11: =G12+G15+G17+G18+G20 -> 2125587 | H11: =H12+H15+H17+H18+H20 -> 2195569 | I11: =I12+I15+I17+I18+I20 -> 2999575 | J11: =J12+J15+J17+J18+J20 -> 3519978 | K11: =K12+K15+K17+K18+K20 -> 3929358 | L11: =L12+L15+L17+L18+L20 -> 3626438
A12: Projeções | E12: Caixa e Equivalentes de Caixa | F12: 489705 | G12: 431759 | H12: 446006 | I12: 447109 | J12: 1509159 | K12: 1050251 | L12: =660373+3978 -> 664351
A13: Lojas | E13: Caixa Operacional | F13: ='DRE + DCF'!F11*0.025 -> 119517.35 | G13: ='DRE + DCF'!G11*0.025 -> 125890.25 | H13: ='DRE + DCF'!H11*0.025 -> 128477.85 | I13: ='DRE + DCF'!I11*0.025 -> 132129.4 | J13: ='DRE + DCF'!J11*0.025 -> 102137.15 | K13: ='DRE + DCF'!K11*0.025 -> 128830.12 | L13: ='DRE + DCF'!N11*0.025 -> 139854.24
E14: Excesso de caixa | F14: =F12-F13 -> 370187.65 | G14: =G12-G13 -> 305868.75 | H14: =H12-H13 -> 317528.15 | I14: =I12-I13 -> 314979.6 | J14: =J12-J13 -> 1407021.9 | K14: =K12-K13 -> 921420.88 | L14: =L12-L13 -> 524496.76
E15: Contas a Receber | F15: 1013011 | G15: 1070690 | H15: 1142836 | I15: 1151484 | J15: 1063844 | K15: 1145336 | L15: 986769
E16: Clientes | F16: 1013011 | G16: 1070690 | H16: 1142836 | I16: 1151484 | J16: 1063844 | K16: 1145336 | L16: 986769
E17: Estoques | F17: 536579 | G17: 479427 | H17: 490614 | I17: 544717 | J17: 641020 | K17: 849269 | L17: 979770
E18: Tributos a Recuperar | F18: 55725 | G18: 72877 | H18: 42847 | I18: 833649 | J18: 282660 | K18: 849115 | L18: 936586
E19: Tributos Correntes a Recuperar | F19: 55725 | G19: 7287 | H19: 42847 | I19: 833649 | J19: 282660 | K19: 849115 | L19: 936586
E20: Outros Ativos Circulantes | F20: 49623 | G20: 70834 | H20: 73266 | I20: 22616 | J20: 23295 | K20: 35387 | L20: 58962
E21: Outros | F21: 49623 | G21: 70834 | H21: 73266 | I21: 22616 | J21: 23295 | K21: 35387 | L21: 58962
E22: Outros Créditos | F22: 13393 | G22: 15968 | H22: 17940 | I22: 21609 | J22: 22933 | K22: 33348 | L22: 58892
E23: Instrumentos Financeiros Derivativos | F23: 35463 | G23: 53835 | H23: 55067 | I23: 651 | J23: 238 | K23: 1535 | L23: 0
E24: Partes Relacionadas | F24: 767 | G24: 1031 | H24: 259 | I24: 356 | J24: 124 | K24: 504 | L24: 70
E25: Ativo Não Circulante | F25: =F26+F34+F38 -> 1486533 | G25: =G26+G34+G38 -> 1268712 | H25: =H26+H34+H38 -> 1282768 | I25: =I26+I34+I38 -> 3037517 | J25: =J26+J34+J38 -> 3789669 | K25: =K26+K34+K38 -> 4743268 | L25: =L26+L34+L38 -> 4629751
E26: Ativo Realizável a Longo Prazo | F26: 546237 | G26: 457050 | H26: 448943 | I26: 624950 | J26: 1313046 | K26: 1291014 | L26: 1266451
E27: Aplicações Financeiras | F27: 0 | G27: 0 | H27: 0 | I27: 0 | J27: 0 | K27: 0 | L27: 3978
E28: Tributos Diferidos | F28: 440059 | G28: 398811 | H28: 370643 | I28: 0 | J28: 71492 | K28: 378803 | L28: 475718
E29: IRPJ + CSLL | F29: 440059 | G29: 398811 | H29: 370643 | I29: 0 | J29: 71492 | K29: 378803 | L29: 475718
E30: Outros Ativos Não Circulantes | F30: 106178 | G30: 58239 | H30: 78300 | I30: 624950 | J30: 1241554 | K30: 904302 | L30: 786637
E31: Tributos a Recuperar | F31: 1727 | G31: 2396 | H31: 7649 | I31: 521136 | J31: 1157357 | K31: 839778 | L31: 720027
E32: Depósito Judicial | F32: 50474 | G32: 52280 | H32: 67748 | I32: 101836 | J32: 81513 | K32: 61937 | L32: 62527
E33: Outros Créditos | F33: 53977 | G33: 3563 | H33: 2903 | I33: 1978 | J33: 2684 | K33: 2587 | L33: 4083
E34: Imobilizado | F34: 780251 | G34: 612572 | H34: 636927 | I34: 2225227 | J34: 2181663 | K34: 2476559 | L34: 2397442
E35: Imobilizado em Operação | F35: 705570 | G35: 588325 | H35: 607408 | I35: 665906 | J35: 651814 | K35: 817978 | L35: 796588
E36: Direito de Uso em Arrendamento | F36: 4736 | G36: 4473 | H36: 4210 | I36: 1507815 | J36: 1514438 | K36: 1640290 | L36: 1576101
E37: Imobilizado em Andamento | F37: 69945 | G37: 19774 | H37: 25309 | I37: 51506 | J37: 15411 | K37: 18291 | L37: 24753
... E39: Intangíveis | F39: 160045 | G39: 199090 | H39: 196898 | I39: 187340 | J39: 294960 | K39: 975695 | L39: 965858
E40: Passivo Total | F40: =F41+F62 -> 2804888 | G40: =G41+G62 -> 2387786 | H40: =H41+H62 -> 2363298 | I40: =I41+I62 -> 3297522 | J40: =J41+J62 -> 4654847 | K40: =K41+K62 -> 5677657 | L40: =L41+L62 -> 5430243
E41: Passivo Circulante | F41: =F42+F44+F47+F52+F55 -> 1746409 | G41: =G42+G44+G47+G52+G55 -> 2022855 | H41: =H42+H44+H47+H52+H55 -> 1750068 | I41: =I42+I44+I47+I52+I55 -> 1751077 | J41: =J42+J44+J47+J52+J55 -> 2251711 | K41: =K42+K44+K47+K52+K55 -> 2415055 | L41: =L42+L44+L47+L52+L55 -> 2381594
E42: Obrigações Sociais e Trabalhistas | F42: 104360 | G42: 136866 | H42: 130922 | I42: 128548 | J42: 136126 | K42: 155470 | L42: 160656
E43: Obrigações Trabalhistas | F43: 104360 | G43: 136866 | H43: 130922 | I43: 128548 | J43: 136126 | K43: 155470 | L43: 160656
E44: Fornecedores | F44: 609005 | G44: 686193 | H44: 678846 | I44: 804013 | J44: 1158914 | K44: 1400736 | L44: 1291227
E45: Nacionais | F45: 607021 | G45: 681917 | H45: 677120 | I45: 803651 | J45: 1151964 | K45: 1400736 | L45: 1291227
E46: Estrangeiros | F46: 1984 | G46: 4276 | H46: 1726 | I46: 362 | J46: 6950 | K46: 0 | L46: 0
E47: Obrigações Fiscais | F47: 173590 | G47: 184184 | H47: 187495 | I47: 219282 | J47: 107276 | K47: 176103 | L47: 91235
...

Sheet Painel de Índices
A7: Páginas
A8: Dashboard
A9: WACC | F9: 2016 | G9: 2017 | H9: 2018 | I9: 2019 | J9: 2020 | K9: 2021 | L9: 1T22
A10: DRE + DCF | E10: Liquidez Geral | F10: ='Balanço Patrimonial'!F10/'Balanço Patrimonial'!F40 -> 1.2945886 | G10: ='Balanço Patrimonial'!G10/'Balanço Patrimonial'!G40 -> 1.4215256 | H10: ='Balanço Patrimonial'!H10/'Balanço Patrimonial'!H40 -> 1.4718148 | I10: ='Balanço Patrimonial'!I10/'Balanço Patrimonial'!I40 -> 1.8307966 | J10: ='Balanço Patrimonial'!J10/'Balanço Patrimonial'!J40 -> 1.5703302 | K10: ='Balanço Patrimonial'!K10/'Balanço Patrimonial'!K40 -> 1.5275009 | L10: ='Balanço Patrimonial'!L10/'Balanço Patrimonial'!L40 -> 1.5204088
A11: Balanço Patrimonial | E11: Liquidez Corrente | F11: ='Balanço Patrimonial'!F11/'Balanço Patrimonial'!F41 -> 1.2280302 | G11: ='Balanço Patrimonial'!G11/'Balanço Patrimonial'!G41 -> 1.0507856 | H11: ='Balanço Patrimonial'!H11/'Balanço Patrimonial'!H41 -> 1.2545621 | I11: ='Balanço Patrimonial'!I11/'Balanço Patrimonial'!I41 -> 1.7129886 | J11: ='Balanço Patrimonial'!J11/'Balanço Patrimonial'!J41 -> 1.5632459 | K11: ='Balanço Patrimonial'!K11/'Balanço Patrimonial'!K41 -> 1.6270263 | L11: ='Balanço Patrimonial'!L11/'Balanço Patrimonial'!L41 -> 1.5226936
A12: Projeções | E12: Liquidez Seca | F12: =('Balanço Patrimonial'!F11-'Balanço Patrimonial'!F17)/'Balanço Patrimonial'!F41 -> 0.92078316 | G12: =('Balanço Patrimonial'!G11-'Balanço Patrimonial'!G17)/'Balanço Patrimonial'!G41 -> 0.81378052 | H12: =('Balanço Patrimonial'!H11-'Balanço Patrimonial'!H17)/'Balanço Patrimonial'!H41 -> 0.97422214 | I12: =('Balanço Patrimonial'!I11-'Balanço Patrimonial'!I17)/'Balanço Patrimonial'!I41 -> 1.4019132 | J12: =('Balanço Patrimonial'!J11-'Balanço Patrimonial'!J17)/'Balanço Patrimonial'!J41 -> 1.2785646 | K12: =('Balanço Patrimonial'!K11-'Balanço Patrimonial'!K17)/'Balanço Patrimonial'!K41 -> 1.2753701 | L12: =('Balanço Patrimonial'!L11-'Balanço Patrimonial'!L17)/'Balanço Patrimonial'!L41 -> 1.1113011
A13: Lojas | E13: Liquidez Imediata | F13: ='Balanço Patrimonial'!F12/'Balanço Patrimonial'!F41 -> 0.28040682 | G13: ='Balanço Patrimonial'!G12/'Balanço Patrimonial'!G41 -> 0.21344041 | H13: ='Balanço Patrimonial'!H12/'Balanço Patrimonial'!H41 -> 0.25485067 | I13: ='Balanço Patrimonial'!I12/'Balanço Patrimonial'!I41 -> 0.25533372 | J13: ='Balanço Patrimonial'!J12/'Balanço Patrimonial'!J41 -> 0.67022766 | K13: ='Balanço Patrimonial'!K12/'Balanço Patrimonial'!K41 -> 0.43487664 | L13: ='Balanço Patrimonial'!L12/'Balanço Patrimonial'!L41 -> 0.27895225
F17: 2016 | G17: 2017 | H17: 2018 | I17: 2019 | J17: 2020 | K17: 2021 | L17: 1T22
E18: Retorno sobre o Equity (ROE) | F18: ='DRE + DCF'!F32/'Balanço Patrimonial'!F82 -> -0.17097186 | G18: ='DRE + DCF'!G32/'Balanço Patrimonial'!G82 -> 0.096253104 | H18: ='DRE + DCF'!H32/'Balanço Patrimonial'!H82 -> 0.15572191 | I18: ='DRE + DCF'!I32/'Balanço Patrimonial'!I82 -> 0.35479765 | J18: ='DRE + DCF'!J32/'Balanço Patrimonial'!J82 -> -0.062653307 | K18: ='DRE + DCF'!K32/'Balanço Patrimonial'!K82 -> 0.10985242 | L18: ='DRE + DCF'!L32*4/'Balanço Patrimonial'!L82 -> -0.21618247
E19: Retorno sobre o Ativo (ROA) | F19: ='DRE + DCF'!F32/'Balanço Patrimonial'!F10 -> -0.038905302 | G19: ='DRE + DCF'!G32/'Balanço Patrimonial'!G10 -> 0.028541976 | H19: ='DRE + DCF'!H32/'Balanço Patrimonial'!H10 -> 0.049919257 | I19: ='DRE + DCF'!I32/'Balanço Patrimonial'!I10 -> 0.16100351 | J19: ='DRE + DCF'!J32/'Balanço Patrimonial'!J10 -> -0.022755134 | K19: ='DRE + DCF'!K32/'Balanço Patrimonial'!K10 -> 0.037936491 | L19: ='DRE + DCF'!L32*4/'Balanço Patrimonial'!L10 -> -0.073995399
E20: ROIC | F20: ='DRE + DCF'!F40/('Balanço Patrimonial'!F57+'Balanço Patrimonial'!F52+'Balanço Patrimonial'!F64+'Balanço Patrimonial'!F65+'Balanço Patrimonial'!F67+'Balanço Patrimonial'!F82-'Balanço Patrimonial'!F14) -> 0.030416282 | G20: ='DRE + DCF'!G40/('Balanço Patrimonial'!G57+'Balanço Patrimonial'!G52+'Balanço Patrimonial'!G64+'Balanço Patrimonial'!G65+'Balanço Patrimonial'!G67+'Balanço Patrimonial'!G82-'Balanço Patrimonial'!G14) -> 0.14977 | H20: ='DRE + DCF'!H40/('Balanço Patrimonial'!H57+'Balanço Patrimonial'!H52+'Balanço Patrimonial'!H64+'Balanço Patrimonial'!H65+'Balanço Patrimonial'!H67+'Balanço Patrimonial'!H82-'Balanço Patrimonial'!H14) -> 0.16679988 | I20: ='DRE + DCF'!I40/('Balanço Patrimonial'!I57+'Balanço Patrimonial'!I52+'Balanço Patrimonial'!I64+'Balanço Patrimonial'!I65+'Balanço Patrimonial'!I67+'Balanço Patrimonial'!I82-'Balanço Patrimonial'!I14) -> 0.14983478 | J20: ='DRE + DCF'!J40/('Balanço Patrimonial'!J57+'Balanço Patrimonial'!J52+'Balanço Patrimonial'!J64+'Balanço Patrimonial'!J65+'Balanço Patrimonial'!J67+'Balanço Patrimonial'!J82-'Balanço Patrimonial'!J14) -> 0.055813151 | K20: ='DRE + DCF'!K40/('Balanço Patrimonial'!K57+'Balanço Patrimonial'!K52+'Balanço Patrimonial'!K64+'Balanço Patrimonial'!K65+'Balanço Patrimonial'!K67+'Balanço Patrimonial'!K82-'Balanço Patrimonial'!K14) -> 0.14265336 | L20: ='DRE + DCF'!L40*4/('Balanço Patrimonial'!L57+'Balanço Patrimonial'!L52+'Balanço Patrimonial'!L64+'Balanço Patrimonial'!L65+'Balanço Patrimonial'!L67+'Balanço Patrimonial'!L82-'Balanço Patrimonial'!L14) -> 0.0070687799
F24: 2016 | G24: 2017 | H24: 2018 | I24: 2019 | J24: 2020 | K24: 2021 | L24: 1T22
E25: Divida Líquida/EBITDA | F25: =('Balanço Patrimonial'!F52+'Balanço Patrimonial'!F63+'Balanço Patrimonial'!F56+'Balanço Patrimonial'!F67-'Balanço Patrimonial'!F12)/('DRE + DCF'!F22+'DRE + DCF'!F44+'DRE + DCF'!F38) -> 4.603121 | G25: =('Balanço Patrimonial'!G52+'Balanço Patrimonial'!G63+'Balanço Patrimonial'!G56+'Balanço Patrimonial'!G67-'Balanço Patrimonial'!G12)/('DRE + DCF'!G22+'DRE + DCF'!G44+'DRE + DCF'!G38) -> 1.1128191 | H25: =('Balanço Patrimonial'!H52+'Balanço Patrimonial'!H63+'Balanço Patrimonial'!H56+'Balanço Patrimonial'!H67-'Balanço Patrimonial'!H12)/('DRE + DCF'!H22+'DRE + DCF'!H44+'DRE + DCF'!H38) -> 1.034838 | I25: =('Balanço Patrimonial'!I52+'Balanço Patrimonial'!I63+'Balanço Patrimonial'!I56+'Balanço Patrimonial'!I67-'Balanço Patrimonial'!I12)/('DRE + DCF'!I22+'DRE + DCF'!I44+'DRE + DCF'!I38) -> 0.77480422 | J25: =('Balanço Patrimonial'!J52+'Balanço Patrimonial'!J63+'Balanço Patrimonial'!J56+'Balanço Patrimonial'!J67-'Balanço Patrimonial'!J12)/('DRE + DCF'!J22+'DRE + DCF'!J44+'DRE + DCF'!J38) -> 3.5818746 | K25: =('Balanço Patrimonial'!K52+'Balanço Patrimonial'!K63+'Balanço Patrimonial'!K56+'Balanço Patrimonial'!K67-'Balanço Patrimonial'!K12)/('DRE + DCF'!K22+'DRE + DCF'!K44+'DRE + DCF'!K38) -> 3.2425647 | L25: =('Balanço Patrimonial'!L52+'Balanço Patrimonial'!L63+'Balanço Patrimonial'!L56+'Balanço Patrimonial'!L67-'Balanço Patrimonial'!L12)/('DRE + DCF'!L22+'DRE + DCF'!L44+'DRE + DCF'!L38)/4 -> 164.6984
E26: Cobertura de Juros | F26: ='DRE + DCF'!F22/'DRE + DCF'!F29 -> 0.010613158 | G26: ='DRE + DCF'!G22/'DRE + DCF'!G29 -> -0.91742268 | H26: ='DRE + DCF'!H22/'DRE + DCF'!H29 -> -1.1242221 | I26: ='DRE + DCF'!I22/'DRE + DCF'!I29 -> -3.664835 | J26: ='DRE + DCF'!J22/'DRE + DCF'!J29 -> 0.72742493 | K26: ='DRE + DCF'!K22/'DRE + DCF'!K29 -> -0.34626636 | L26: ='DRE + DCF'!L22/'DRE + DCF'!L29 -> 1.549351
E27: Dívida/Ativo | F27: =('Balanço Patrimonial'!F52+'Balanço Patrimonial'!F63)/'Balanço Patrimonial'!F10 -> 0.00065873976 | G27: =('Balanço Patrimonial'!G52+'Balanço Patrimonial'!G63)/'Balanço Patrimonial'!G10 -> 0.00062015751 | H27: =('Balanço Patrimonial'!H52+'Balanço Patrimonial'!H63)/'Balanço Patrimonial'!H10 -> 0.00053128837 | I27: =('Balanço Patrimonial'!I52+'Balanço Patrimonial'!I63)/'Balanço Patrimonial'!I10 -> 0.26298754 | J27: =('Balanço Patrimonial'!J52+'Balanço Patrimonial'!J63)/'Balanço Patrimonial'!J10 -> 0.39209116 | K27: =('Balanço Patrimonial'!K52+'Balanço Patrimonial'!K63)/'Balanço Patrimonial'!K10 -> 0.3677057 | L27: =('Balanço Patrimonial'!L52+'Balanço Patrimonial'!L63)/'Balanço Patrimonial'!L10 -> 0.42045416
E28: Dívida/Patrimônio Líquido | F28: =('Balanço Patrimonial'!F53+'Balanço Patrimonial'!F64)/'Balanço Patrimonial'!F82 -> 0.0025475379 | G28: =('Balanço Patrimonial'!G53+'Balanço Patrimonial'!G64)/'Balanço Patrimonial'!G82 -> 0.0018360419 | H28: =('Balanço Patrimonial'!H53+'Balanço Patrimonial'!H64)/'Balanço Patrimonial'!H82 -> 0.0014510703 | I28: =('Balanço Patrimonial'!I53+'Balanço Patrimonial'!I64)/'Balanço Patrimonial'!I82 -> 0.44889855 | J28: =('Balanço Patrimonial'!J53+'Balanço Patrimonial'!J64)/'Balanço Patrimonial'!J82 -> 0.62332115 | K28: =('Balanço Patrimonial'!K53+'Balanço Patrimonial'!K64)/'Balanço Patrimonial'!K82 -> 0.48868067 | L28: =('Balanço Patrimonial'!L53+'Balanço Patrimonial'!L64)/'Balanço Patrimonial'!L82 -> 0.52076367
E29: Dívida/(Dívida + Patrimônio Líquido) | F29: =('Balanço Patrimonial'!F53+'Balanço Patrimonial'!F64)/('Balanço Patrimonial'!F53+'Balanço Patrimonial'!F64+'Balanço Patrimonial'!F82) -> 0.0025410644 | G29: =('Balanço Patrimonial'!G53+'Balanço Patrimonial'!G64)/('Balanço Patrimonial'!G53+'Balanço Patrimonial'!G64+'Balanço Patrimonial'!G82) -> 0.001832677 | H29: =('Balanço Patrimonial'!H53+'Balanço Patrimonial'!H64)/('Balanço Patrimonial'!H53+'Balanço Patrimonial'!H64+'Balanço Patrimonial'!H82) -> 0.0014489678 | I29: =('Balanço Patrimonial'!I53+'Balanço Patrimonial'!I64)/('Balanço Patrimonial'!I53+'Balanço Patrimonial'!I64+'Balanço Patrimonial'!I82) -> 0.30982055 | J29: =('Balanço Patrimonial'!J53+'Balanço Patrimonial'!J64)/('Balanço Patrimonial'!J53+'Balanço Patrimonial'!J64+'Balanço Patrimonial'!J82) -> 0.38397895 | K29: =('Balanço Patrimonial'!K53+'Balanço Patrimonial'!K64)/('Balanço Patrimonial'!K53+'Balanço Patrimonial'!K64+'Balanço Patrimonial'!K82) -> 0.32826427 | L29: =('Balanço Patrimonial'!L53+'Balanço Patrimonial'!L64)/('Balanço Patrimonial'!L53+'Balanço Patrimonial'!L64+'Balanço Patrimonial'!L82) -> 0.34243563
F33: 2016 | G33: 2017 | H33: 2018 | I33: 2019 | J33: 2020 | K33: 2021 | L33: 1T22
E34: Prazo Médio de Recebimento | F34: ='Balanço Patrimonial'!F15*365/'DRE + DCF'!F11 -> 77.342121 | G34: ='Balanço Patrimonial'!G15*365/'DRE + DCF'!G11 -> 77.607648 | H34: ='Balanço Patrimonial'!H15*365/'DRE + DCF'!H11 -> 81.168688 | I34: ='Balanço Patrimonial'!I15*365/'DRE + DCF'!I11 -> 79.522737 | J34: ='Balanço Patrimonial'!J15*365/'DRE + DCF'!J11 -> 95.044521 | K34: ='Balanço Patrimonial'!K15*365/'DRE + DCF'!K11 -> 81.123813 | L34: ='Balanço Patrimonial'!L15*365/'DRE + DCF'!L11/4 -> 75.22211
E35: Prazo Médio de Estoques | F35: ='Balanço Patrimonial'!F17*365/-'DRE + DCF'!F16 -> 97.322656 | G35: ='Balanço Patrimonial'!G17*365/-'DRE + DCF'!G16 -> 82.35542 | H35: ='Balanço Patrimonial'!H17*365/-'DRE + DCF'!H16 -> 81.660045 | I35: ='Balanço Patrimonial'!I17*365/-'DRE + DCF'!I16 -> 129.52326 | J35: ='Balanço Patrimonial'!J17*365/-'DRE + DCF'!J16 -> 113.53111 | K35: ='Balanço Patrimonial'!K17*365/-'DRE + DCF'!K16 -> 134.51154 | L35: ='Balanço Patrimonial'!L17*365/-'DRE + DCF'!L16/4 -> 121.08425
E36: Prazo Médio de Pagamento | F36: =('Balanço Patrimonial'!F44+'Balanço Patrimonial'!F42)*365/-('DRE + DCF'!F13+'DRE + DCF'!F16+'DRE + DCF'!F38+'DRE + DCF'!F44) -> 56.782159 | G36: =('Balanço Patrimonial'!G44+'Balanço Patrimonial'!G42)*365/-('DRE + DCF'!G13+'DRE + DCF'!G16+'DRE + DCF'!G38+'DRE + DCF'!G44) -> 66.156282 | H36: =('Balanço Patrimonial'!H44+'Balanço Patrimonial'!H42)*365/-('DRE + DCF'!H13+'DRE + DCF'!H16+'DRE + DCF'!H38+'DRE + DCF'!H44) -> 64.564898 | I36: =('Balanço Patrimonial'!I44+'Balanço Patrimonial'!I42)*365/-('DRE + DCF'!I13+'DRE + DCF'!I16+'DRE + DCF'!I38+'DRE + DCF'!I44) -> 91.418341 | J36: =('Balanço Patrimonial'!J44+'Balanço Patrimonial'!J42)*365/-('DRE + DCF'!J13+'DRE + DCF'!J16+'DRE + DCF'!J38+'DRE + DCF'!J44) -> 127.85903 | K36: =('Balanço Patrimonial'!K44+'Balanço Patrimonial'!K42)*365/-('DRE + DCF'!K13+'DRE + DCF'!K16+'DRE + DCF'!K38+'DRE + DCF'!K44) -> 126.91866 | L36: =('Balanço Patrimonial'!L44+'Balanço Patrimonial'!L42)*365/-('DRE + DCF'!L13+'DRE + DCF'!L16+'DRE + DCF'!L38+'DRE + DCF'!L44)/4 -> 111.08772
E37: Ciclo de Caixa | F37: =F34+F35-F36 -> 117.88262 | G37: =G34+G35-G36 -> 93.806787 | H37: =H34+H35-H36 -> 98.263835 | I37: =I34+I35-I36 -> 117.62766 | J37: =J34+J35-J36 -> 80.716603 | K37: =K34+K35-K36 -> 88.716693 | L37: =L34+L35-L36 -> 85.218647
F41: 2016 | G41: 2017 | H41: 2018 | I41: 2019 | J41: 2020 | K41: 2021 | L41: 1T22
E42: Proventos por ação | F42: 0 | G42: 0 | H42: 0 | I42: 0.25347738 | J42: 0 | K42: 0 | L42: 0
E43: Dividend Yield (12 meses) | F43: 0 | G43: 0 | H43: 0 | I43: 0.014004275 | J43: 0 | K43: 0 | L43: 0
E44: Payout | F44: 0 | G44: 0 | H44: 0 | I44: 0.08038448 | J44: 0 | K44: 0 | L44: 0

Sheet Provisões e Processos
M1: Remota | N1: Tributário
M2: Possível | N2: Cível
M3: Provável | N3: Trabalhista
N4: Administrativo
A7: Páginas
A8: Dashboard
A9: WACC | F9: Valor dos Processos | G9: Valor das Provisões | H9: Valor de Perdas Possiveis | I9: Valor de Perdas Remotas
A10: DRE + DCF | E10: Tributários | F10: =SUM(G19:G28) -> 604643.85 | G10: 90295.469 | H10: =SUMIF($H$19:$H$28,"Possível",$G$19:$G$28)+16764+8161 -> 282122.01 | I10: =SUMIF($H$19:$H$28,"Remota",$G$19:$G$28) -> 232224.97
A11: Balanço Patrimonial | E11: Cíveis | F11: 0 | G11: 0 | H11: 0 | I11: =F11-G11-H11 -> 0
A12: Provisões e Processos | E12: Trabalhistas | F12: 0 | G12: 0 | H12: 0 | I12: =F12-G12-H12 -> 0
A13: Projeções | E13: Administrativos | F13: 0 | G13: 0 | H13: 0 | I13: =F13-G13-H13 -> 0
A14: Lojas | E14: Total | F14: =SUM(F10:F13) -> 604643.85 | G14: =SUM(G10:G13) -> 90295.469 | H14: =SUM(H10:H13) -> 282122.01 | I14: =SUM(I10:I13) -> 232224.97
E18: Classificação | F18: Descrição | G18: Valor do Processo (R$ mil) | H18: Chance de Perda | I18: Comentário
E19: Tributário | F19: Ação judicial proposta pela Companhia para discutir o direito de fruição da alíquota zero do PIS e da COFINS, prevista pela Lei nº 11.196/2005 (“Lei do Bem”), para a venda a varejo de smartphones produzidos no país. A Companhia foi intimada da instauração de um processo administrativo para inclusão, controle e cobrança dos débitos confessados por meio de declaração. A Companhia ajuizou uma ação com pedido de tutela provisória de urgência, cautelar incidental e/ou tutela de evidência para a antecipação de garantia do débito mediante a apresentação de seguro garantia. | G19: 172197.42 | H19: Possível | I19: Em caso de perda a Companhia, estará sujeita ao pagamento do valor do débito em discussão, devidamente atualizado. Em caso positivo, a Companhia terá direito à restituir os valores indevidamente recolhidos.
E20: Tributário | F20: Ação judicial proposta pela Companhia para discutir o reconhecimento do seu direito líquido e certo de não incluir o valor do ICMS nas bases de cálculo do PIS e da COFINS à luz da Lei nº 12.973/14, a partir da sua vigência. | G20: 232224.97 | H20: Remota | I20: 0
E21: Tributário | F21: Trata-se de processo administrativo fiscal relativo a cobrança de contribuições previdenciárias incidentes sobre valores pagos a título de Assistência Médica e Hospitalar a seus funcionários e empregados segurados, dos períodos de 12/12/1997 e 28/02/2005. | G21: 8130.6528 | H21: Possível | I21: -
E22: Tributário | F22: Trata-se de Execução Fiscal ajuizada pela União, objetivando a cobrança de supostos créditos tributários inscritos nas Certidões de Dívida Ativa nº. 80.6.15.071746-61 e 80.7.15.017496-78, oriundos da não homologação das compensações relacionadas ao Processo Administrativo de Compensação nº 13896.722.554/2011-37, realizadas pela empresa para compensar débitos de PIS/COFINS com crédito decorrente de valores pagos indevidamente a título de PIS e COFINS sobre receitas de terceiros, referente ao ano-calendário de 2008. | G22: 17071.171 | H22: Possível | I22: 0
E23: Tributário | F23: Trata-se de pedido de compensação, em razão de pagamento indevido ou a maior de COFINS, relativo ao mês de agosto de 2012 e recolhido em 25/09/13, compensado com débito do mesmo tributo (cód. 5856-01), referente ao período de apuração de setembro de 2012, com vencimento em 25/10/2012. | G23: 14985.83 | H23: Possível | I23: 0
E24: Tributário | F24: Trata-se de processo administrativo decorrente ao Auto de Infração que visa à cobrança de Imposto sobre Importação, PIS/PASEP Importação e COFINS Importação ante a não inclusão de Royalties pagos por uso de marcas licenciadas, na base de cálculo de mercadorias importadas em 2012. | G24: 14082.918 | H24: Possível | I24: 0
E25: Tributário | F25: Trata-se de processo administrativo fiscal federal relativo a PIS e COFINS sobre frete de transferência, taxa de cartão de crédito, propaganda e publicidade, mão de obra temporário, energia elétrica, ajustes positivos de créditos e despesas de aluguéis de imóveis. | G25: 59142.234 | H25: Provável | I25: Chance de perda possível de R$ 16.764 e provável de R$ 42.377.
E26: Tributário | F26: Trata-se de processo administrativo fiscal federal relativo a PIS e COFINS sobre taxa de frete, mão de obra temporária, aquisição de cabides, aquisição de embalagens, cartão de terceiros, cartão PL, propaganda de televisão, jornal, rádio e contratos exclusivos de propaganda. | G26: 39331.939 | H26: Provável | I26: Chance de perda possível de R$ 8.161 e provável de R$ 31.170.
E27: Tributário | F27: Trata-se de Ação Ordinária na qual se busca afastar o recolhimento da Contribuição instituída pelo ar. 1º da LC nº. 110/01, bem como a repetição dos valores indevidamente recolhidos no curso da ação ora ajuizada e nos 5 anos anteriores à propositura da demanda. | G27: 16747.701 | H27: Provável | I27: 0
E28: Tributário | F28: Trata-se de Mandado de Segurança impetrado para assegurar o direito líquido e certo da Impetrante excluir o ICMS e o ISS da base de cálculo da Contribuição Previdenciária Substitutiva (Lei nº 12.546/2011), bem como o seu direito de crédito, no que concerne aos pagamentos indevidamente realizados àquele título nos últimos 5 (cinco) anos. | G28: 30729.018 | H28: Possível | I28: 0

Sheet Projeções - Receita
L4: C&A (CEAB3)
A7: Páginas
A8: Dashboard
A9: WACC | F9: 2016 | G9: 2017 | H9: 2018 | I9: 2019 | J9: 2020 | K9: 2021 | L9: 2022 | M9: 2023 | N9: 2024 | O9: 2025 | P9: =O9+1 -> 2026 | Q9: =P9+1 -> 2027 | R9: =Q9+1 -> 2028 | S9: CAGR (16 - 19) | T9: Premissa | U9: Nível de Otimismo (0-5)
A10: DRE + DCF | E10: Receita Total | F10: ='DRE + DCF'!F11 -> 4780694 | G10: ='DRE + DCF'!G11 -> 5035610 | H10: ='DRE + DCF'!H11 -> 5139114 | I10: =I11+I12+I14 -> 5285178 | J10: ='DRE + DCF'!J11 -> 4085486 | K10: =K11+K12+K14 -> 5153206 | L10: =L11+L12+L14 -> 5594169.6 | M10: =M11+M12+M14 -> 6643601.4 | N10: =N11+N12+N14 -> 7910445.7 | O10: =O11+O12+O14 -> 9223569.7 | P10: =P11+P12+P14 -> 10319264 | Q10: =Q11+Q12+Q14 -> 11455213 | R10: =R11+R12+R14 -> 12401748 | S10: =(I10/F10)^(1/COUNT($G$9:$I$9))-1 -> 0.0340056
