Workbook
Name _1_2: #REF!
Name _2: #REF!
Name a: #REF!
Name CotacoesTodosAtivos_3: #REF!
Name default_2: #REF!

Sheet Posições
A1: 4.6 | B1: Controle de Operações Swing Trade - Posições
B2: Gerenciamento de Risco | F2: Gerenciamento de Capital
B3: Campo | D3: Valor | F3: Capital Total | H3: =SUM(Metas!C36,Resultados!$H$4:$H$951) -> 271996.18
B4: Relação RxG (Parcial) | F4: Ordens Inseridas | H4: =IF(SUM(Posições!$M$17:$M$162)=0,"0",SUM(Posições!$M$17:$M$162)) -> 182536
B5: Saída Parcial (Qtde.) | F5: Ordens Executadas | H5: =SUMIFS(Posições!$O$17:$O$47,Posições!$K$17:$K$47,"<>") -> 29166
B6: Relação RxG (Final) | F6: Poder de Compra/Venda | H6: =H3-H4 -> 89460.184
B7: Capital por Operação | F7: Exposição Total | H7: =IF(ISBLANK(H3),"",IF(SUM(Posições!$N$17:$N$47)=0,"0,0%",SUM(Posições!$N$17:$N$47))) -> 0.012356791
B8: Risco Carteira (%) | F8: Stop Gain Projetado Total | H8: =SUMIFS(Posições!$O$17:$O$47,Posições!$K$17:$K$47,"<>") -> 29166
B9: Exposição Total | F9: Stop Loss Projetado Total | H9: =SUMIFS(Posições!$P$17:$P$36,Posições!$K$17:$K$36,"<>") -> -3361
B11: Calculadora de Saídas & Tamanho de Lote
B12: Tipo | C12: Entrada | D12: Stop Loss | E12: Saída Parcial | F12: Saída Final | G12: Qtde. Parcial | H12: Qtde. Final | I12: Qtde. Total
B13: Ação | E13: =IF(OR(ISBLANK(C13),ISBLANK(D13)),"",IF(AND(D4<>"",D5<>""),((C13-D13)*D4)+C13,"")) | F13: =IF(OR(ISBLANK(C13),ISBLANK(D13)),"",IF(D6<>"",((C13-D13)*D6)+C13,"")) | G13: =IFERROR(IF(OR(I13=10,I13=100),0, IF(AND(B13="Ação",C13<>"",D13<>""),MROUND(I13*D5,100), IF(AND(B13="ETF",C13<>"",D13<>""),MROUND(I13*D5,10),""))),"") | H13: =IFERROR(I13-G13,"") | I13: =IFERROR(IF(B13="Ação",IF(OR(Dados!L5=0,Dados!L6=0),"LIMITE",SMALL(Dados!L5:L6,1)),IF(B13="ETF",IF(OR(Dados!M5=0,Dados!M6=0),"LIMITE",SMALL(Dados!M5:M6,1)),)),"")
B15: Operações Ativas
B16: Compra ou Venda | C16: Ativo | D16: Qtde. | E16: Preço Entrada | F16: Stop Loss | G16: Saída Parcial | H16: Saída Final | I16: Data Execução | J16: Preço Atual | K16: Resultado % | L16: Resultado R$ | M16: Total da Operação | N16: Risco Carteira | O16: Stop Gain Projetado | P16: Stop Loss Projetado
B17: Compra | C17: CIEL3 | D17: 2500 | E17: 4.03 | F17: 5.24 | H17: 6.89 | I17: 44750 | K17: =IFERROR(IF(ISBLANK(Posições!$I17),"",IF(Posições!$B17="Compra",Posições!$J17/Posições!$E17-1,IF(Posições!$B17="Venda",Posições!$J17/Posições!$E17-1,""))),"") -> -1 | L17: =IFERROR(IF(ISBLANK(Posições!$I17),"",IF(Posições!$B17="Compra",Posições!$J17*Posições!$D17-Posições!$M17,IF(Posições!$B17="Venda",Posições!$M17-Posições!$J17*Posições!$D17,""))),"") -> -10075 | M17: =IF(OR(ISBLANK(Posições!$D17),ISBLANK(Posições!$E17)),"",Posições!$D17*Posições!$E17) -> 10075 | N17: =IF(OR(ISBLANK($H$3),ISBLANK(Posições!$B17),ISBLANK(Posições!$D17),ISBLANK(Posições!$E17),ISBLANK(Posições!$F17)),"",IF(Posições!$B17="Compra",(Posições!$E17-Posições!$F17)*Posições!$D17/$H$3,(Posições!$F17-Posições!$E17)*Posições!$D17/$H$3)) -> -0.01112148 | O17: =IF(AND(Posições!$G17<>"",Posições!$I17<>""),ABS(Posições!$G17-Posições!$E17)*Posições!$D17,0)+IF(AND(Posições!$H17<>"",Posições!$I17<>""),ABS(Posições!$H17-Posições!$E17)*Posições!$D17,0) -> 7150 | P17: =IF(AND(Posições!$B17="Compra",Posições!$I17<>""),(Posições!$F17-Posições!$E17)*Posições!$D17,IF(AND(Posições!$B17="Venda",Posições!$I17<>""),(Posições!$E17-Posições!$F17)*Posições!$D17,"")) -> 3025
B18: Compra | C18: ALUP11 | D18: 500 | E18: 27.27 | F18: 27.99 | H18: 30.72 | I18: 44767 | K18: =IFERROR(IF(ISBLANK(Posições!$I18),"",IF(Posições!$B18="Compra",Posições!$J18/Posições!$E18-1,IF(Posições!$B18="Venda",Posições!$J18/Posições!$E18-1,""))),"") -> -1 | L18: =IFERROR(IF(ISBLANK(Posições!$I18),"",IF(Posições!$B18="Compra",Posições!$J18*Posições!$D18-Posições!$M18,IF(Posições!$B18="Venda",Posições!$M18-Posições!$J18*Posições!$D18,""))),"") -> -13635 | M18: =IF(OR(ISBLANK(Posições!$D18),ISBLANK(Posições!$E18)),"",Posições!$D18*Posições!$E18) -> 13635 | N18: =IF(OR(ISBLANK($H$3),ISBLANK(Posições!$B18),ISBLANK(Posições!$D18),ISBLANK(Posições!$E18),ISBLANK(Posições!$F18)),"",IF(Posições!$B18="Compra",(Posições!$E18-Posições!$F18)*Posições!$D18/$H$3,(Posições!$F18-Posições!$E18)*Posições!$D18/$H$3)) -> -0.001323548 | O18: =IF(AND(Posições!$G18<>"",Posições!$I18<>""),ABS(Posições!$G18-Posições!$E18)*Posições!$D18,0)+IF(AND(Posições!$H18<>"",Posições!$I18<>""),ABS(Posições!$H18-Posições!$E18)*Posições!$D18,0) -> 1725 | P18: =IF(AND(Posições!$B18="Compra",Posições!$I18<>""),(Posições!$F18-Posições!$E18)*Posições!$D18,IF(AND(Posições!$B18="Venda",Posições!$I18<>""),(Posições!$E18-Posições!$F18)*Posições!$D18,"")) -> 360
B19: Compra | C19: ABCB4 | D19: 700 | E19: 17.18 | F19: 18.59 | H19: 20.15 | I19: 44770 | K19: =IFERROR(IF(ISBLANK(Posições!$I19),"",IF(Posições!$B19="Compra",Posições!$J19/Posições!$E19-1,IF(Posições!$B19="Venda",Posições!$J19/Posições!$E19-1,""))),"") -> -1 | L19: =IFERROR(IF(ISBLANK(Posições!$I19),"",IF(Posições!$B19="Compra",Posições!$J19*Posições!$D19-Posições!$M19,IF(Posições!$B19="Venda",Posições!$M19-Posições!$J19*Posições!$D19,""))),"") -> -12026 | M19: =IF(OR(ISBLANK(Posições!$D19),ISBLANK(Posições!$E19)),"",Posições!$D19*Posições!$E19) -> 12026 | N19: =IF(OR(ISBLANK($H$3),ISBLANK(Posições!$B19),ISBLANK(Posições!$D19),ISBLANK(Posições!$E19),ISBLANK(Posições!$F19)),"",IF(Posições!$B19="Compra",(Posições!$E19-Posições!$F19)*Posições!$D19/$H$3,(Posições!$F19-Posições!$E19)*Posições!$D19/$H$3)) -> -0.0036287274 | O19: =IF(AND(Posições!$G19<>"",Posições!$I19<>""),ABS(Posições!$G19-Posições!$E19)*Posições!$D19,0)+IF(AND(Posições!$H19<>"",Posições!$I19<>""),ABS(Posições!$H19-Posições!$E19)*Posições!$D19,0) -> 2079 | P19: =IF(AND(Posições!$B19="Compra",Posições!$I19<>""),(Posições!$F19-Posições!$E19)*Posições!$D19,IF(AND(Posições!$B19="Venda",Posições!$I19<>""),(Posições!$E19-Posições!$F19)*Posições!$D19,"")) -> 987
B20: Compra | C20: ABEV3 | D20: 800 | E20: 15.06 | F20: 15.19 | H20: 17.22 | I20: 44783 | K20: =IFERROR(IF(ISBLANK(Posições!$I20),"",IF(Posições!$B20="Compra",Posições!$J20/Posições!$E20-1,IF(Posições!$B20="Venda",Posições!$J20/Posições!$E20-1,""))),"") -> -1 | L20: =IFERROR(IF(ISBLANK(Posições!$I20),"",IF(Posições!$B20="Compra",Posições!$J20*Posições!$D20-Posições!$M20,IF(Posições!$B20="Venda",Posições!$M20-Posições!$J20*Posições!$D20,""))),"") -> -12048 | M20: =IF(OR(ISBLANK(Posições!$D20),ISBLANK(Posições!$E20)),"",Posições!$D20*Posições!$E20) -> 12048 | N20: =IF(OR(ISBLANK($H$3),ISBLANK(Posições!$B20),ISBLANK(Posições!$D20),ISBLANK(Posições!$E20),ISBLANK(Posições!$F20)),"",IF(Posições!$B20="Compra",(Posições!$E20-Posições!$F20)*Posições!$D20/$H$3,(Posições!$F20-Posições!$E20)*Posições!$D20/$H$3)) -> -0.00038235831 | O20: =IF(AND(Posições!$G20<>"",Posições!$I20<>""),ABS(Posições!$G20-Posições!$E20)*Posições!$D20,0)+IF(AND(Posições!$H20<>"",Posições!$I20<>""),ABS(Posições!$H20-Posições!$E20)*Posições!$D20,0) -> 1728 | P20: =IF(AND(Posições!$B20="Compra",Posições!$I20<>""),(Posições!$F20-Posições!$E20)*Posições!$D20,IF(AND(Posições!$B20="Venda",Posições!$I20<>""),(Posições!$E20-Posições!$F20)*Posições!$D20,"")) -> 104
B21: Compra | C21: KLBN11 | D21: 500 | E21: 20.07 | F21: 19.69 | H21: 23.03 | I21: 44785 | K21: =IFERROR(IF(ISBLANK(Posições!$I21),"",IF(Posições!$B21="Compra",Posições!$J21/Posições!$E21-1,IF(Posições!$B21="Venda",Posições!$J21/Posições!$E21-1,""))),"") -> -1 | L21: =IFERROR(IF(ISBLANK(Posições!$I21),"",IF(Posições!$B21="Compra",Posições!$J21*Posições!$D21-Posições!$M21,IF(Posições!$B21="Venda",Posições!$M21-Posições!$J21*Posições!$D21,""))),"") -> -10035 | M21: =IF(OR(ISBLANK(Posições!$D21),ISBLANK(Posições!$E21)),"",Posições!$D21*Posições!$E21) -> 10035 | N21: =IF(OR(ISBLANK($H$3),ISBLANK(Posições!$B21),ISBLANK(Posições!$D21),ISBLANK(Posições!$E21),ISBLANK(Posições!$F21)),"",IF(Posições!$B21="Compra",(Posições!$E21-Posições!$F21)*Posições!$D21/$H$3,(Posições!$F21-Posições!$E21)*Posições!$D21/$H$3)) -> 0.00069853921 | O21: =IF(AND(Posições!$G21<>"",Posições!$I21<>""),ABS(Posições!$G21-Posições!$E21)*Posições!$D21,0)+IF(AND(Posições!$H21<>"",Posições!$I21<>""),ABS(Posições!$H21-Posições!$E21)*Posições!$D21,0) -> 1480 | P21: =IF(AND(Posições!$B21="Compra",Posições!$I21<>""),(Posições!$F21-Posições!$E21)*Posições!$D21,IF(AND(Posições!$B21="Venda",Posições!$I21<>""),(Posições!$E21-Posições!$F21)*Posições!$D21,"")) -> -190
B22: Compra | C22: RADL3 | D22: 500 | E22: 23.02 | F22: 22.18 | G22: 24.31 | I22: 44790 | K22: =IFERROR(IF(ISBLANK(Posições!$I22),"",IF(Posições!$B22="Compra",Posições!$J22/Posições!$E22-1,IF(Posições!$B22="Venda",Posições!$J22/Posições!$E22-1,""))),"") -> -1 | L22: =IFERROR(IF(ISBLANK(Posições!$I22),"",IF(Posições!$B22="Compra",Posições!$J22*Posições!$D22-Posições!$M22,IF(Posições!$B22="Venda",Posições!$M22-Posições!$J22*Posições!$D22,""))),"") -> -11510 | M22: =IF(OR(ISBLANK(Posições!$D22),ISBLANK(Posições!$E22)),"",Posições!$D22*Posições!$E22) -> 11510 | N22: =IF(OR(ISBLANK($H$3),ISBLANK(Posições!$B22),ISBLANK(Posições!$D22),ISBLANK(Posições!$E22),ISBLANK(Posições!$F22)),"",IF(Posições!$B22="Compra",(Posições!$E22-Posições!$F22)*Posições!$D22/$H$3,(Posições!$F22-Posições!$E22)*Posições!$D22/$H$3)) -> 0.0015441393 | O22: =IF(AND(Posições!$G22<>"",Posições!$I22<>""),ABS(Posições!$G22-Posições!$E22)*Posições!$D22,0)+IF(AND(Posições!$H22<>"",Posições!$I22<>""),ABS(Posições!$H22-Posições!$E22)*Posições!$D22,0) -> 645 | P22: =IF(AND(Posições!$B22="Compra",Posições!$I22<>""),(Posições!$F22-Posições!$E22)*Posições!$D22,IF(AND(Posições!$B22="Venda",Posições!$I22<>""),(Posições!$E22-Posições!$F22)*Posições!$D22,"")) -> -420
B23: Compra | C23: RADL3 | D23: 400 | E23: 23.02 | F23: 22.18 | H23: 26.89 | I23: 44790 | K23: =IFERROR(IF(ISBLANK(Posições!$I23),"",IF(Posições!$B23="Compra",Posições!$J23/Posições!$E23-1,IF(Posições!$B23="Venda",Posições!$J23/Posições!$E23-1,""))),"") -> -1 | L23: =IFERROR(IF(ISBLANK(Posições!$I23),"",IF(Posições!$B23="Compra",Posições!$J23*Posições!$D23-Posições!$M23,IF(Posições!$B23="Venda",Posições!$M23-Posições!$J23*Posições!$D23,""))),"") -> -9208 | M23: =IF(OR(ISBLANK(Posições!$D23),ISBLANK(Posições!$E23)),"",Posições!$D23*Posições!$E23) -> 9208 | N23: =IF(OR(ISBLANK($H$3),ISBLANK(Posições!$B23),ISBLANK(Posições!$D23),ISBLANK(Posições!$E23),ISBLANK(Posições!$F23)),"",IF(Posições!$B23="Compra",(Posições!$E23-Posições!$F23)*Posições!$D23/$H$3,(Posições!$F23-Posições!$E23)*Posições!$D23/$H$3)) -> 0.0012353114 | O23: =IF(AND(Posições!$G23<>"",Posições!$I23<>""),ABS(Posições!$G23-Posições!$E23)*Posições!$D23,0)+IF(AND(Posições!$H23<>"",Posições!$I23<>""),ABS(Posições!$H23-Posições!$E23)*Posições!$D23,0) -> 1548 | P23: =IF(AND(Posições!$B23="Compra",Posições!$I23<>""),(Posições!$F23-Posições!$E23)*Posições!$D23,IF(AND(Posições!$B23="Venda",Posições!$I23<>""),(Posições!$E23-Posições!$F23)*Posições!$D23,"")) -> -336
B24: Compra | C24: ODPV3 | D24: 900 | E24: 10.22 | F24: 9.69 | G24: 10.75 | I24: 44795 | K24: =IFERROR(IF(ISBLANK(Posições!$I24),"",IF(Posições!$B24="Compra",Posições!$J24/Posições!$E24-1,IF(Posições!$B24="Venda",Posições!$J24/Posições!$E24-1,""))),"") -> -1 | L24: =IFERROR(IF(ISBLANK(Posições!$I24),"",IF(Posições!$B24="Compra",Posições!$J24*Posições!$D24-Posições!$M24,IF(Posições!$B24="Venda",Posições!$M24-Posições!$J24*Posições!$D24,""))),"") -> -9198 | M24: =IF(OR(ISBLANK(Posições!$D24),ISBLANK(Posições!$E24)),"",Posições!$D24*Posições!$E24) -> 9198 | N24: =IF(OR(ISBLANK($H$3),ISBLANK(Posições!$B24),ISBLANK(Posições!$D24),ISBLANK(Posições!$E24),ISBLANK(Posições!$F24)),"",IF(Posições!$B24="Compra",(Posições!$E24-Posições!$F24)*Posições!$D24/$H$3,(Posições!$F24-Posições!$E24)*Posições!$D24/$H$3)) -> 0.0017537011 | O24: =IF(AND(Posições!$G24<>"",Posições!$I24<>""),ABS(Posições!$G24-Posições!$E24)*Posições!$D24,0)+IF(AND(Posições!$H24<>"",Posições!$I24<>""),ABS(Posições!$H24-Posições!$E24)*Posições!$D24,0) -> 477 | P24: =IF(AND(Posições!$B24="Compra",Posições!$I24<>""),(Posições!$F24-Posições!$E24)*Posições!$D24,IF(AND(Posições!$B24="Venda",Posições!$I24<>""),(Posições!$E24-Posições!$F24)*Posições!$D24,"")) -> -477
B25: Compra | C25: ODPV3 | D25: 900 | E25: 10.22 | F25: 9.69 | H25: 11.81 | I25: 44795 | K25: =IFERROR(IF(ISBLANK(Posições!$I25),"",IF(Posições!$B25="Compra",Posições!$J25/Posições!$E25-1,IF(Posições!$B25="Venda",Posições!$J25/Posições!$E25-1,""))),"") -> -1 | L25: =IFERROR(IF(ISBLANK(Posições!$I25),"",IF(Posições!$B25="Compra",Posições!$J25*Posições!$D25-Posições!$M25,IF(Posições!$B25="Venda",Posições!$M25-Posições!$J25*Posições!$D25,""))),"") -> -9198 | M25: =IF(OR(ISBLANK(Posições!$D25),ISBLANK(Posições!$E25)),"",Posições!$D25*Posições!$E25) -> 9198 | N25: =IF(OR(ISBLANK($H$3),ISBLANK(Posições!$B25),ISBLANK(Posições!$D25),ISBLANK(Posições!$E25),ISBLANK(Posições!$F25)),"",IF(Posições!$B25="Compra",(Posições!$E25-Posições!$F25)*Posições!$D25/$H$3,(Posições!$F25-Posições!$E25)*Posições!$D25/$H$3)) -> 0.0017537011 | O25: =IF(AND(Posições!$G25<>"",Posições!$I25<>""),ABS(Posições!$G25-Posições!$E25)*Posições!$D25,0)+IF(AND(Posições!$H25<>"",Posições!$I25<>""),ABS(Posições!$H25-Posições!$E25)*Posições!$D25,0) -> 1431 | P25: =IF(AND(Posições!$B25="Compra",Posições!$I25<>""),(Posições!$F25-Posições!$E25)*Posições!$D25,IF(AND(Posições!$B25="Venda",Posições!$I25<>""),(Posições!$E25-Posições!$F25)*Posições!$D25,"")) -> -477
B26: Venda | C26: VALE3 | D26: 200 | E26: 66.35 | F26: 70.55 | G26: 62.15 | I26: 44795 | K26: =IFERROR(IF(ISBLANK(Posições!$I26),"",IF(Posições!$B26="Compra",Posições!$J26/Posições!$E26-1,IF(Posições!$B26="Venda",Posições!$J26/Posições!$E26-1,""))),"") -> -1 | L26: =IFERROR(IF(ISBLANK(Posições!$I26),"",IF(Posições!$B26="Compra",Posições!$J26*Posições!$D26-Posições!$M26,IF(Posições!$B26="Venda",Posições!$M26-Posições!$J26*Posições!$D26,""))),"") -> 13270 | M26: =IF(OR(ISBLANK(Posições!$D26),ISBLANK(Posições!$E26)),"",Posições!$D26*Posições!$E26) -> 13270 | N26: =IF(OR(ISBLANK($H$3),ISBLANK(Posições!$B26),ISBLANK(Posições!$D26),ISBLANK(Posições!$E26),ISBLANK(Posições!$F26)),"",IF(Posições!$B26="Compra",(Posições!$E26-Posições!$F26)*Posições!$D26/$H$3,(Posições!$F26-Posições!$E26)*Posições!$D26/$H$3)) -> 0.0030882786 | O26: =IF(AND(Posições!$G26<>"",Posições!$I26<>""),ABS(Posições!$G26-Posições!$E26)*Posições!$D26,0)+IF(AND(Posições!$H26<>"",Posições!$I26<>""),ABS(Posições!$H26-Posições!$E26)*Posições!$D26,0) -> 840 | P26: =IF(AND(Posições!$B26="Compra",Posições!$I26<>""),(Posições!$F26-Posições!$E26)*Posições!$D26,IF(AND(Posições!$B26="Venda",Posições!$I26<>""),(Posições!$E26-Posições!$F26)*Posições!$D26,"")) -> -840
B27: Venda | C27: VALE3 | D27: 200 | E27: 66.35 | F27: 70.55 | H27: 53.75 | I27: 44795 | K27: =IFERROR(IF(ISBLANK(Posições!$I27),"",IF(Posições!$B27="Compra",Posições!$J27/Posições!$E27-1,IF(Posições!$B27="Venda",Posições!$J27/Posições!$E27-1,""))),"") -> -1 | L27: =IFERROR(IF(ISBLANK(Posições!$I27),"",IF(Posições!$B27="Compra",Posições!$J27*Posições!$D27-Posições!$M27,IF(Posições!$B27="Venda",Posições!$M27-Posições!$J27*Posições!$D27,""))),"") -> 13270 | M27: =IF(OR(ISBLANK(Posições!$D27),ISBLANK(Posições!$E27)),"",Posições!$D27*Posições!$E27) -> 13270 | N27: =IF(OR(ISBLANK($H$3),ISBLANK(Posições!$B27),ISBLANK(Posições!$D27),ISBLANK(Posições!$E27),ISBLANK(Posições!$F27)),"",IF(Posições!$B27="Compra",(Posições!$E27-Posições!$F27)*Posições!$D27/$H$3,(Posições!$F27-Posições!$E27)*Posições!$D27/$H$3)) -> 0.0030882786 | O27: =IF(AND(Posições!$G27<>"",Posições!$I27<>""),ABS(Posições!$G27-Posições!$E27)*Posições!$D27,0)+IF(AND(Posições!$H27<>"",Posições!$I27<>""),ABS(Posições!$H27-Posições!$E27)*Posições!$D27,0) -> 2520 | P27: =IF(AND(Posições!$B27="Compra",Posições!$I27<>""),(Posições!$F27-Posições!$E27)*Posições!$D27,IF(AND(Posições!$B27="Venda",Posições!$I27<>""),(Posições!$E27-Posições!$F27)*Posições!$D27,"")) -> -840
B28: Compra | C28: ARZZ3 | D28: 200 | E28: 91.02 | F28: 85.99 | G28: 96.05 | I28: 44797 | K28: =IFERROR(IF(ISBLANK(Posições!$I28),"",IF(Posições!$B28="Compra",Posições!$J28/Posições!$E28-1,IF(Posições!$B28="Venda",Posições!$J28/Posições!$E28-1,""))),"") -> -1 | L28: =IFERROR(IF(ISBLANK(Posições!$I28),"",IF(Posições!$B28="Compra",Posições!$J28*Posições!$D28-Posições!$M28,IF(Posições!$B28="Venda",Posições!$M28-Posições!$J28*Posições!$D28,""))),"") -> -18204 | M28: =IF(OR(ISBLANK(Posições!$D28),ISBLANK(Posições!$E28)),"",Posições!$D28*Posições!$E28) -> 18204 | N28: =IF(OR(ISBLANK($H$3),ISBLANK(Posições!$B28),ISBLANK(Posições!$D28),ISBLANK(Posições!$E28),ISBLANK(Posições!$F28)),"",IF(Posições!$B28="Compra",(Posições!$E28-Posições!$F28)*Posições!$D28/$H$3,(Posições!$F28-Posições!$E28)*Posições!$D28/$H$3)) -> 0.0036985813 | O28: =IF(AND(Posições!$G28<>"",Posições!$I28<>""),ABS(Posições!$G28-Posições!$E28)*Posições!$D28,0)+IF(AND(Posições!$H28<>"",Posições!$I28<>""),ABS(Posições!$H28-Posições!$E28)*Posições!$D28,0) -> 1006 | P28: =IF(AND(Posições!$B28="Compra",Posições!$I28<>""),(Posições!$F28-Posições!$E28)*Posições!$D28,IF(AND(Posições!$B28="Venda",Posições!$I28<>""),(Posições!$E28-Posições!$F28)*Posições!$D28,"")) -> -1006
B29: Compra | C29: ARZZ3 | D29: 100 | E29: 91.02 | F29: 85.99 | H29: 106.11 | I29: 44797 | K29: =IFERROR(IF(ISBLANK(Posições!$I29),"",IF(Posições!$B29="Compra",Posições!$J29/Posições!$E29-1,IF(Posições!$B29="Venda",Posições!$J29/Posições!$E29-1,""))),"") -> -1 | L29: =IFERROR(IF(ISBLANK(Posições!$I29),"",IF(Posições!$B29="Compra",Posições!$J29*Posições!$D29-Posições!$M29,IF(Posições!$B29="Venda",Posições!$M29-Posições!$J29*Posições!$D29,""))),"") -> -9102 | M29: =IF(OR(ISBLANK(Posições!$D29),ISBLANK(Posições!$E29)),"",Posições!$D29*Posições!$E29) -> 9102 | N29: =IF(OR(ISBLANK($H$3),ISBLANK(Posições!$B29),ISBLANK(Posições!$D29),ISBLANK(Posições!$E29),ISBLANK(Posições!$F29)),"",IF(Posições!$B29="Compra",(Posições!$E29-Posições!$F29)*Posições!$D29/$H$3,(Posições!$F29-Posições!$E29)*Posições!$D29/$H$3)) -> 0.0018492906 | O29: =IF(AND(Posições!$G29<>"",Posições!$I29<>""),ABS(Posições!$G29-Posições!$E29)*Posições!$D29,0)+IF(AND(Posições!$H29<>"",Posições!$I29<>""),ABS(Posições!$H29-Posições!$E29)*Posições!$D29,0) -> 1509 | P29: =IF(AND(Posições!$B29="Compra",Posições!$I29<>""),(Posições!$F29-Posições!$E29)*Posições!$D29,IF(AND(Posições!$B29="Venda",Posições!$I29<>""),(Posições!$E29-Posições!$F29)*Posições!$D29,"")) -> -503
B30: Compra | C30: MODL11 | D30: 600 | E30: 9.27 | F30: 8.14 | G30: 10.4 | I30: 44797 | K30: =IFERROR(IF(ISBLANK(Posições!$I30),"",IF(Posições!$B30="Compra",Posições!$J30/Posições!$E30-1,IF(Posições!$B30="Venda",Posições!$J30/Posições!$E30-1,""))),"") -> -1 | L30: =IFERROR(IF(ISBLANK(Posições!$I30),"",IF(Posições!$B30="Compra",Posições!$J30*Posições!$D30-Posições!$M30,IF(Posições!$B30="Venda",Posições!$M30-Posições!$J30*Posições!$D30,""))),"") -> -5562 | M30: =IF(OR(ISBLANK(Posições!$D30),ISBLANK(Posições!$E30)),"",Posições!$D30*Posições!$E30) -> 5562 | N30: =IF(OR(ISBLANK($H$3),ISBLANK(Posições!$B30),ISBLANK(Posições!$D30),ISBLANK(Posições!$E30),ISBLANK(Posições!$F30)),"",IF(Posições!$B30="Compra",(Posições!$E30-Posições!$F30)*Posições!$D30/$H$3,(Posições!$F30-Posições!$E30)*Posições!$D30/$H$3)) -> 0.002492682 | O30: =IF(AND(Posições!$G30<>"",Posições!$I30<>""),ABS(Posições!$G30-Posições!$E30)*Posições!$D30,0)+IF(AND(Posições!$H30<>"",Posições!$I30<>""),ABS(Posições!$H30-Posições!$E30)*Posições!$D30,0) -> 678 | P30: =IF(AND(Posições!$B30="Compra",Posições!$I30<>""),(Posições!$F30-Posições!$E30)*Posições!$D30,IF(AND(Posições!$B30="Venda",Posições!$I30<>""),(Posições!$E30-Posições!$F30)*Posições!$D30,"")) -> -678
B31: Compra | C31: MODL11 | D31: 500 | E31: 9.27 | F31: 8.14 | H31: 12.66 | I31: 44797 | K31: =IFERROR(IF(ISBLANK(Posições!$I31),"",IF(Posições!$B31="Compra",Posições!$J31/Posições!$E31-1,IF(Posições!$B31="Venda",Posições!$J31/Posições!$E31-1,""))),"") -> -1 | L31: =IFERROR(IF(ISBLANK(Posições!$I31),"",IF(Posições!$B31="Compra",Posições!$J31*Posições!$D31-Posições!$M31,IF(Posições!$B31="Venda",Posições!$M31-Posições!$J31*Posições!$D31,""))),"") -> -4635 | M31: =IF(OR(ISBLANK(Posições!$D31),ISBLANK(Posições!$E31)),"",Posições!$D31*Posições!$E31) -> 4635 | N31: =IF(OR(ISBLANK($H$3),ISBLANK(Posições!$B31),ISBLANK(Posições!$D31),ISBLANK(Posições!$E31),ISBLANK(Posições!$F31)),"",IF(Posições!$B31="Compra",(Posições!$E31-Posições!$F31)*Posições!$D31/$H$3,(Posições!$F31-Posições!$E31)*Posições!$D31/$H$3)) -> 0.002077235 | O31: =IF(AND(Posições!$G31<>"",Posições!$I31<>""),ABS(Posições!$G31-Posições!$E31)*Posições!$D31,0)+IF(AND(Posições!$H31<>"",Posições!$I31<>""),ABS(Posições!$H31-Posições!$E31)*Posições!$D31,0) -> 1695 | P31: =IF(AND(Posições!$B31="Compra",Posições!$I31<>""),(Posições!$F31-Posições!$E31)*Posições!$D31,IF(AND(Posições!$B31="Venda",Posições!$I31<>""),(Posições!$E31-Posições!$F31)*Posições!$D31,"")) -> -565
B32: Compra | C32: ONCO3 | D32: 1800 | E32: 6.16 | F32: 5.73 | G32: 6.53 | I32: 44797 | K32: =IFERROR(IF(ISBLANK(Posições!$I32),"",IF(Posições!$B32="Compra",Posições!$J32/Posições!$E32-1,IF(Posições!$B32="Venda",Posições!$J32/Posições!$E32-1,""))),"") -> -1 | L32: =IFERROR(IF(ISBLANK(Posições!$I32),"",IF(Posições!$B32="Compra",Posições!$J32*Posições!$D32-Posições!$M32,IF(Posições!$B32="Venda",Posições!$M32-Posições!$J32*Posições!$D32,""))),"") -> -11088 | M32: =IF(OR(ISBLANK(Posições!$D32),ISBLANK(Posições!$E32)),"",Posições!$D32*Posições!$E32) -> 11088 | N32: =IF(OR(ISBLANK($H$3),ISBLANK(Posições!$B32),ISBLANK(Posições!$D32),ISBLANK(Posições!$E32),ISBLANK(Posições!$F32)),"",IF(Posições!$B32="Compra",(Posições!$E32-Posições!$F32)*Posições!$D32/$H$3,(Posições!$F32-Posições!$E32)*Posições!$D32/$H$3)) -> 0.0028456282 | O32: =IF(AND(Posições!$G32<>"",Posições!$I32<>""),ABS(Posições!$G32-Posições!$E32)*Posições!$D32,0)+IF(AND(Posições!$H32<>"",Posições!$I32<>""),ABS(Posições!$H32-Posições!$E32)*Posições!$D32,0) -> 666 | P32: =IF(AND(Posições!$B32="Compra",Posições!$I32<>""),(Posições!$F32-Posições!$E32)*Posições!$D32,IF(AND(Posições!$B32="Venda",Posições!$I32<>""),(Posições!$E32-Posições!$F32)*Posições!$D32,"")) -> -774
B33: Compra | C33: ONCO3 | D33: 1700 | E33: 6.16 | F33: 5.73 | H33: 7.33 | I33: 44797 | K33: =IFERROR(IF(ISBLANK(Posições!$I33),"",IF(Posições!$B33="Compra",Posições!$J33/Posições!$E33-1,IF(Posições!$B33="Venda",Posições!$J33/Posições!$E33-1,""))),"") -> -1 | L33: =IFERROR(IF(ISBLANK(Posições!$I33),"",IF(Posições!$B33="Compra",Posições!$J33*Posições!$D33-Posições!$M33,IF(Posições!$B33="Venda",Posições!$M33-Posições!$J33*Posições!$D33,""))),"") -> -10472 | M33: =IF(OR(ISBLANK(Posições!$D33),ISBLANK(Posições!$E33)),"",Posições!$D33*Posições!$E33) -> 10472 | N33: =IF(OR(ISBLANK($H$3),ISBLANK(Posições!$B33),ISBLANK(Posições!$D33),ISBLANK(Posições!$E33),ISBLANK(Posições!$F33)),"",IF(Posições!$B33="Compra",(Posições!$E33-Posições!$F33)*Posições!$D33/$H$3,(Posições!$F33-Posições!$E33)*Posições!$D33/$H$3)) -> 0.0026875377 | O33: =IF(AND(Posições!$G33<>"",Posições!$I33<>""),ABS(Posições!$G33-Posições!$E33)*Posições!$D33,0)+IF(AND(Posições!$H33<>"",Posições!$I33<>""),ABS(Posições!$H33-Posições!$E33)*Posições!$D33,0) -> 1989 | P33: =IF(AND(Posições!$B33="Compra",Posições!$I33<>""),(Posições!$F33-Posições!$E33)*Posições!$D33,IF(AND(Posições!$B33="Venda",Posições!$I33<>""),(Posições!$E33-Posições!$F33)*Posições!$D33,"")) -> -731
K35: =IFERROR(IF(ISBLANK(Posições!$I35),"",IF(Posições!$B35="Compra",Posições!$J35/Posições!$E35-1,IF(Posições!$B35="Venda",Posições!$J35/Posições!$E35-1,""))),"") | L35: =IFERROR(IF(ISBLANK(Posições!$I35),"",IF(Posições!$B35="Compra",Posições!$J35*Posições!$D35-Posições!$M35,IF(Posições!$B35="Venda",Posições!$M35-Posições!$J35*Posições!$D35,""))),"") | M35: =IF(OR(ISBLANK(Posições!$D35),ISBLANK(Posições!$E35)),"",Posições!$D35*Posições!$E35) | N35: =IF(OR(ISBLANK($H$3),ISBLANK(Posições!$B35),ISBLANK(Posições!$D35),ISBLANK(Posições!$E35),ISBLANK(Posições!$F35)),"",IF(Posições!$B35="Compra",(Posições!$E35-Posições!$F35)*Posições!$D35/$H$3,(Posições!$F35-Posições!$E35)*Posições!$D35/$H$3)) | O35: =IF(AND(Posições!$G35<>"",Posições!$I35<>""),ABS(Posições!$G35-Posições!$E35)*Posições!$D35,0)+IF(AND(Posições!$H35<>"",Posições!$I35<>""),ABS(Posições!$H35-Posições!$E35)*Posições!$D35,0) -> 0 | P35: =IF(AND(Posições!$B35="Compra",Posições!$I35<>""),(Posições!$F35-Posições!$E35)*Posições!$D35,IF(AND(Posições!$B35="Venda",Posições!$I35<>""),(Posições!$E35-Posições!$F35)*Posições!$D35,""))
K37: =IFERROR(IF(ISBLANK(Posições!$I37),"",IF(Posições!$B37="Compra",Posições!$J37/Posições!$E37-1,IF(Posições!$B37="Venda",Posições!$J37/Posições!$E37-1,""))),"") | L37: =IFERROR(IF(ISBLANK(Posições!$I37),"",IF(Posições!$B37="Compra",Posições!$J37*Posições!$D37-Posições!$M37,IF(Posições!$B37="Venda",Posições!$M37-Posições!$J37*Posições!$D37,""))),"") | M37: =IF(OR(ISBLANK(Posições!$D37),ISBLANK(Posições!$E37)),"",Posições!$D37*Posições!$E37) | N37: =IF(OR(ISBLANK($H$3),ISBLANK(Posições!$B37),ISBLANK(Posições!$D37),ISBLANK(Posições!$E37),ISBLANK(Posições!$F37)),"",IF(Posições!$B37="Compra",(Posições!$E37-Posições!$F37)*Posições!$D37/$H$3,(Posições!$F37-Posições!$E37)*Posições!$D37/$H$3)) | O37: =IF(AND(Posições!$G37<>"",Posições!$I37<>""),ABS(Posições!$G37-Posições!$E37)*Posições!$D37,0)+IF(AND(Posições!$H37<>"",Posições!$I37<>""),ABS(Posições!$H37-Posições!$E37)*Posições!$D37,0) -> 0 | P37: =IF(AND(Posições!$B37="Compra",Posições!$I37<>""),(Posições!$F37-Posições!$E37)*Posições!$D37,IF(AND(Posições!$B37="Venda",Posições!$I37<>""),(Posições!$E37-Posições!$F37)*Posições!$D37,""))
K39: =IFERROR(IF(ISBLANK(Posições!$I39),"",IF(Posições!$B39="Compra",Posições!$J39/Posições!$E39-1,IF(Posições!$B39="Venda",Posições!$J39/Posições!$E39-1,""))),"") | L39: =IFERROR(IF(ISBLANK(Posições!$I39),"",IF(Posições!$B39="Compra",Posições!$J39*Posições!$D39-Posições!$M39,IF(Posições!$B39="Venda",Posições!$M39-Posições!$J39*Posições!$D39,""))),"") | M39: =IF(OR(ISBLANK(Posições!$D39),ISBLANK(Posições!$E39)),"",Posições!$D39*Posições!$E39) | N39: =IF(OR(ISBLANK($H$3),ISBLANK(Posições!$B39),ISBLANK(Posições!$D39),ISBLANK(Posições!$E39),ISBLANK(Posições!$F39)),"",IF(Posições!$B39="Compra",(Posições!$E39-Posições!$F39)*Posições!$D39/$H$3,(Posições!$F39-Posições!$E39)*Posições!$D39/$H$3)) | O39: =IF(AND(Posições!$G39<>"",Posições!$I39<>""),ABS(Posições!$G39-Posições!$E39)*Posições!$D39,0)+IF(AND(Posições!$H39<>"",Posições!$I39<>""),ABS(Posições!$H39-Posições!$E39)*Posições!$D39,0) -> 0 | P39: =IF(AND(Posições!$B39="Compra",Posições!$I39<>""),(Posições!$F39-Posições!$E39)*Posições!$D39,IF(AND(Posições!$B39="Venda",Posições!$I39<>""),(Posições!$E39-Posições!$F39)*Posições!$D39,""))
K41: =IFERROR(IF(ISBLANK(Posições!$I41),"",IF(Posições!$B41="Compra",Posições!$J41/Posições!$E41-1,IF(Posições!$B41="Venda",Posições!$J41/Posições!$E41-1,""))),"") | L41: =IFERROR(IF(ISBLANK(Posições!$I41),"",IF(Posições!$B41="Compra",Posições!$J41*Posições!$D41-Posições!$M41,IF(Posições!$B41="Venda",Posições!$M41-Posições!$J41*Posições!$D41,""))),"") | M41: =IF(OR(ISBLANK(Posições!$D41),ISBLANK(Posições!$E41)),"",Posições!$D41*Posições!$E41) | N41: =IF(OR(ISBLANK($H$3),ISBLANK(Posições!$B41),ISBLANK(Posições!$D41),ISBLANK(Posições!$E41),ISBLANK(Posições!$F41)),"",IF(Posições!$B41="Compra",(Posições!$E41-Posições!$F41)*Posições!$D41/$H$3,(Posições!$F41-Posições!$E41)*Posições!$D41/$H$3)) | O41: =IF(AND(Posições!$G41<>"",Posições!$I41<>""),ABS(Posições!$G41-Posições!$E41)*Posições!$D41,0)+IF(AND(Posições!$H41<>"",Posições!$I41<>""),ABS(Posições!$H41-Posições!$E41)*Posições!$D41,0) -> 0 | P41: =IF(AND(Posições!$B41="Compra",Posições!$I41<>""),(Posições!$F41-Posições!$E41)*Posições!$D41,IF(AND(Posições!$B41="Venda",Posições!$I41<>""),(Posições!$E41-Posições!$F41)*Posições!$D41,""))
K43: =IFERROR(IF(ISBLANK(Posições!$I43),"",IF(Posições!$B43="Compra",Posições!$J43/Posições!$E43-1,IF(Posições!$B43="Venda",Posições!$J43/Posições!$E43-1,""))),"") | L43: =IFERROR(IF(ISBLANK(Posições!$I43),"",IF(Posições!$B43="Compra",Posições!$J43*Posições!$D43-Posições!$M43,IF(Posições!$B43="Venda",Posições!$M43-Posições!$J43*Posições!$D43,""))),"") | M43: =IF(OR(ISBLANK(Posições!$D43),ISBLANK(Posições!$E43)),"",Posições!$D43*Posições!$E43) | N43: =IF(OR(ISBLANK($H$3),ISBLANK(Posições!$B43),ISBLANK(Posições!$D43),ISBLANK(Posições!$E43),ISBLANK(Posições!$F43)),"",IF(Posições!$B43="Compra",(Posições!$E43-Posições!$F43)*Posições!$D43/$H$3,(Posições!$F43-Posições!$E43)*Posições!$D43/$H$3)) | O43: =IF(AND(Posições!$G43<>"",Posições!$I43<>""),ABS(Posições!$G43-Posições!$E43)*Posições!$D43,0)+IF(AND(Posições!$H43<>"",Posições!$I43<>""),ABS(Posições!$H43-Posições!$E43)*Posições!$D43,0) -> 0 | P43: =IF(AND(Posições!$B43="Compra",Posições!$I43<>""),(Posições!$F43-Posições!$E43)*Posições!$D43,IF(AND(Posições!$B43="Venda",Posições!$I43<>""),(Posições!$E43-Posições!$F43)*Posições!$D43,""))
K45: =IFERROR(IF(ISBLANK(Posições!$I45),"",IF(Posições!$B45="Compra",Posições!$J45/Posições!$E45-1,IF(Posições!$B45="Venda",Posições!$J45/Posições!$E45-1,""))),"") | L45: =IFERROR(IF(ISBLANK(Posições!$I45),"",IF(Posições!$B45="Compra",Posições!$J45*Posições!$D45-Posições!$M45,IF(Posições!$B45="Venda",Posições!$M45-Posições!$J45*Posições!$D45,""))),"") | M45: =IF(OR(ISBLANK(Posições!$D45),ISBLANK(Posições!$E45)),"",Posições!$D45*Posições!$E45) | N45: =IF(OR(ISBLANK($H$3),ISBLANK(Posições!$B45),ISBLANK(Posições!$D45),ISBLANK(Posições!$E45),ISBLANK(Posições!$F45)),"",IF(Posições!$B45="Compra",(Posições!$E45-Posições!$F45)*Posições!$D45/$H$3,(Posições!$F45-Posições!$E45)*Posições!$D45/$H$3)) | O45: =IF(AND(Posições!$G45<>"",Posições!$I45<>""),ABS(Posições!$G45-Posições!$E45)*Posições!$D45,0)+IF(AND(Posições!$H45<>"",Posições!$I45<>""),ABS(Posições!$H45-Posições!$E45)*Posições!$D45,0) -> 0 | P45: =IF(AND(Posições!$B45="Compra",Posições!$I45<>""),(Posições!$F45-Posições!$E45)*Posições!$D45,IF(AND(Posições!$B45="Venda",Posições!$I45<>""),(Posições!$E45-Posições!$F45)*Posições!$D45,""))
K47: =IFERROR(IF(ISBLANK(Posições!$I47),"",IF(Posições!$B47="Compra",Posições!$J47/Posições!$E47-1,IF(Posições!$B47="Venda",Posições!$J47/Posições!$E47-1,""))),"") | L47: =IFERROR(IF(ISBLANK(Posições!$I47),"",IF(Posições!$B47="Compra",Posições!$J47*Posições!$D47-Posições!$M47,IF(Posições!$B47="Venda",Posições!$M47-Posições!$J47*Posições!$D47,""))),"") | M47: =IF(OR(ISBLANK(Posições!$D47),ISBLANK(Posições!$E47)),"",Posições!$D47*Posições!$E47) | N47: =IF(OR(ISBLANK($H$3),ISBLANK(Posições!$B47),ISBLANK(Posições!$D47),ISBLANK(Posições!$E47),ISBLANK(Posições!$F47)),"",IF(Posições!$B47="Compra",(Posições!$E47-Posições!$F47)*Posições!$D47/$H$3,(Posições!$F47-Posições!$E47)*Posições!$D47/$H$3)) | O47: =IF(AND(Posições!$G47<>"",Posições!$I47<>""),ABS(Posições!$G47-Posições!$E47)*Posições!$D47,0)+IF(AND(Posições!$H47<>"",Posições!$I47<>""),ABS(Posições!$H47-Posições!$E47)*Posições!$D47,0) -> 0 | P47: =IF(AND(Posições!$B47="Compra",Posições!$I47<>""),(Posições!$F47-Posições!$E47)*Posições!$D47,IF(AND(Posições!$B47="Venda",Posições!$I47<>""),(Posições!$E47-Posições!$F47)*Posições!$D47,""))
K49: =IFERROR(IF(ISBLANK(Posições!$I49),"",IF(Posições!$B49="Compra",Posições!$J49/Posições!$E49-1,IF(Posições!$B49="Venda",Posições!$J49/Posições!$E49-1,""))),"") | L49: =IFERROR(IF(ISBLANK(Posições!$I49),"",IF(Posições!$B49="Compra",Posições!$J49*Posições!$D49-Posições!$M49,IF(Posições!$B49="Venda",Posições!$M49-Posições!$J49*Posições!$D49,""))),"") | M49: =IF(OR(ISBLANK(Posições!$D49),ISBLANK(Posições!$E49)),"",Posições!$D49*Posições!$E49) | N49: =IF(OR(ISBLANK($H$3),ISBLANK(Posições!$B49),ISBLANK(Posições!$D49),ISBLANK(Posições!$E49),ISBLANK(Posições!$F49)),"",IF(Posições!$B49="Compra",(Posições!$E49-Posições!$F49)*Posições!$D49/$H$3,(Posições!$F49-Posições!$E49)*Posições!$D49/$H$3)) | O49: =IF(AND(Posições!$G49<>"",Posições!$I49<>""),ABS(Posições!$G49-Posições!$E49)*Posições!$D49,0)+IF(AND(Posições!$H49<>"",Posições!$I49<>""),ABS(Posições!$H49-Posições!$E49)*Posições!$D49,0) -> 0 | P49: =IF(AND(Posições!$B49="Compra",Posições!$I49<>""),(Posições!$F49-Posições!$E49)*Posições!$D49,IF(AND(Posições!$B49="Venda",Posições!$I49<>""),(Posições!$E49-Posições!$F49)*Posições!$D49,""))

Sheet Resultados
B1: Controle de Operações Swing Trade - Resultados
B2: Operações Concluídas
B3: Data de Entrada | C3: Data de Saída | D3: Ativo | E3: Qtde. | F3: Preço de Compra | G3: Preço de Venda | H3: Resultado Final | I3: Acumulado | J3: Mês de Saída
B4: 43675 | C4: 43655 | D4: BTOW3 | E4: 200 | F4: 36.66 | G4: 41.5 | H4: =IF(OR(Resultados!$F4="",Resultados!$G4=""),"",(Resultados!$G4-Resultados!$F4)*Resultados!$E4) -> 968 | I4: =IF(ISBLANK(Resultados!$C4),"", IF(ROW()-1=3,Resultados!$H4,INDIRECT(ADDRESS(ROW()-1,COLUMN()))+Resultados!$H4)) -> 968 | J4: =IFERROR(EOMONTH((WORKDAY(C4,0,Dados!$C$3:$C$29)),-1)+1,"") -> 43647
B5: 43670 | C5: 43670 | D5: CIEL3 | E5: 1400 | F5: 6.92 | G5: 7.09 | H5: =IF(OR(Resultados!$F5="",Resultados!$G5=""),"",(Resultados!$G5-Resultados!$F5)*Resultados!$E5) -> 238 | I5: =IF(ISBLANK(Resultados!$C5),"", IF(ROW()-1=3,Resultados!$H5,INDIRECT(ADDRESS(ROW()-1,COLUMN()))+Resultados!$H5)) -> 1206 | J5: =IFERROR(EOMONTH((WORKDAY(C5,0,Dados!$C$3:$C$29)),-1)+1,"") -> 43647
B6: 43668 | C6: 43676 | D6: CNTO3 | E6: 600 | F6: 15.89 | G6: 16.98 | H6: =IF(OR(Resultados!$F6="",Resultados!$G6=""),"",(Resultados!$G6-Resultados!$F6)*Resultados!$E6) -> 654 | I6: =IF(ISBLANK(Resultados!$C6),"", IF(ROW()-1=3,Resultados!$H6,INDIRECT(ADDRESS(ROW()-1,COLUMN()))+Resultados!$H6)) -> 1860 | J6: =IFERROR(EOMONTH((WORKDAY(C6,0,Dados!$C$3:$C$29)),-1)+1,"") -> 43647
B7: 43670 | C7: 43677 | D7: CIEL3 | E7: 1400 | F7: 6.92 | G7: 7.19 | H7: =IF(OR(Resultados!$F7="",Resultados!$G7=""),"",(Resultados!$G7-Resultados!$F7)*Resultados!$E7) -> 378 | I7: =IF(ISBLANK(Resultados!$C7),"", IF(ROW()-1=3,Resultados!$H7,INDIRECT(ADDRESS(ROW()-1,COLUMN()))+Resultados!$H7)) -> 2238 | J7: =IFERROR(EOMONTH((WORKDAY(C7,0,Dados!$C$3:$C$29)),-1)+1,"") -> 43647
B8: 43675 | C8: 43678 | D8: BTOW3 | E8: 300 | F8: 36.66 | G8: 38.44 | H8: =IF(OR(Resultados!$F8="",Resultados!$G8=""),"",(Resultados!$G8-Resultados!$F8)*Resultados!$E8) -> 534 | I8: =IF(ISBLANK(Resultados!$C8),"", IF(ROW()-1=3,Resultados!$H8,INDIRECT(ADDRESS(ROW()-1,COLUMN()))+Resultados!$H8)) -> 2772 | J8: =IFERROR(EOMONTH((WORKDAY(C8,0,Dados!$C$3:$C$29)),-1)+1,"") -> 43678
B9: 43676 | C9: 43683 | D9: CSAN3 | E9: 400 | F9: 50.99 | G9: 48.9 | H9: =IF(OR(Resultados!$F9="",Resultados!$G9=""),"",(Resultados!$G9-Resultados!$F9)*Resultados!$E9) -> -836 | I9: =IF(ISBLANK(Resultados!$C9),"", IF(ROW()-1=3,Resultados!$H9,INDIRECT(ADDRESS(ROW()-1,COLUMN()))+Resultados!$H9)) -> 1936 | J9: =IFERROR(EOMONTH((WORKDAY(C9,0,Dados!$C$3:$C$29)),-1)+1,"") -> 43678
B10: 43684 | C10: 43684 | D10: ITUB4 | E10: 300 | F10: 35.56 | G10: 35.79 | H10: =IF(OR(Resultados!$F10="",Resultados!$G10=""),"",(Resultados!$G10-Resultados!$F10)*Resultados!$E10) -> 69 | I10: =IF(ISBLANK(Resultados!$C10),"", IF(ROW()-1=3,Resultados!$H10,INDIRECT(ADDRESS(ROW()-1,COLUMN()))+Resultados!$H10)) -> 2005 | J10: =IFERROR(EOMONTH((WORKDAY(C10,0,Dados!$C$3:$C$29)),-1)+1,"") -> 43678
B11: 43676 | C11: 43685 | D11: B3SA3 | E11: 200 | F11: 42.83 | G11: 45.09 | H11: =IF(OR(Resultados!$F11="",Resultados!$G11=""),"",(Resultados!$G11-Resultados!$F11)*Resultados!$E11) -> 452 | I11: =IF(ISBLANK(Resultados!$C11),"", IF(ROW()-1=3,Resultados!$H11,INDIRECT(ADDRESS(ROW()-1,COLUMN()))+Resultados!$H11)) -> 2457 | J11: =IFERROR(EOMONTH((WORKDAY(C11,0,Dados!$C$3:$C$29)),-1)+1,"") -> 43678
B12: 43676 | C12: 43685 | D12: GNDI3 | E12: 200 | F12: 44.04 | G12: 46.89 | H12: =IF(OR(Resultados!$F12="",Resultados!$G12=""),"",(Resultados!$G12-Resultados!$F12)*Resultados!$E12) -> 570 | I12: =IF(ISBLANK(Resultados!$C12),"", IF(ROW()-1=3,Resultados!$H12,INDIRECT(ADDRESS(ROW()-1,COLUMN()))+Resultados!$H12)) -> 3027 | J12: =IFERROR(EOMONTH((WORKDAY(C12,0,Dados!$C$3:$C$29)),-1)+1,"") -> 43678
B13: 43683 | C13: 43685 | D13: ANIM3 | E13: 500 | F13: 21.92 | G13: 22.88 | H13: =IF(OR(Resultados!$F13="",Resultados!$G13=""),"",(Resultados!$G13-Resultados!$F13)*Resultados!$E13) -> 480 | I13: =IF(ISBLANK(Resultados!$C13),"", IF(ROW()-1=3,Resultados!$H13,INDIRECT(ADDRESS(ROW()-1,COLUMN()))+Resultados!$H13)) -> 3507 | J13: =IFERROR(EOMONTH((WORKDAY(C13,0,Dados!$C$3:$C$29)),-1)+1,"") -> 43678
B14: 43685 | C14: 43685 | D14: GGBR4 | E14: 800 | F14: 13.31 | G14: 13.43 | H14: =IF(OR(Resultados!$F14="",Resultados!$G14=""),"",(Resultados!$G14-Resultados!$F14)*Resultados!$E14) -> 96 | I14: =IF(ISBLANK(Resultados!$C14),"", IF(ROW()-1=3,Resultados!$H14,INDIRECT(ADDRESS(ROW()-1,COLUMN()))+Resultados!$H14)) -> 3603 | J14: =IFERROR(EOMONTH((WORKDAY(C14,0,Dados!$C$3:$C$29)),-1)+1,"") -> 43678
B15: 43676 | C15: 43686 | D15: BRML3 | E15: 700 | F15: 14.18 | G15: 15.11 | H15: =IF(OR(Resultados!$F15="",Resultados!$G15=""),"",(Resultados!$G15-Resultados!$F15)*Resultados!$E15) -> 651 | I15: =IF(ISBLANK(Resultados!$C15),"", IF(ROW()-1=3,Resultados!$H15,INDIRECT(ADDRESS(ROW()-1,COLUMN()))+Resultados!$H15)) -> 4254 | J15: =IFERROR(EOMONTH((WORKDAY(C15,0,Dados!$C$3:$C$29)),-1)+1,"") -> 43678
... B447: 44026 | C447: 44027 | D447: ENAT3 | E447: 800 | F447: 11.13 | G447: 11.5 | H447: =IF(OR(Resultados!$F447="",Resultados!$G447=""),"",(Resultados!$G447-Resultados!$F447)*Resultados!$E447) -> 296 | I447: =IF(ISBLANK(Resultados!$C447),"", IF(ROW()-1=3,Resultados!$H447,INDIRECT(ADDRESS(ROW()-1,COLUMN()))+Resultados!$H447)) -> 43353.714 | J447: =IFERROR(EOMONTH((WORKDAY(C447,0,Dados!$C$3:$C$29)),-1)+1,"") -> 44013
B448: 44027 | C448: 44028 | D448: CSAN3 | E448: 200 | F448: 76.48 | G448: 78.19 | H448: =IF(OR(Resultados!$F448="",Resultados!$G448=""),"",(Resultados!$G448-Resultados!$F448)*Resultados!$E448) -> 342 | I448: =IF(ISBLANK(Resultados!$C448),"", IF(ROW()-1=3,Resultados!$H448,INDIRECT(ADDRESS(ROW()-1,COLUMN()))+Resultados!$H448)) -> 43695.714
B449: 44013 | C449: 44028 | D449: CMIG4 | E449: 1000 | F449: 11.27 | G449: 11.29 | H449: =IF(OR(Resultados!$F449="",Resultados!$G449=""),"",(Resultados!$G449-Resultados!$F449)*Resultados!$E449) -> 20 | I449: =IF(ISBLANK(Resultados!$C449),"", IF(ROW()-1=3,Resultados!$H449,INDIRECT(ADDRESS(ROW()-1,COLUMN()))+Resultados!$H449)) -> 43715.714
B450: 44022 | C450: 44028 | D450: GOLL4 | E450: 300 | F450: 20.63 | G450: 20.99 | H450: =IF(OR(Resultados!$F450="",Resultados!$G450=""),"",(Resultados!$G450-Resultados!$F450)*Resultados!$E450) -> 108 | I450: =IF(ISBLANK(Resultados!$C450),"", IF(ROW()-1=3,Resultados!$H450,INDIRECT(ADDRESS(ROW()-1,COLUMN()))+Resultados!$H450)) -> 43823.714
B451: 44026 | C451: 44029 | D451: B3SA3 | E451: 200 | F451: 61.59 | G451: 63.25 | H451: =IF(OR(Resultados!$F451="",Resultados!$G451=""),"",(Resultados!$G451-Resultados!$F451)*Resultados!$E451) -> 332 | I451: =IF(ISBLANK(Resultados!$C451),"", IF(ROW()-1=3,Resultados!$H451,INDIRECT(ADDRESS(ROW()-1,COLUMN()))+Resultados!$H451)) -> 44155.714
B452: 44028 | C452: 44029 | D452: BRML3 | E452: 900 | F452: 11.13 | G452: 11.39 | H452: =IF(OR(Resultados!$F452="",Resultados!$G452=""),"",(Resultados!$G452-Resultados!$F452)*Resultados!$E452) -> 234 | I452: =IF(ISBLANK(Resultados!$C452),"", IF(ROW()-1=3,Resultados!$H452,INDIRECT(ADDRESS(ROW()-1,COLUMN()))+Resultados!$H452)) -> 44389.714
B453: 44026 | C453: 44032 | D453: ENAT3 | E453: 700 | F453: 11.13 | G453: 10.89 | H453: =IF(OR(Resultados!$F453="",Resultados!$G453=""),"",(Resultados!$G453-Resultados!$F453)*Resultados!$E453) -> -168 | I453: =IF(ISBLANK(Resultados!$C453),"", IF(ROW()-1=3,Resultados!$H453,INDIRECT(ADDRESS(ROW()-1,COLUMN()))+Resultados!$H453)) -> 44221.714
B454: 44027 | C454: 44032 | D454: CSAN3 | E454: 100 | F454: 76.48 | G454: 82.59 | H454: =IF(OR(Resultados!$F454="",Resultados!$G454=""),"",(Resultados!$G454-Resultados!$F454)*Resultados!$E454) -> 611 | I454: =IF(ISBLANK(Resultados!$C454),"", IF(ROW()-1=3,Resultados!$H454,INDIRECT(ADDRESS(ROW()-1,COLUMN()))+Resultados!$H454)) -> 44832.714
B455: 44028 | C455: 44032 | D455: COGN3 | E455: 700 | F455: 9.18 | G455: 9.74 | H455: =IF(OR(Resultados!$F455="",Resultados!$G455=""),"",(Resultados!$G455-Resultados!$F455)*Resultados!$E455) -> 392 | I455: =IF(ISBLANK(Resultados!$C455),"", IF(ROW()-1=3,Resultados!$H455,INDIRECT(ADDRESS(ROW()-1,COLUMN()))+Resultados!$H455)) -> 45224.714
B456: 44026 | C456: 44032 | D456: B3SA3 | E456: 200 | F456: 61.59 | G456: 66.84 | H456: =IF(OR(Resultados!$F456="",Resultados!$G456=""),"",(Resultados!$G456-Resultados!$F456)*Resultados!$E456) -> 1050 | I456: =IF(ISBLANK(Resultados!$C456),"", IF(ROW()-1=3,Resultados!$H456,INDIRECT(ADDRESS(ROW()-1,COLUMN()))+Resultados!$H456)) -> 46274.714
B457: 44029 | C457: 44033 | D457: UGPA3 | E457: 600 | F457: 19.41 | G457: 19.94 | H457: =IF(OR(Resultados!$F457="",Resultados!$G457=""),"",(Resultados!$G457-Resultados!$F457)*Resultados!$E457) -> 318 | I457: =IF(ISBLANK(Resultados!$C457),"", IF(ROW()-1=3,Resultados!$H457,INDIRECT(ADDRESS(ROW()-1,COLUMN()))+Resultados!$H457)) -> 46592.714
B458: 44026 | C458: 44033 | D458: TIET11 | E458: 600 | F458: 16.56 | G458: 16.85 | H458: =IF(OR(Resultados!$F458="",Resultados!$G458=""),"",(Resultados!$G458-Resultados!$F458)*Resultados!$E458) -> 174 | I458: =IF(ISBLANK(Resultados!$C458),"", IF(ROW()-1=3,Resultados!$H458,INDIRECT(ADDRESS(ROW()-1,COLUMN()))+Resultados!$H458)) -> 46766.714
B459: 44018 | C459: 44033 | D459: TRIS3 | E459: 700 | F459: 13.51 | G459: 13.99 | H459: =IF(OR(Resultados!$F459="",Resultados!$G459=""),"",(Resultados!$G459-Resultados!$F459)*Resultados!$E459) -> 336 | I459: =IF(ISBLANK(Resultados!$C459),"", IF(ROW()-1=3,Resultados!$H459,INDIRECT(ADDRESS(ROW()-1,COLUMN()))+Resultados!$H459)) -> 47102.714
... B927: 44770 | C927: 44795 | D927: EZTC3 | E927: 600 | F927: 16.95 | G927: 18.88 | H927: =IF(OR(Resultados!$F927="",Resultados!$G927=""),"",(Resultados!$G927-Resultados!$F927)*Resultados!$E927) -> 1158 | I927: =IF(ISBLANK(Resultados!$C927),"", IF(ROW()-1=3,Resultados!$H927,INDIRECT(ADDRESS(ROW()-1,COLUMN()))+Resultados!$H927)) -> 71996.184
H928: =IF(OR(Resultados!$F928="",Resultados!$G928=""),"",(Resultados!$G928-Resultados!$F928)*Resultados!$E928) | I928: =IF(ISBLANK(Resultados!$C928),"", IF(ROW()-1=3,Resultados!$H928,INDIRECT(ADDRESS(ROW()-1,COLUMN()))+Resultados!$H928))
H929: =IF(OR(Resultados!$F929="",Resultados!$G929=""),"",(Resultados!$G929-Resultados!$F929)*Resultados!$E929) | I929: =IF(ISBLANK(Resultados!$C929),"", IF(ROW()-1=3,Resultados!$H929,INDIRECT(ADDRESS(ROW()-1,COLUMN()))+Resultados!$H929))
H930: =IF(OR(Resultados!$F930="",Resultados!$G930=""),"",(Resultados!$G930-Resultados!$F930)*Resultados!$E930) | I930: =IF(ISBLANK(Resultados!$C930),"", IF(ROW()-1=3,Resultados!$H930,INDIRECT(ADDRESS(ROW()-1,COLUMN()))+Resultados!$H930))
H931: =IF(OR(Resultados!$F931="",Resultados!$G931=""),"",(Resultados!$G931-Resultados!$F931)*Resultados!$E931) | I931: =IF(ISBLANK(Resultados!$C931),"", IF(ROW()-1=3,Resultados!$H931,INDIRECT(ADDRESS(ROW()-1,COLUMN()))+Resultados!$H931))
H932: =IF(OR(Resultados!$F932="",Resultados!$G932=""),"",(Resultados!$G932-Resultados!$F932)*Resultados!$E932) | I932: =IF(ISBLANK(Resultados!$C932),"", IF(ROW()-1=3,Resultados!$H932,INDIRECT(ADDRESS(ROW()-1,COLUMN()))+Resultados!$H932))
H933: =IF(OR(Resultados!$F933="",Resultados!$G933=""),"",(Resultados!$G933-Resultados!$F933)*Resultados!$E933) | I933: =IF(ISBLANK(Resultados!$C933),"", IF(ROW()-1=3,Resultados!$H933,INDIRECT(ADDRESS(ROW()-1,COLUMN()))+Resultados!$H933))
H934: =IF(OR(Resultados!$F934="",Resultados!$G934=""),"",(Resultados!$G934-Resultados!$F934)*Resultados!$E934) | I934: =IF(ISBLANK(Resultados!$C934),"", IF(ROW()-1=3,Resultados!$H934,INDIRECT(ADDRESS(ROW()-1,COLUMN()))+Resultados!$H934))
H935: =IF(OR(Resultados!$F935="",Resultados!$G935=""),"",(Resultados!$G935-Resultados!$F935)*Resultados!$E935) | I935: =IF(ISBLANK(Resultados!$C935),"", IF(ROW()-1=3,Resultados!$H935,INDIRECT(ADDRESS(ROW()-1,COLUMN()))+Resultados!$H935))
H936: =IF(OR(Resultados!$F936="",Resultados!$G936=""),"",(Resultados!$G936-Resultados!$F936)*Resultados!$E936) | I936: =IF(ISBLANK(Resultados!$C936),"", IF(ROW()-1=3,Resultados!$H936,INDIRECT(ADDRESS(ROW()-1,COLUMN()))+Resultados!$H936))
H937: =IF(OR(Resultados!$F937="",Resultados!$G937=""),"",(Resultados!$G937-Resultados!$F937)*Resultados!$E937) | I937: =IF(ISBLANK(Resultados!$C937),"", IF(ROW()-1=3,Resultados!$H937,INDIRECT(ADDRESS(ROW()-1,COLUMN()))+Resultados!$H937))
H938: =IF(OR(Resultados!$F938="",Resultados!$G938=""),"",(Resultados!$G938-Resultados!$F938)*Resultados!$E938) | I938: =IF(ISBLANK(Resultados!$C938),"", IF(ROW()-1=3,Resultados!$H938,INDIRECT(ADDRESS(ROW()-1,COLUMN()))+Resultados!$H938))
...

Sheet Metas
B1: Controle de Operações Swing Trade - Desempenho
B34: Base de Dados
B35: Mês de Apuração | C35: Saldo Inicial | D35: Ganho Mensal (R$) | E35: Perda Mensal (R$) | F35: Fator de Lucro Mensal | G35: Resultado Alcançado Mensal (R$) | H35: Rendimento Alcançado Mensal (%) | I35: Ganho Acumulado (R$) | J35: Perda Acumulada (R$) | K35: Fator de Lucro Acumulado | L35: Resultado Alcançado Acumulado (R$) | M35: Rendimento Alcançado Acumulado (%)
B36: 43647 | C36: 200000 | D36: =SUMIFS(Resultados!$H$4:$H$447,Resultados!$C$4:$C$447,">="&Dados!D4,Resultados!$C$4:$C$447,"<="&Dados!E4,Resultados!$H$4:$H$447,">0") -> 2238 | E36: =SUMIFS(Resultados!$H$4:$H$447,Resultados!$C$4:$C$447,">="&Dados!D4,Resultados!$C$4:$C$447,"<="&Dados!E4,Resultados!$H$4:$H$447,"<0") -> 0 | F36: =IFERROR(D36/ABS(E36),"0") -> 0 | G36: =D36+E36 -> 2238 | H36: =IFERROR(G36/C36,0) -> 0.01119 | I36: =SUM($D$36:D36) -> 2238 | J36: =SUM($E$36:E36) -> 0 | K36: =IFERROR(I36/ABS(J36),"0") -> 0 | L36: =SUM($G$36:G36) -> 2238 | M36: =IFERROR(L36/C36,0) -> 0.01119
B37: 43678 | C37: =C36+G36 -> 202238 | D37: =SUMIFS(Resultados!$H$4:$H$447,Resultados!$C$4:$C$447,">="&Dados!D5,Resultados!$C$4:$C$447,"<="&Dados!E5,Resultados!$H$4:$H$447,">0") -> 10437 | E37: =SUMIFS(Resultados!$H$4:$H$447,Resultados!$C$4:$C$447,">="&Dados!D5,Resultados!$C$4:$C$447,"<="&Dados!E5,Resultados!$H$4:$H$447,"<0") -> -7089 | F37: =IFERROR(D37/ABS(E37),"0") -> 1.472281 | G37: =D37+E37 -> 3348 | H37: =IFERROR(G37/C37,0) -> 0.016554752 | I37: =SUM($D$36:D37) -> 12675 | J37: =SUM($E$36:E37) -> -7089 | K37: =IFERROR(I37/ABS(J37),"0") -> 1.7879814 | L37: =SUM($G$36:G37) -> 5586 | M37: =IFERROR(L37/C37,0) -> 0.027620922
B38: 43709 | C38: =C37+G37 -> 205586 | D38: =SUMIFS(Resultados!$H$4:$H$447,Resultados!$C$4:$C$447,">="&Dados!D6,Resultados!$C$4:$C$447,"<="&Dados!E6,Resultados!$H$4:$H$447,">0") -> 12276 | E38: =SUMIFS(Resultados!$H$4:$H$447,Resultados!$C$4:$C$447,">="&Dados!D6,Resultados!$C$4:$C$447,"<="&Dados!E6,Resultados!$H$4:$H$447,"<0") -> -6523 | F38: =IFERROR(D38/ABS(E38),"0") -> 1.8819562 | G38: =D38+E38 -> 5753 | H38: =IFERROR(G38/C38,0) -> 0.027983423 | I38: =SUM($D$36:D38) -> 24951 | J38: =SUM($E$36:E38) -> -13612 | K38: =IFERROR(I38/ABS(J38),"0") -> 1.833015 | L38: =SUM($G$36:G38) -> 11339 | M38: =IFERROR(L38/C38,0) -> 0.055154534
B39: 43739 | C39: =C38+G38 -> 211339 | D39: =SUMIFS(Resultados!$H$4:$H$447,Resultados!$C$4:$C$447,">="&Dados!D7,Resultados!$C$4:$C$447,"<="&Dados!E7,Resultados!$H$4:$H$447,">0") -> 9960 | E39: =SUMIFS(Resultados!$H$4:$H$447,Resultados!$C$4:$C$447,">="&Dados!D7,Resultados!$C$4:$C$447,"<="&Dados!E7,Resultados!$H$4:$H$447,"<0") -> -7126 | F39: =IFERROR(D39/ABS(E39),"0") -> 1.3976986 | G39: =D39+E39 -> 2834 | H39: =IFERROR(G39/C39,0) -> 0.013409735 | I39: =SUM($D$36:D39) -> 34911 | J39: =SUM($E$36:E39) -> -20738 | K39: =IFERROR(I39/ABS(J39),"0") -> 1.6834314 | L39: =SUM($G$36:G39) -> 14173 | M39: =IFERROR(L39/C39,0) -> 0.067062871
B40: 43770 | C40: =C39+G39 -> 214173 | D40: =SUMIFS(Resultados!$H$4:$H$447,Resultados!$C$4:$C$447,">="&Dados!D8,Resultados!$C$4:$C$447,"<="&Dados!E8,Resultados!$H$4:$H$447,">0") -> 10325 | E40: =SUMIFS(Resultados!$H$4:$H$447,Resultados!$C$4:$C$447,">="&Dados!D8,Resultados!$C$4:$C$447,"<="&Dados!E8,Resultados!$H$4:$H$447,"<0") -> -4280 | F40: =IFERROR(D40/ABS(E40),"0") -> 2.4123832 | G40: =D40+E40 -> 6045 | H40: =IFERROR(G40/C40,0) -> 0.028224846 | I40: =SUM($D$36:D40) -> 45236 | J40: =SUM($E$36:E40) -> -25018 | K40: =IFERROR(I40/ABS(J40),"0") -> 1.8081381 | L40: =SUM($G$36:G40) -> 20218 | M40: =IFERROR(L40/C40,0) -> 0.094400321
B41: 43800 | C41: =C40+G40 -> 220218 | D41: =SUMIFS(Resultados!$H$4:$H$447,Resultados!$C$4:$C$447,">="&Dados!D9,Resultados!$C$4:$C$447,"<="&Dados!E9,Resultados!$H$4:$H$447,">0") -> 13632 | E41: =SUMIFS(Resultados!$H$4:$H$447,Resultados!$C$4:$C$447,">="&Dados!D9,Resultados!$C$4:$C$447,"<="&Dados!E9,Resultados!$H$4:$H$447,"<0") -> -3924 | F41: =IFERROR(D41/ABS(E41),"0") -> 3.4740061 | G41: =D41+E41 -> 9708 | H41: =IFERROR(G41/C41,0) -> 0.04408359 | I41: =SUM($D$36:D41) -> 58868 | J41: =SUM($E$36:E41) -> -28942 | K41: =IFERROR(I41/ABS(J41),"0") -> 2.033999 | L41: =SUM($G$36:G41) -> 29926 | M41: =IFERROR(L41/C41,0) -> 0.13589262
B42: 43831 | C42: =C41+G41 -> 229926 | D42: =SUMIFS(Resultados!$H$4:$H$447,Resultados!$C$4:$C$447,">="&Dados!D10,Resultados!$C$4:$C$447,"<="&Dados!E10,Resultados!$H$4:$H$447,">0") -> 17657 | E42: =SUMIFS(Resultados!$H$4:$H$447,Resultados!$C$4:$C$447,">="&Dados!D10,Resultados!$C$4:$C$447,"<="&Dados!E10,Resultados!$H$4:$H$447,"<0") -> -9878 | F42: =IFERROR(D42/ABS(E42),"0") -> 1.7875076 | G42: =D42+E42 -> 7779 | H42: =IFERROR(G42/C42,0) -> 0.033832624 | I42: =SUM($D$36:D42) -> 76525 | J42: =SUM($E$36:E42) -> -38820 | K42: =IFERROR(I42/ABS(J42),"0") -> 1.9712777 | L42: =SUM($G$36:G42) -> 37705 | M42: =IFERROR(L42/C42,0) -> 0.16398754
B43: 43862 | C43: =C42+G42 -> 237705 | D43: =SUMIFS(Resultados!$H$4:$H$447,Resultados!$C$4:$C$447,">="&Dados!D11,Resultados!$C$4:$C$447,"<="&Dados!E11,Resultados!$H$4:$H$447,">0") -> 5888 | E43: =SUMIFS(Resultados!$H$4:$H$447,Resultados!$C$4:$C$447,">="&Dados!D11,Resultados!$C$4:$C$447,"<="&Dados!E11,Resultados!$H$4:$H$447,"<0") -> -19111.286 | F43: =IFERROR(D43/ABS(E43),"0") -> 0.30809021 | G43: =D43+E43 -> -13223.286 | H43: =IFERROR(G43/C43,0) -> -0.055628976 | I43: =SUM($D$36:D43) -> 82413 | J43: =SUM($E$36:E43) -> -57931.286 | K43: =IFERROR(I43/ABS(J43),"0") -> 1.4225992 | L43: =SUM($G$36:G43) -> 24481.714 | M43: =IFERROR(L43/C43,0) -> 0.102992
B44: 43891 | C44: =C43+G43 -> 224481.71 | D44: =SUMIFS(Resultados!$H$4:$H$447,Resultados!$C$4:$C$447,">="&Dados!D12,Resultados!$C$4:$C$447,"<="&Dados!E12,Resultados!$H$4:$H$447,">0") -> 6970 | E44: =SUMIFS(Resultados!$H$4:$H$447,Resultados!$C$4:$C$447,">="&Dados!D12,Resultados!$C$4:$C$447,"<="&Dados!E12,Resultados!$H$4:$H$447,"<0") -> -230 | F44: =IFERROR(D44/ABS(E44),"0") -> 30.304348 | G44: =D44+E44 -> 6740 | H44: =IFERROR(G44/C44,0) -> 0.030024717 | I44: =SUM($D$36:D44) -> 89383 | J44: =SUM($E$36:E44) -> -58161.286 | K44: =IFERROR(I44/ABS(J44),"0") -> 1.5368127 | L44: =SUM($G$36:G44) -> 31221.714 | M44: =IFERROR(L44/C44,0) -> 0.13908355
B45: 43922 | C45: =C44+G44 -> 231221.71 | D45: =SUMIFS(Resultados!$H$4:$H$447,Resultados!$C$4:$C$447,">="&Dados!D13,Resultados!$C$4:$C$447,"<="&Dados!E13,Resultados!$H$4:$H$447,">0") -> 12228 | E45: =SUMIFS(Resultados!$H$4:$H$447,Resultados!$C$4:$C$447,">="&Dados!D13,Resultados!$C$4:$C$447,"<="&Dados!E13,Resultados!$H$4:$H$447,"<0") -> -11524 | F45: =IFERROR(D45/ABS(E45),"0") -> 1.0610899 | G45: =D45+E45 -> 704 | H45: =IFERROR(G45/C45,0) -> 0.0030446967 | I45: =SUM($D$36:D45) -> 101611 | J45: =SUM($E$36:E45) -> -69685.286 | K45: =IFERROR(I45/ABS(J45),"0") -> 1.4581414 | L45: =SUM($G$36:G45) -> 31925.714 | M45: =IFERROR(L45/C45,0) -> 0.13807403
B46: 43952 | C46: =C45+G45 -> 231925.71 | D46: =SUMIFS(Resultados!$H$4:$H$447,Resultados!$C$4:$C$447,">="&Dados!D14,Resultados!$C$4:$C$447,"<="&Dados!E14,Resultados!$H$4:$H$447,">0") -> 17832.9 | E46: =SUMIFS(Resultados!$H$4:$H$447,Resultados!$C$4:$C$447,">="&Dados!D14,Resultados!$C$4:$C$447,"<="&Dados!E14,Resultados!$H$4:$H$447,"<0") -> -15576.4 | F46: =IFERROR(D46/ABS(E46),"0") -> 1.1448666 | G46: =D46+E46 -> 2256.5 | H46: =IFERROR(G46/C46,0) -> 0.0097294084 | I46: =SUM($D$36:D46) -> 119443.9 | J46: =SUM($E$36:E46) -> -85261.686 | K46: =IFERROR(I46/ABS(J46),"0") -> 1.4009094 | L46: =SUM($G$36:G46) -> 34182.214 | M46: =IFERROR(L46/C46,0) -> 0.14738432
B47: 43983 | C47: =C46+G46 -> 234182.21 | D47: =SUMIFS(Resultados!$H$4:$H$447,Resultados!$C$4:$C$447,">="&Dados!D15,Resultados!$C$4:$C$447,"<="&Dados!E15,Resultados!$H$4:$H$447,">0") -> 18162 | E47: =SUMIFS(Resultados!$H$4:$H$447,Resultados!$C$4:$C$447,">="&Dados!D15,Resultados!$C$4:$C$447,"<="&Dados!E15,Resultados!$H$4:$H$447,"<0") -> -13936.5 | F47: =IFERROR(D47/ABS(E47),"0") -> 1.3031966 | G47: =D47+E47 -> 4225.5 | H47: =IFERROR(G47/C47,0) -> 0.018043642 | I47: =SUM($D$36:D47) -> 137605.9 | J47: =SUM($E$36:E47) -> -99198.186 | K47: =IFERROR(I47/ABS(J47),"0") -> 1.3871816 | L47: =SUM($G$36:G47) -> 38407.714 | M47: =IFERROR(L47/C47,0) -> 0.16400782
B48: 44013 | C48: =C47+G47 -> 238407.71 | D48: =SUMIFS(Resultados!$H$4:$H$447,Resultados!$C$4:$C$447,">="&Dados!D16,Resultados!$C$4:$C$447,"<="&Dados!E16,Resultados!$H$4:$H$447,">0") -> 15668 | E48: =SUMIFS(Resultados!$H$4:$H$447,Resultados!$C$4:$C$447,">="&Dados!D16,Resultados!$C$4:$C$447,"<="&Dados!E16,Resultados!$H$4:$H$447,"<0") -> -10722 | F48: =IFERROR(D48/ABS(E48),"0") -> 1.4612945 | G48: =D48+E48 -> 4946 | H48: =IFERROR(G48/C48,0) -> 0.020745973 | I48: =SUM($D$36:D48) -> 153273.9 | J48: =SUM($E$36:E48) -> -109920.19 | K48: =IFERROR(I48/ABS(J48),"0") -> 1.3944109 | L48: =SUM($G$36:G48) -> 43353.714 | M48: =IFERROR(L48/C48,0) -> 0.18184694
... B65: 44531 | C65: =C64+G64 -> 243353.71 | D65: =SUMIFS(Resultados!$H$4:$H$447,Resultados!$C$4:$C$447,">="&Dados!D33,Resultados!$C$4:$C$447,"<="&Dados!E33,Resultados!$H$4:$H$447,">0") -> 0 | E65: =SUMIFS(Resultados!$H$4:$H$447,Resultados!$C$4:$C$447,">="&Dados!D33,Resultados!$C$4:$C$447,"<="&Dados!E33,Resultados!$H$4:$H$447,"<0") -> 0 | F65: =IFERROR(D65/ABS(E65),"0") -> 0 | G65: =D65+E65 -> 0 | H65: =IFERROR(G65/C65,0) -> 0 | I65: =SUM($D$36:D65) -> 153273.9 | J65: =SUM($E$36:E65) -> -109920.19 | K65: =IFERROR(I65/ABS(J65),"0") -> 1.3944109 | L65: =SUM($G$36:G65) -> 43353.714 | M65: =IFERROR(L65/C65,0) -> 0.17815103

Sheet Dados
A1: Informações de Apoio
A3: Ativo | B3: Cotação | D3: Início | E3: Fim | G3: C/V | I3: Tipo | K3: Calculadora de Tamanho de Lote
A4: USIM5 | B4: #ERROR! | D4: 43647 | E4: 43677 | G4: Compra | I4: Ação | K4: Critério | L4: Ação | M4: ETF
A5: VIVT4 | B5: #ERROR! | D5: 43678 | E5: 43708 | G5: Venda | I5: ETF | K5: Capital por operação | L5: =IF(OR(ISBLANK(Posições!D7),ISBLANK(Posições!H3),ISBLANK(Posições!C13),),"",ROUNDDOWN((Posições!D7*Posições!H3)/Posições!C13,-2)) | M5: =IF(OR(ISBLANK(Posições!D7),ISBLANK(Posições!H3),ISBLANK(Posições!C13),),"",ROUNDDOWN((Posições!D7*Posições!H3)/Posições!C13,-1))
A6: GGBR4 | B6: #ERROR! | D6: 43709 | E6: 43738 | K6: Risco Carteira (%) | L6: =IF(OR(ISBLANK(Posições!D8),ISBLANK(Posições!H3),ISBLANK(Posições!C13),ISBLANK(Posições!D13)),"",ROUNDDOWN(Posições!D8*Posições!H3/ABS(Posições!C13-Posições!D13),-2)) | M6: =IF(OR(ISBLANK(Posições!D8),ISBLANK(Posições!H3),ISBLANK(Posições!C13),ISBLANK(Posições!D13)),"",ROUNDDOWN(Posições!D8*Posições!H3/ABS(Posições!C13-Posições!D13),-1))
A7: EGIE3 | B7: #ERROR! | D7: 43739 | E7: 43769
A8: FLRY3 | B8: #ERROR! | D8: 43770 | E8: 43799
A9: BRPR3 | B9: #ERROR! | D9: 43800 | E9: 43830
A10: BEEF3 | B10: #ERROR! | D10: 43831 | E10: 43861
A11: VIVA3 | B11: #ERROR! | D11: 43862 | E11: 43890
A12: AGRO3 | B12: #ERROR! | D12: 43891 | E12: 43921
A13: PSSA3 | B13: #ERROR! | D13: 43922 | E13: 43951
A14: TESA3 | B14: #ERROR! | D14: 43952 | E14: 43982
A15: BOVA11 | B15: #ERROR! | D15: 43983 | E15: 44012
A16: GNDI3 | B16: #ERROR! | D16: 44013 | E16: 44043
A17: CVCB3 | B17: #ERROR! | D17: 44044 | E17: 44074
A18: ALPA4 | B18: #ERROR! | D18: 44075 | E18: 44104
... A33: ESTC3 | B33: #ERROR! | D33: 44531 | E33: 44561
A34: TIET11 | B34: #ERROR!
A35: TRIS3 | B35: #ERROR!
A36: SAPR4 | B36: #ERROR!
A37: WEGE3 | B37: #ERROR!
A38: MRVE3 | B38: #ERROR!
A39: XPML11 | B39: #ERROR!
A40: AMAR3 | B40: #ERROR!
A41: HYPE3 | B41: #ERROR!
A42: KLBN11 | B42: #ERROR!
A43: MILS3 | B43: #ERROR!
A44: WDOFUT | B44: #ERROR!
A45: WSPFUTV | B45: #ERROR!
... A366: YDUQ3 | B366: #ERROR!
