Workbook

Sheet AlocacaoCarteira
A1: Data | B1: ARX_Acoes | C1: Votorantim_Cambial | D1: BNPTargus_RF | E1: XPTop_CreditoPrivado | F1: SPX_Macro | G1: GAP_LongShort
A2: 41641 | B2: 7.3786359e-05 | C2: -0.0053048014 | D2: 0.00035041296 | E2: 0.00038166065 | F2: -0.00064615707 | G2: -0.0029128688 | J2: ARX_Acoes | K2: Votorantim_Cambial | L2: BNPTargus_RF | M2: XPTop_CreditoPrivado | N2: SPX_Macro | O2: GAP_LongShort
A3: 41642 | B3: -0.0035155615 | C3: -0.0019751489 | D3: 0.00039126844 | E3: 0.00038757599 | F3: 0.0010658564 | G3: -5.8667822e-05 | I3: ARX_Acoes | J3: =VARP(AlocacaoCarteira!$B$2:$B$1239) -> 0.00019629365 | K3: =J4 -> -6.2734053e-05 | L3: =J5 -> -1.2381752e-08 | M3: =J6 -> 2.9127745e-08 | N3: =J7 -> -5.8022301e-06 | O3: =J8 -> -2.6298304e-06
A4: 41645 | B4: -0.0065518828 | C4: -0.0019365427 | D4: 0.00038331607 | E4: 0.00038686192 | F4: 0.00071669473 | G4: 9.6603252e-05 | I4: Votorantim_Cambial | J4: -6.2734053e-05 | K4: =VARP(AlocacaoCarteira!$C$2:$C$1239) -> 9.5547837e-05 | L4: =K5 -> -3.5910171e-08 | M4: =K6 -> 3.8402005e-08 | N4: =K7 -> 1.0809935e-05 | O4: =K8 -> 3.9478986e-07
A5: 41646 | B5: 0.0039340813 | C5: 0.0072076086 | D5: 0.00037200616 | E5: 0.00040236892 | F5: 0.0042508504 | G5: 0.0012761149 | I5: BNPTargus_RF | J5: =_xlfn.COVARIANCE.P(D2:D1239,B2:B1239) -> -1.2381752e-08 | K5: -3.5910171e-08 | L5: =VARP(AlocacaoCarteira!$D$2:$D$1239) -> 1.3307777e-08 | M5: =L6 -> 1.0040233e-08 | N5: =L7 -> 2.488803e-08 | O5: =L8 -> 8.1289598e-09
A6: 41647 | B6: -0.021533088 | C6: 0.0032438617 | D6: 0.00036346414 | E6: 0.00037774634 | F6: 0.0030182035 | G6: -0.00044698694 | I6: XPTop_CreditoPrivado | J6: 2.9127745e-08 | K6: 3.8402005e-08 | L6: 1.0040233e-08 | M6: =VARP(AlocacaoCarteira!$E$2:$E$1239) -> 1.4626073e-07 | N6: =M7 -> 5.1776965e-09 | O6: =M8 -> 2.5831099e-08
A7: 41648 | B7: 0.0081651306 | C7: -0.011935611 | D7: 0.00033792986 | E7: 0.00039510731 | F7: -0.0038867902 | G7: 0.00023516055 | I7: SPX_Macro | J7: -5.8022301e-06 | K7: 1.0809935e-05 | L7: 2.488803e-08 | M7: 5.1776965e-09 | N7: =VARP(AlocacaoCarteira!$F$2:$F$1239) -> 1.0841395e-05 | O7: =N8 -> 4.2577493e-07
A8: 41649 | B8: -0.0040243929 | C8: -0.0035842491 | D8: 0.00033017189 | E8: 0.00040231476 | F8: -0.0022384703 | G8: 0.0010495448 | I8: GAP_LongShort | J8: -2.6298304e-06 | K8: 3.9478986e-07 | L8: 8.1289598e-09 | M8: 2.5831099e-08 | N8: 4.2577493e-07 | O8: =VARP(AlocacaoCarteira!$G$2:$G$1239) -> 1.6406479e-06
A9: 41652 | B9: 0.0027143003 | C9: -0.0021980732 | D9: 0.00042520096 | E9: 0.00037057561 | F9: 0.0022409681 | G9: 0.0016185549
A10: 41653 | B10: 0.0075628491 | C10: -0.0022455828 | D10: 0.00037401082 | E10: 0.0003660018 | F10: 0.0011956463 | G10: 0.0020262828 | J10: Peso | K10: Retorno CDI | L10: Retorno Abs | N10: Peso x Cov
A11: 41654 | B11: -0.0047436719 | C11: 0.0057726086 | D11: 0.00052521202 | E11: 0.00039800854 | F11: -0.0010290743 | G11: 0.0013364058 | I11: ARX_Acoes | J11: 0.033871879 | L11: 0.15 | N11: {=MMULT(J3:O8,J11:J16)} -> 2.168152e-06 | Q11: 12 meses
A12: 41655 | B12: -0.0089747975 | C12: -0.0061190601 | D12: 0.00039629984 | E12: 0.00038387939 | F12: -0.0016954749 | G12: 0.00023863978 | I12: Votorantim_Cambial | J12: 0.042583637 | K12: 1.3 | L12: =K12*$Q$12 -> 0.169 | N12: 4.2135427e-06 | P12: CDI | Q12: 0.13 | V12: Perguntas
A13: 41656 | B13: -0.01086671 | C13: -0.0041617321 | D13: 0.00039071134 | E13: 0.00040555868 | F13: -9.8784346e-05 | G13: -0.00083049389 | I13: BNPTargus_RF | J13: 0.12354448 | K13: 1 | L13: =K13*$Q$12 -> 0.13 | N13: 1.0219451e-08 | P13: Inflação | Q13: 0.04
A14: 41659 | B14: -0.0034852886 | C14: 0.01085568 | D14: 0.00039439718 | E14: 0.00040031732 | F14: 0.0030947986 | G14: -0.00033431842 | I14: XPTop_CreditoPrivado | J14: 0.35 | K14: 1.15 | L14: =K14*$Q$12 -> 0.1495 | N14: 6.2546894e-08 | P14: Juro Real 3 anos | Q14: 0.065 | V14: 1-Qual sua despesa mensal | AA14: 5000 | AF14: Carteira | AI14: Carteira
A15: 41660 | B15: 0.013366073 | C15: 0.0036879046 | D15: 0.00039783926 | E15: 0.00039540951 | F15: 0.0017800803 | G15: 0.00036314381 | I15: SPX_Macro | J15: 0.2 | K15: 1.4 | L15: =K15*$Q$12 -> 0.182 | N15: 2.5434037e-06 | P15: Índice Big Mac | Q15: 0.5 | V15: 2-Qual o montante annual de despesa em moeda forte? | AA15: 0
A16: 41661 | B16: -0.015658275 | C16: 0.0094504875 | D16: 0.00040719633 | E16: 0.00040625431 | F16: 0.0026810152 | G16: 0.00060834567 | I16: GAP_LongShort | J16: =1-SUM(J11:J15) -> 0.25 | K16: 1.25 | L16: =K16*$Q$12 -> 0.1625 | N16: 4.3309642e-07 | V16: 3-Qual a renda mensal? | AA16: 15000 | AF16: Ações | AG16: =J11 -> 0.033871879 | AI16: ARX_Acoes | AJ16: =AG16 -> 0.033871879
A17: 41662 | B17: -0.0092244115 | C17: 0.0038434334 | D17: 0.00038904709 | E17: 0.00037985608 | F17: -0.0019412692 | G17: 0.001237211 | V17: 4-Você possui aversão a algum tipo de investimento? Coloque 0 para aquelas que sim e 1 não | AF17: Cambial | AG17: =J12 -> 0.042583637 | AI17: Votorantim_Cambial | AJ17: =AG17 -> 0.042583637
A18: 41663 | B18: -0.004034279 | C18: 0.0055946964 | D18: 0.00038435752 | E18: 0.00037599962 | F18: 0.0030205557 | G18: -1.3085322e-05 | I18: {=TRANSPOSE(I11:I16)} -> ARX_Acoes | J18: Votorantim_Cambial | K18: BNPTargus_RF | L18: XPTop_CreditoPrivado | M18: SPX_Macro | N18: GAP_LongShort | AF18: Renda Fixa DI | AG18: =J13 -> 0.12354448 | AI18: BNPTargus_RF | AJ18: =AG18-J32 -> 0.045544484
A19: 41666 | B19: 0.0047327051 | C19: 0.0030059146 | D19: 0.00038989311 | E19: -6.6442413e-05 | F19: -3.3257121e-05 | G19: -0.00082075789 | I19: {=TRANSPOSE(J11:J16)} -> 0.033871879 | J19: 0.042583637 | K19: 0.12354448 | L19: 0.35 | M19: 0.2 | N19: 0.25 | W19: Renda Fixa | AA19: 1 | AF19: Crédito Privado | AG19: =J14 -> 0.35 | AI19: Previdência RF | AJ19: =J32 -> 0.078
A20: 41667 | B20: -0.002604159 | C20: 0.0035969488 | D20: 0.00034116253 | E20: 0.00019354711 | F20: -0.00033021634 | G20: 0.00332063 | W20: Moedas | AA20: 1 | AF20: Macro | AG20: =J15 -> 0.2 | AI20: XPTop_CreditoPrivado | AJ20: =AG19 -> 0.35
A21: 41668 | B21: -0.010601663 | C21: -0.0094798511 | D21: 0.00038744552 | E21: 0.0003796806 | F21: -0.0058114283 | G21: -0.0018832642 | W21: Long-Short | AA21: 1 | AF21: Long-Short | AG21: =J16 -> 0.25 | AI21: SPX_Macro | AJ21: =AG20 -> 0.2
A22: 41669 | B22: 0.007595274 | C22: 0.00060394287 | D22: 0.00039104881 | E22: 0.00045763847 | F22: 0.0022493446 | G22: 0.0023410473 | I22: Var | J22: {=MMULT(I19:N19,N11:N16)} -> 8.9297616e-07 | W22: Crédito Privado | AA22: 1 | AI22: GAP_LongShort | AJ22: =AG21 -> 0.25
A23: 41670 | B23: -0.030034621 | C23: 0.0079759483 | D23: 0.00040592441 | E23: 7.0716902e-05 | F23: 0.0011431518 | G23: -0.00059444176 | I23: Desvio Diário | J23: =SQRT(J22) -> 0.00094497416 | W23: Macro | AA23: 1
A24: 41673 | B24: 0.0094870011 | C24: -0.0094014721 | D24: 0.00024799397 | E24: 0.00042973469 | F24: -0.00069208979 | G24: 0.0029606038 | I24: Desvio Annual | J24: =J23*SQRT(252) -> 0.015001 | W24: Ações | AA24: 1
A25: 41674 | B25: -0.0078172495 | C25: -0.0044837255 | D25: 0.0003884042 | E25: 0.0007310787 | F25: 0.00045664792 | G25: 0.0019620631 | I25: Retorno Abs | J25: =SUMPRODUCT(AlocacaoCarteira!J11:J16,AlocacaoCarteira!L11:L16) -> 0.1576882 | V25: 5-Dentre os portfólios abaixo, qual representaria sua opção de investimento preferida? | AD25: B | AF25: 12 meses | AG25: Abs. | AH25: CDI
A26: 41675 | B26: 0.020668554 | C26: -0.0053477725 | D26: 0.00039164964 | E26: 0.00075321769 | F26: -0.0033749537 | G26: 0.0020158294 | I26: Retorno % CDI | J26: =J25/Q12 -> 1.2129861 | AF26: Retorno Esperado | AG26: =J25 -> 0.1576882 | AH26: =J26 -> 1.2129861
A27: 41676 | B27: 0.0039457296 | C27: -0.0020036405 | D27: 0.0003968724 | E27: 0.00046271541 | F27: -0.00076847897 | G27: -0.0022046786 | I27: Vol alvo | J27: =AlocacaoCarteira!AF46 -> 0.015 | AF27: Pior Retorno | AG27: =AG26-1.96*J24 -> 0.12828624 | AH27: =AG27/$Q$12 -> 0.98681723
A28: 41677 | B28: -0.0095362092 | C28: 0.0072143241 | D28: 0.00039114188 | E28: 0.00042640262 | F28: 0.0047163408 | G28: 0.00019205512 | AF28: Melhor Retorno | AG28: =AG26+1.96*J24 -> 0.18709016 | AH28: =AG28/$Q$12 -> 1.4391551
A29: 41680 | B29: 0.014093082 | C29: 0.0023465337 | D29: 0.00039765477 | E29: 0.00043664094 | F29: -2.9883833e-05 | G29: -0.00031594193 | I29: Alocações alvo
A30: 41681 | B30: -0.0074184879 | C30: 0.0072563861 | D30: 0.00040465362 | E30: 0.00028226707 | F30: 0.001695433 | G30: -0.0007109964 | I30: Reserva | J30: =K30/AA34-J32 -> 0.022 | K30: =AA14*6 -> 30000
A31: 41682 | B31: -0.0085921132 | C31: -0.0076434979 | D31: 0.00040548088 | E31: 0.00031966905 | F31: -0.0032557779 | G31: -0.0010253293 | I31: Cambial | J31: =K31/AA34 -> 0 | K31: =AA15*2 -> 0
A32: 41683 | B32: 0.0061999336 | C32: -0.0076573685 | D32: 0.00038764391 | E32: 0.00059094936 | F32: 0.0014565352 | G32: 0.00084329996 | I32: PGBL RF | J32: =K32/AA34 -> 0.078 | K32: =AA16*13*0.12 -> 23400
A33: 41684 | B33: -0.013274127 | C33: -0.00014428769 | D33: 0.00039253092 | E33: 0.00049472827 | F33: 0 | G33: -5.704752e-05
A34: 41687 | B34: -0.022678051 | C34: 0.0027190604 | D34: 0.00038537523 | E34: 0.00045568128 | F34: 0.0031530889 | G34: 0.0013916173 | L34: Max | M34: Min | V34: 6-Qual o seu patrimônio para investir hoje? | AA34: 300000
A35: 41688 | B35: 0.011421891 | C35: -0.001696502 | D35: 0.00038756298 | E35: 0.00049809599 | F35: 0.00078106532 | G35: 0.00179844 | K35: Renda Fixa | L35: =IF($AD$25="A",70%,IF($AD$25="B",60%,IF($AD$25="C",50%,40%))) -> 0.6 | M35: =IF($AD$25="A",40%,IF($AD$25="B",30%,IF($AD$25="C",15%,10%))) -> 0.3
A36: 41689 | B36: 0.0017308131 | C36: -0.0052088042 | D36: 0.00039929167 | E36: 0.00030974029 | F36: -0.0011855015 | G36: 3.7158235e-05 | K36: Moedas | L36: =IF($AD$25="A",10%,IF($AD$25="B",15%,IF($AD$25="C",20%,30%))) -> 0.15 | M36: =IF(Q15>70%,IF($AD$25="A",0%,IF($AD$25="B",5%,IF($AD$25="C",10%,15%))),IF($AD$25="A",0%,IF($AD$25="B",0%,IF($AD$25="C",0%,0%)))) -> 0
A37: 41690 | B37: 0.00063299042 | C37: -0.0080820872 | D37: 0.00038640059 | E37: 0.00060083837 | F37: -0.0021623351 | G37: 0.00041639357 | K37: Long-Short | L37: =IF($AD$25="A",20%,IF($AD$25="B",25%,IF($AD$25="C",30%,30%))) -> 0.25 | M37: =IF($AD$25="A",0%,IF($AD$25="B",5%,IF($AD$25="C",10%,10%))) -> 0.05
A38: 41691 | B38: 0.0036584937 | C38: -0.0067505088 | D38: 0.00038801213 | E38: 0.00055823365 | F38: -0.0010307794 | G38: 0.00194342 | K38: Crédito Privado | L38: =IF($AD$25="A",40%,IF($AD$25="B",35%,IF($AD$25="C",30%,25%))) -> 0.35 | M38: =IF($AD$25="A",25%,IF($AD$25="B",15%,IF($AD$25="C",5%,5%))) -> 0.15
A39: 41694 | B39: -0.015406193 | C39: -0.002063944 | D39: 0.00038571463 | E39: 0.0004982454 | F39: -0.001985101 | G39: 0.00083921344 | K39: Macro | L39: =IF($AD$25="A",10%,IF($AD$25="B",20%,IF($AD$25="C",30%,40%))) -> 0.2 | M39: =IF($AD$25="A",0%,IF($AD$25="B",10%,IF($AD$25="C",15%,20%))) -> 0.1
A40: 41695 | B40: -0.0018257358 | C40: 0.0070609432 | D40: 0.0003904759 | E40: 0.00052962252 | F40: 0.0030480143 | G40: -0.00046857961 | K40: Ações | L40: =IF($AD$25="A",5%,IF($AD$25="B",15%,IF($AD$25="C",20%,40%))) -> 0.15 | M40: =IF($AD$25="A",0%,IF($AD$25="B",5%,IF($AD$25="C",10%,15%))) -> 0.05
...
