Workbook

Sheet Planejamento Financeiro
B6: Cliente: | N6: Data Atual:
B7: AMSF | N7: =TODAY() -> 44720
B9: Fase de Acúmulo
C11: Perfil de Risco: | E11: Selic md -10anos (a.a.) | G11: Taxa Nominal (a.a.) | I11: Valor Nominal Final | K11: Retorno Total Nominal
C12: Arrojado | E12: =C21+2.67% -> 0.079 | G12: =E12+3% -> 0.109 | I12: =IFERROR(-FV('Base Dash acum'!C3,M21*12,$C$18,(IF($E$15=0,$C$15,$E$15)),),"") -> 11913209 | K12: =IFERROR(I12-C24,"") -> 9713208.9
C14: Valor Inicial | G14: Taxa Real (a.a.) | I14: Valor Real Final | K14: Retorno Total Real | M14: Idade Atual:
C15: 1000000 | G15: =IFERROR(((1+G12)/(1+C21)-1),"") -> 0.053881973 | I15: =IFERROR(-FV('Base Dash acum'!C4,M21*12,$C$18,(IF($E$15=0,$C$15,$E$15)),),"") -> 4974440.7 | K15: =IFERROR(I15-C24,"") -> 2774440.7 | M15: 30 | N15: Anos
C17: Aporte Mensal Médio: | M17: Idade Objetivo:
C18: 5000 | M18: 50 | N18: Anos
C20: Inflação md -10anos (a.a.) | M20: Tempo de Contribuição (Anos):
C21: 0.0523 | M21: =IFERROR(IF((M18-M15)<0,"",(M18-M15)),"") -> 20 | N21: Anos
C23: Valor Total Investido
C24: =IFERROR(((C18*12)*M21)+(IF($E$15=0,$C$15,$E$15)),"") -> 2200000
B27: Fase de Usufruto
C29: Taxa de Juros real
C30: =G15 -> 0.053881973
C32: RENDA PASSIVA POTENCIAL (PL)
C33: =IFERROR('Base Dash acum'!$R$4/12,"")-C36 -> 22336.056
C35: ALUGUEL + INSS
C36: 7087.22
C38: RENDA PASSIVA POTENCIAL (PL + INSS)
C39: =C36+C33 -> 29423.276
C41: Objetivo Gasto Mensal:
C42: 25000
C44: Superávit / Déficit
C45: =C39-C42 -> 4423.2765

Sheet Base Dash acum
C2: =((('Planejamento Financeiro'!C21+1)^(1/12))-1) -> 0.0042572234
C3: =((('Planejamento Financeiro'!G12+1)^(1/12))-1) -> 0.0086588317 | E3: IDADE | F3: Ano | G3: Juros | H3: Total Investido | I3: Total Juros | J3: TotalAcumulado | O3: ANO | P3: IDADE | Q3: PL | R3: RENDA ANO | S3: GASTO ANO | T3: GASTO MÊS
C4: =((('Planejamento Financeiro'!G15+1)^(1/12))-1) -> 0.0043829491 | E4: =Tabela1[[#This Row],[Ano]]+'Planejamento Financeiro'!$M$15 -> 30 | F4: 0 | G4: =Tabela1[[#This Row],[TotalAcumulado]]-Tabela1[[#This Row],[Total Investido]] -> 0 | H4: ='Planejamento Financeiro'!$C$15 -> 1000000 | I4: =Tabela1[[#This Row],[Juros]] -> 0 | J4: =-FV('Base Dash acum'!$C$3,Tabela1[[#This Row],[Ano]]*12,'Planejamento Financeiro'!$C$18,'Planejamento Financeiro'!$C$15,) -> 1000000 | O4: =0 -> 0 | P4: =Tabela46[[#This Row],[ANO]]+'Planejamento Financeiro'!$M$18 -> 50 | Q4: ='Planejamento Financeiro'!$I$15 -> 4974440.7 | R4: ='Planejamento Financeiro'!$C$30*Tabela46[[#This Row],[PL]]+('Planejamento Financeiro'!$C$36*12) -> 353079.32 | S4: =Tabela46[[#This Row],[GASTO MÊS]]*12 -> 300000 | T4: ='Planejamento Financeiro'!$C$42-V4 -> 25000
E5: =Tabela1[[#This Row],[Ano]]+'Planejamento Financeiro'!$M$15 -> 31 | F5: =F4+1 -> 1 | G5: =Tabela1[[#This Row],[TotalAcumulado]]-Tabela1[[#This Row],[Total Investido]] -> 111941.52 | H5: =H4+('Planejamento Financeiro'!$C$18*12) -> 1060000 | I5: =Tabela1[[#This Row],[Juros]] -> 111941.52 | J5: =-FV('Base Dash acum'!$C$3,Tabela1[[#This Row],[Ano]]*12,'Planejamento Financeiro'!$C$18,'Planejamento Financeiro'!$C$15,) -> 1171941.5 | O5: =1+O4 -> 1 | P5: =Tabela46[[#This Row],[ANO]]+'Planejamento Financeiro'!$M$18 -> 51 | Q5: =Q4+R4-S4 -> 5027520 | R5: ='Planejamento Financeiro'!$C$30*Tabela46[[#This Row],[PL]]+('Planejamento Financeiro'!$C$36*12) -> 355939.34 | S5: =Tabela46[[#This Row],[GASTO MÊS]]*12 -> 300000 | T5: ='Planejamento Financeiro'!$C$42-V5 -> 25000
E6: =Tabela1[[#This Row],[Ano]]+'Planejamento Financeiro'!$M$15 -> 32 | F6: =F5+1 -> 2 | G6: =Tabela1[[#This Row],[TotalAcumulado]]-Tabela1[[#This Row],[Total Investido]] -> 242624.66 | H6: =H5+('Planejamento Financeiro'!$C$18*12) -> 1120000 | I6: =Tabela1[[#This Row],[Juros]] -> 242624.66 | J6: =-FV('Base Dash acum'!$C$3,Tabela1[[#This Row],[Ano]]*12,'Planejamento Financeiro'!$C$18,'Planejamento Financeiro'!$C$15,) -> 1362624.7 | O6: =1+O5 -> 2 | P6: =Tabela46[[#This Row],[ANO]]+'Planejamento Financeiro'!$M$18 -> 52 | Q6: =Q5+R5-S5 -> 5083459.3 | R6: ='Planejamento Financeiro'!$C$30*Tabela46[[#This Row],[PL]]+('Planejamento Financeiro'!$C$36*12) -> 358953.46 | S6: =Tabela46[[#This Row],[GASTO MÊS]]*12 -> 300000 | T6: ='Planejamento Financeiro'!$C$42-V6 -> 25000
E7: =Tabela1[[#This Row],[Ano]]+'Planejamento Financeiro'!$M$15 -> 33 | F7: =F6+1 -> 3 | G7: =Tabela1[[#This Row],[TotalAcumulado]]-Tabela1[[#This Row],[Total Investido]] -> 394092.26 | H7: =H6+('Planejamento Financeiro'!$C$18*12) -> 1180000 | I7: =Tabela1[[#This Row],[Juros]] -> 394092.26 | J7: =-FV('Base Dash acum'!$C$3,Tabela1[[#This Row],[Ano]]*12,'Planejamento Financeiro'!$C$18,'Planejamento Financeiro'!$C$15,) -> 1574092.3 | O7: =1+O6 -> 3 | P7: =Tabela46[[#This Row],[ANO]]+'Planejamento Financeiro'!$M$18 -> 53 | Q7: =Q6+R6-S6 -> 5142412.8 | R7: ='Planejamento Financeiro'!$C$30*Tabela46[[#This Row],[PL]]+('Planejamento Financeiro'!$C$36*12) -> 362129.99 | S7: =Tabela46[[#This Row],[GASTO MÊS]]*12 -> 300000 | T7: ='Planejamento Financeiro'!$C$42-V7 -> 25000
E8: =Tabela1[[#This Row],[Ano]]+'Planejamento Financeiro'!$M$15 -> 34 | F8: =F7+1 -> 4 | G8: =Tabela1[[#This Row],[TotalAcumulado]]-Tabela1[[#This Row],[Total Investido]] -> 568609.84 | H8: =H7+('Planejamento Financeiro'!$C$18*12) -> 1240000 | I8: =Tabela1[[#This Row],[Juros]] -> 568609.84 | J8: =-FV('Base Dash acum'!$C$3,Tabela1[[#This Row],[Ano]]*12,'Planejamento Financeiro'!$C$18,'Planejamento Financeiro'!$C$15,) -> 1808609.8 | O8: =1+O7 -> 4 | P8: =Tabela46[[#This Row],[ANO]]+'Planejamento Financeiro'!$M$18 -> 54 | Q8: =Q7+R7-S7 -> 5204542.8 | R8: ='Planejamento Financeiro'!$C$30*Tabela46[[#This Row],[PL]]+('Planejamento Financeiro'!$C$36*12) -> 365477.67 | S8: =Tabela46[[#This Row],[GASTO MÊS]]*12 -> 300000 | T8: ='Planejamento Financeiro'!$C$42-V8 -> 25000
E9: =Tabela1[[#This Row],[Ano]]+'Planejamento Financeiro'!$M$15 -> 35 | F9: =F8+1 -> 5 | G9: =Tabela1[[#This Row],[TotalAcumulado]]-Tabela1[[#This Row],[Total Investido]] -> 768689.83 | H9: =H8+('Planejamento Financeiro'!$C$18*12) -> 1300000 | I9: =Tabela1[[#This Row],[Juros]] -> 768689.83 | J9: =-FV('Base Dash acum'!$C$3,Tabela1[[#This Row],[Ano]]*12,'Planejamento Financeiro'!$C$18,'Planejamento Financeiro'!$C$15,) -> 2068689.8 | O9: =1+O8 -> 5 | P9: =Tabela46[[#This Row],[ANO]]+'Planejamento Financeiro'!$M$18 -> 55 | Q9: =Q8+R8-S8 -> 5270020.5 | R9: ='Planejamento Financeiro'!$C$30*Tabela46[[#This Row],[PL]]+('Planejamento Financeiro'!$C$36*12) -> 369005.74 | S9: =Tabela46[[#This Row],[GASTO MÊS]]*12 -> 300000 | T9: ='Planejamento Financeiro'!$C$42-V9 -> 25000
E10: =Tabela1[[#This Row],[Ano]]+'Planejamento Financeiro'!$M$15 -> 36 | F10: =F9+1 -> 6 | G10: =Tabela1[[#This Row],[TotalAcumulado]]-Tabela1[[#This Row],[Total Investido]] -> 997118.53 | H10: =H9+('Planejamento Financeiro'!$C$18*12) -> 1360000 | I10: =Tabela1[[#This Row],[Juros]] -> 997118.53 | J10: =-FV('Base Dash acum'!$C$3,Tabela1[[#This Row],[Ano]]*12,'Planejamento Financeiro'!$C$18,'Planejamento Financeiro'!$C$15,) -> 2357118.5 | O10: =1+O9 -> 6 | P10: =Tabela46[[#This Row],[ANO]]+'Planejamento Financeiro'!$M$18 -> 56 | Q10: =Q9+R9-S9 -> 5339026.2 | R10: ='Planejamento Financeiro'!$C$30*Tabela46[[#This Row],[PL]]+('Planejamento Financeiro'!$C$36*12) -> 372723.9 | S10: =Tabela46[[#This Row],[GASTO MÊS]]*12 -> 300000 | T10: ='Planejamento Financeiro'!$C$42-V10 -> 25000
E11: =Tabela1[[#This Row],[Ano]]+'Planejamento Financeiro'!$M$15 -> 37 | F11: =F10+1 -> 7 | G11: =Tabela1[[#This Row],[TotalAcumulado]]-Tabela1[[#This Row],[Total Investido]] -> 1256986 | H11: =H10+('Planejamento Financeiro'!$C$18*12) -> 1420000 | I11: =Tabela1[[#This Row],[Juros]] -> 1256986 | J11: =-FV('Base Dash acum'!$C$3,Tabela1[[#This Row],[Ano]]*12,'Planejamento Financeiro'!$C$18,'Planejamento Financeiro'!$C$15,) -> 2676986 | O11: =1+O10 -> 7 | P11: =Tabela46[[#This Row],[ANO]]+'Planejamento Financeiro'!$M$18 -> 57 | Q11: =Q10+R10-S10 -> 5411750.1 | R11: ='Planejamento Financeiro'!$C$30*Tabela46[[#This Row],[PL]]+('Planejamento Financeiro'!$C$36*12) -> 376642.41 | S11: =Tabela46[[#This Row],[GASTO MÊS]]*12 -> 300000 | T11: ='Planejamento Financeiro'!$C$42-V11 -> 25000
E12: =Tabela1[[#This Row],[Ano]]+'Planejamento Financeiro'!$M$15 -> 38 | F12: =F11+1 -> 8 | G12: =Tabela1[[#This Row],[TotalAcumulado]]-Tabela1[[#This Row],[Total Investido]] -> 1551719 | H12: =H11+('Planejamento Financeiro'!$C$18*12) -> 1480000 | I12: =Tabela1[[#This Row],[Juros]] -> 1551719 | J12: =-FV('Base Dash acum'!$C$3,Tabela1[[#This Row],[Ano]]*12,'Planejamento Financeiro'!$C$18,'Planejamento Financeiro'!$C$15,) -> 3031719 | O12: =1+O11 -> 8 | P12: =Tabela46[[#This Row],[ANO]]+'Planejamento Financeiro'!$M$18 -> 58 | Q12: =Q11+R11-S11 -> 5488392.5 | R12: ='Planejamento Financeiro'!$C$30*Tabela46[[#This Row],[PL]]+('Planejamento Financeiro'!$C$36*12) -> 380772.06 | S12: =Tabela46[[#This Row],[GASTO MÊS]]*12 -> 300000 | T12: ='Planejamento Financeiro'!$C$42-V12 -> 25000
E13: =Tabela1[[#This Row],[Ano]]+'Planejamento Financeiro'!$M$15 -> 39 | F13: =F12+1 -> 9 | G13: =Tabela1[[#This Row],[TotalAcumulado]]-Tabela1[[#This Row],[Total Investido]] -> 1885117.8 | H13: =H12+('Planejamento Financeiro'!$C$18*12) -> 1540000 | I13: =Tabela1[[#This Row],[Juros]] -> 1885117.8 | J13: =-FV('Base Dash acum'!$C$3,Tabela1[[#This Row],[Ano]]*12,'Planejamento Financeiro'!$C$18,'Planejamento Financeiro'!$C$15,) -> 3425117.8 | O13: =1+O12 -> 9 | P13: =Tabela46[[#This Row],[ANO]]+'Planejamento Financeiro'!$M$18 -> 59 | Q13: =Q12+R12-S12 -> 5569164.6 | R13: ='Planejamento Financeiro'!$C$30*Tabela46[[#This Row],[PL]]+('Planejamento Financeiro'!$C$36*12) -> 385124.21 | S13: =Tabela46[[#This Row],[GASTO MÊS]]*12 -> 300000 | T13: ='Planejamento Financeiro'!$C$42-V13 -> 25000
E14: =Tabela1[[#This Row],[Ano]]+'Planejamento Financeiro'!$M$15 -> 40 | F14: =F13+1 -> 10 | G14: =Tabela1[[#This Row],[TotalAcumulado]]-Tabela1[[#This Row],[Total Investido]] -> 2261397.2 | H14: =H13+('Planejamento Financeiro'!$C$18*12) -> 1600000 | I14: =Tabela1[[#This Row],[Juros]] -> 2261397.2 | J14: =-FV('Base Dash acum'!$C$3,Tabela1[[#This Row],[Ano]]*12,'Planejamento Financeiro'!$C$18,'Planejamento Financeiro'!$C$15,) -> 3861397.2 | O14: =1+O13 -> 10 | P14: =Tabela46[[#This Row],[ANO]]+'Planejamento Financeiro'!$M$18 -> 60 | Q14: =Q13+R13-S13 -> 5654288.8 | R14: ='Planejamento Financeiro'!$C$30*Tabela46[[#This Row],[PL]]+('Planejamento Financeiro'!$C$36*12) -> 389710.87 | S14: =Tabela46[[#This Row],[GASTO MÊS]]*12 -> 300000 | T14: ='Planejamento Financeiro'!$C$42-V14 -> 25000
E15: =Tabela1[[#This Row],[Ano]]+'Planejamento Financeiro'!$M$15 -> 41 | F15: =F14+1 -> 11 | G15: =Tabela1[[#This Row],[TotalAcumulado]]-Tabela1[[#This Row],[Total Investido]] -> 2685231 | H15: =H14+('Planejamento Financeiro'!$C$18*12) -> 1660000 | I15: =Tabela1[[#This Row],[Juros]] -> 2685231 | J15: =-FV('Base Dash acum'!$C$3,Tabela1[[#This Row],[Ano]]*12,'Planejamento Financeiro'!$C$18,'Planejamento Financeiro'!$C$15,) -> 4345231 | O15: =1+O14 -> 11 | P15: =Tabela46[[#This Row],[ANO]]+'Planejamento Financeiro'!$M$18 -> 61 | Q15: =Q14+R14-S14 -> 5743999.7 | R15: ='Planejamento Financeiro'!$C$30*Tabela46[[#This Row],[PL]]+('Planejamento Financeiro'!$C$36*12) -> 394544.67 | S15: =Tabela46[[#This Row],[GASTO MÊS]]*12 -> 300000 | T15: ='Planejamento Financeiro'!$C$42-V15 -> 25000
E16: =Tabela1[[#This Row],[Ano]]+'Planejamento Financeiro'!$M$15 -> 42 | F16: =F15+1 -> 12 | G16: =Tabela1[[#This Row],[TotalAcumulado]]-Tabela1[[#This Row],[Total Investido]] -> 3161802.7 | H16: =H15+('Planejamento Financeiro'!$C$18*12) -> 1720000 | I16: =Tabela1[[#This Row],[Juros]] -> 3161802.7 | J16: =-FV('Base Dash acum'!$C$3,Tabela1[[#This Row],[Ano]]*12,'Planejamento Financeiro'!$C$18,'Planejamento Financeiro'!$C$15,) -> 4881802.7 | O16: =1+O15 -> 12 | P16: =Tabela46[[#This Row],[ANO]]+'Planejamento Financeiro'!$M$18 -> 62 | Q16: =Q15+R15-S15 -> 5838544.3 | R16: ='Planejamento Financeiro'!$C$30*Tabela46[[#This Row],[PL]]+('Planejamento Financeiro'!$C$36*12) -> 399638.93 | S16: =Tabela46[[#This Row],[GASTO MÊS]]*12 -> 300000 | T16: ='Planejamento Financeiro'!$C$42-V16 -> 25000
... E30: =Tabela1[[#This Row],[Ano]]+'Planejamento Financeiro'!$M$15 -> 56 | F30: =F29+1 -> 26 | G30: =Tabela1[[#This Row],[TotalAcumulado]]-Tabela1[[#This Row],[Total Investido]] -> 20099255 | H30: =H29+('Planejamento Financeiro'!$C$18*12) -> 2560000 | I30: =Tabela1[[#This Row],[Juros]] -> 20099255 | J30: =-FV('Base Dash acum'!$C$3,Tabela1[[#This Row],[Ano]]*12,'Planejamento Financeiro'!$C$18,'Planejamento Financeiro'!$C$15,) -> 22659255 | O30: =1+O29 -> 26 | P30: =Tabela46[[#This Row],[ANO]]+'Planejamento Financeiro'!$M$18 -> 76 | Q30: =Q29+R29-S29 -> 7844770.7 | R30: ='Planejamento Financeiro'!$C$30*Tabela46[[#This Row],[PL]]+('Planejamento Financeiro'!$C$36*12) -> 507738.36 | S30: =Tabela46[[#This Row],[GASTO MÊS]]*12 -> 300000 | T30: ='Planejamento Financeiro'!$C$42-V30 -> 25000
O31: =1+O30 -> 27 | P31: =Tabela46[[#This Row],[ANO]]+'Planejamento Financeiro'!$M$18 -> 77 | Q31: =Q30+R30-S30 -> 8052509.1 | R31: ='Planejamento Financeiro'!$C$30*Tabela46[[#This Row],[PL]]+('Planejamento Financeiro'!$C$36*12) -> 518931.72 | S31: =Tabela46[[#This Row],[GASTO MÊS]]*12 -> 300000 | T31: ='Planejamento Financeiro'!$C$42-V31 -> 25000
O32: =1+O31 -> 28 | P32: =Tabela46[[#This Row],[ANO]]+'Planejamento Financeiro'!$M$18 -> 78 | Q32: =Q31+R31-S31 -> 8271440.8 | R32: ='Planejamento Financeiro'!$C$30*Tabela46[[#This Row],[PL]]+('Planejamento Financeiro'!$C$36*12) -> 530728.19 | S32: =Tabela46[[#This Row],[GASTO MÊS]]*12 -> 300000 | T32: ='Planejamento Financeiro'!$C$42-V32 -> 25000
O33: =1+O32 -> 29 | P33: =Tabela46[[#This Row],[ANO]]+'Planejamento Financeiro'!$M$18 -> 79 | Q33: =Q32+R32-S32 -> 8502169 | R33: ='Planejamento Financeiro'!$C$30*Tabela46[[#This Row],[PL]]+('Planejamento Financeiro'!$C$36*12) -> 543160.28 | S33: =Tabela46[[#This Row],[GASTO MÊS]]*12 -> 300000 | T33: ='Planejamento Financeiro'!$C$42-V33 -> 25000
O34: =1+O33 -> 30 | P34: =Tabela46[[#This Row],[ANO]]+'Planejamento Financeiro'!$M$18 -> 80 | Q34: =Q33+R33-S33 -> 8745329.3 | R34: ='Planejamento Financeiro'!$C$30*Tabela46[[#This Row],[PL]]+('Planejamento Financeiro'!$C$36*12) -> 556262.23 | S34: =Tabela46[[#This Row],[GASTO MÊS]]*12 -> 300000 | T34: ='Planejamento Financeiro'!$C$42-V34 -> 25000
O35: =1+O34 -> 31 | P35: =Tabela46[[#This Row],[ANO]]+'Planejamento Financeiro'!$M$18 -> 81 | Q35: =Q34+R34-S34 -> 9001591.5 | R35: ='Planejamento Financeiro'!$C$30*Tabela46[[#This Row],[PL]]+('Planejamento Financeiro'!$C$36*12) -> 570070.15 | S35: =Tabela46[[#This Row],[GASTO MÊS]]*12 -> 300000 | T35: ='Planejamento Financeiro'!$C$42-V35 -> 25000
O36: =1+O35 -> 32 | P36: =Tabela46[[#This Row],[ANO]]+'Planejamento Financeiro'!$M$18 -> 82 | Q36: =Q35+R35-S35 -> 9271661.6 | R36: ='Planejamento Financeiro'!$C$30*Tabela46[[#This Row],[PL]]+('Planejamento Financeiro'!$C$36*12) -> 584622.06 | S36: =Tabela46[[#This Row],[GASTO MÊS]]*12 -> 300000 | T36: ='Planejamento Financeiro'!$C$42-V36 -> 25000
O37: =1+O36 -> 33 | P37: =Tabela46[[#This Row],[ANO]]+'Planejamento Financeiro'!$M$18 -> 83 | Q37: =Q36+R36-S36 -> 9556283.7 | R37: ='Planejamento Financeiro'!$C$30*Tabela46[[#This Row],[PL]]+('Planejamento Financeiro'!$C$36*12) -> 599958.06 | S37: =Tabela46[[#This Row],[GASTO MÊS]]*12 -> 300000 | T37: ='Planejamento Financeiro'!$C$42-V37 -> 25000
O38: =1+O37 -> 34 | P38: =Tabela46[[#This Row],[ANO]]+'Planejamento Financeiro'!$M$18 -> 84 | Q38: =Q37+R37-S37 -> 9856241.8 | R38: ='Planejamento Financeiro'!$C$30*Tabela46[[#This Row],[PL]]+('Planejamento Financeiro'!$C$36*12) -> 616120.39 | S38: =Tabela46[[#This Row],[GASTO MÊS]]*12 -> 300000 | T38: ='Planejamento Financeiro'!$C$42-V38 -> 25000
O39: =1+O38 -> 35 | P39: =Tabela46[[#This Row],[ANO]]+'Planejamento Financeiro'!$M$18 -> 85 | Q39: =Q38+R38-S38 -> 10172362 | R39: ='Planejamento Financeiro'!$C$30*Tabela46[[#This Row],[PL]]+('Planejamento Financeiro'!$C$36*12) -> 633153.58 | S39: =Tabela46[[#This Row],[GASTO MÊS]]*12 -> 300000 | T39: ='Planejamento Financeiro'!$C$42-V39 -> 25000
O40: =1+O39 -> 36 | P40: =Tabela46[[#This Row],[ANO]]+'Planejamento Financeiro'!$M$18 -> 86 | Q40: =Q39+R39-S39 -> 10505516 | R40: ='Planejamento Financeiro'!$C$30*Tabela46[[#This Row],[PL]]+('Planejamento Financeiro'!$C$36*12) -> 651104.55 | S40: =Tabela46[[#This Row],[GASTO MÊS]]*12 -> 300000 | T40: ='Planejamento Financeiro'!$C$42-V40 -> 25000
O41: =1+O40 -> 37 | P41: =Tabela46[[#This Row],[ANO]]+'Planejamento Financeiro'!$M$18 -> 87 | Q41: =Q40+R40-S40 -> 10856620 | R41: ='Planejamento Financeiro'!$C$30*Tabela46[[#This Row],[PL]]+('Planejamento Financeiro'!$C$36*12) -> 670022.76 | S41: =Tabela46[[#This Row],[GASTO MÊS]]*12 -> 300000 | T41: ='Planejamento Financeiro'!$C$42-V41 -> 25000
O42: =1+O41 -> 38 | P42: =Tabela46[[#This Row],[ANO]]+'Planejamento Financeiro'!$M$18 -> 88 | Q42: =Q41+R41-S41 -> 11226643 | R42: ='Planejamento Financeiro'!$C$30*Tabela46[[#This Row],[PL]]+('Planejamento Financeiro'!$C$36*12) -> 689960.31 | S42: =Tabela46[[#This Row],[GASTO MÊS]]*12 -> 300000 | T42: ='Planejamento Financeiro'!$C$42-V42 -> 25000
... O54: =1+O53 -> 50 | P54: =Tabela46[[#This Row],[ANO]]+'Planejamento Financeiro'!$M$18 -> 100 | Q54: =Q53+R53-S53 -> 17574994 | R54: ='Planejamento Financeiro'!$C$30*Tabela46[[#This Row],[PL]]+('Planejamento Financeiro'!$C$36*12) -> 1032022 | S54: =Tabela46[[#This Row],[GASTO MÊS]]*12 -> 300000 | T54: ='Planejamento Financeiro'!$C$42-V54 -> 25000

Sheet BaseDadosDosClientes
A1: Nome Completo: | B1: E-mail: | C1: Data de Nascimento: | D1: Tipo | E1: ACRÔNIMO | F1: TITULAR
A2: ALEX CASTILHO ARAUJO | B2: ALEXCASTILHOO@GMAIL.COM | C2: 32929 | D2: TITULAR | E2: ACA | F2: ALEX CASTILHO ARAUJO
A3: ALEXANDRA CAVALCANTI DE FREITAS | B3: ALEXANDRAFREITAS@LIVE.COM | C3: 25932 | D3: TITULAR | E3: ACF | F3: ALEXANDRA CAVALCANTI DE FREITAS
A4: ANDRE LUIZ CORREIA RAMOS | B4: ANDRELCRAMOSCG@GMAIL.COM | C4: 28998 | D4: TITULAR | E4: ACR | F4: ANDRE LUIZ CORREIA RAMOS
A5: THACIRA DANTAS ALMEIDA RAMOS | B5: THACIRADANTAS@GMAIL.COM | C5: 30132 | D5: DEPENDENTE | E5: ACR | F5: ANDRE LUIZ CORREIA RAMOS
A6: CENTRO DE ENDOCRINOLOGIA E METABOLOGIA LTDA | D6: DEPENDENTE | E6: ACR_CEM | F6: ANDRE LUIZ CORREIA RAMOS
A7: ANDREIA NONATO ALBUQUERQUE ESCARIÃO | B7: ANDREIANCA@HOTMAIL.COM | C7: 27977 | D7: DEPENDENTE | E7: AEN | F7: ANDREIA NONATO ALBUQUERQUE ESCARIÃO
A8: ALVARO GONCALVES DA COSTA LIMA | B8: ALVAROGCL@YAHOO.COM.BR | C8: 31513 | D8: TITULAR | E8: AGCL | F8: ALVARO GONCALVES DA COSTA LIMA
A9: LIDIA CARDOSO DE SIQUEIRA | B9: LIDIA_CS@HOTMAIL.COM | C9: 31559 | D9: DEPENDENTE | E9: AGCL_LSG | F9: ALVARO GONCALVES DA COSTA LIMA
A10: ALEXANDRE LOBACK BESERRA | B10: ALEX.LOBACK@HOTMAIL.COM | C10: 24473 | D10: TITULAR | E10: AL | F10: ALEXANDRE LOBACK BESERRA
A11: ALINE LEMGRUBER PRADO COSTA | B11: ALINELEMGRUBER@YAHOO.COM.BR | C11: 28122 | D11: TITULAR | E11: ALPC | F11: ALINE LEMGRUBER PRADO COSTA
A12: FELIPPE JOSE CORRA DE FREITAS | B12: FELIPPEFREITAS@ME.COM | C12: 27038 | D12: DEPENDENTE | E12: ALPC_FCF | F12: ALINE LEMGRUBER PRADO COSTA
A13: ABELARDO GONÇALVES ESCARIÃO | B13: ESCARIAO@HOTMAIL.COM | C13: 26687 | D13: TITULAR | E13: ANE | F13: ANDREIA NONATO ALBUQUERQUE ESCARIÃO
A14: ANDREIA NONATO ALBUQUERQUE ESCARIÃO | D14: TITULAR | E14: ANE | F14: ANDREIA NONATO ALBUQUERQUE ESCARIÃO
A15: BRUNO FREITAS LEAL | B15: FREITAS_BRUNO@YAHOO.COM.BR | C15: 32906 | D15: TITULAR | E15: BFL | F15: BRUNO FREITAS LEAL
A16: LUIZA SILVA DE MELO | B16: CARLOS@EROSHOTEL.COM.BR | C16: 15255 | D16: DEPENDENTE | E16: CESM | F16: CARLOS EDUARDO SILVA DE MELO
A17: CARLOS EDUARDO SILVA DE MELO | B17: CARLOS@EROSHOTEL.COM.BR | C17: 26073 | D17: TITULAR | E17: CESM | F17: CARLOS EDUARDO SILVA DE MELO
A18: MARIA BETANIA TIBURCIO CAVALCANTI | B18: CARLOS@EROSHOTEL.COM.BR | C18: 28810 | D18: DEPENDENTE | E18: CESM | F18: CARLOS EDUARDO SILVA DE MELO
A19: MELO EMPREENDIMENTOS E PARTICIPACOES IMOBILIARIAS LTDA | B19: CARLOS@EROSHOTEL.COM.BR | D19: DEPENDENTE | E19: CESM | F19: CARLOS EDUARDO SILVA DE MELO
A20: PROGRESSO EMPREENDIMENTOS LTDA | B20: CARLOS@EROSHOTEL.COM.BR | D20: DEPENDENTE | E20: CESM | F20: CARLOS EDUARDO SILVA DE MELO
A21: POUSADA | E21: CESM | F21: CARLOS EDUARDO SILVA DE MELO
A22: VRM | E22: CESM | F22: CARLOS EDUARDO SILVA DE MELO
A23: IPUTINGA | E23: CESM | F23: CARLOS EDUARDO SILVA DE MELO
A24: LUIS EDUARDO TIBURCIO DE MELO | E24: CESM | F24: CARLOS EDUARDO SILVA DE MELO
A25: CAMILA RIBEIRO WANDERLEY | B25: CAMILA@PERNAMBUCOCONSTRUTORA.COM.BR | D25: TITULAR | E25: CRW | F25: CAMILA RIBEIRO WANDERLEY
A26: DIOGO CASTRO PAIVA | B26: DIOGOCASTROPAIVA@GMAIL.COM | D26: TITULAR | E26: DCP | F26: DIOGO CASTRO PAIVA
A27: RODRIGO PETRIBU DA COSTA AZEVEDO | B27: RODRIGOPETRIBU@HOTMAIL.COM | C27: 30464 | D27: DEPENDENTE | E27: DFCA | F27: DOMINGOS FERREIRA DA COSTA AZEVEDO
A28: DOMINGOS FERREIRA DA COSTA AZEVEDO | B28: RODRIGOPETRIBU@HOTMAIL.COM | D28: TITULAR | E28: DFCA | F28: DOMINGOS FERREIRA DA COSTA AZEVEDO
A29: AIDA HELENA DE MORAIS | D29: DEPENDENTE | E29: DRLC | F29: LUIZ CARLOS VASCONCELLOS DE MORAES
A30: ALEXANDRE GARBELINI VASCONCELLOS DE MORAES | D30: DEPENDENTE | E30: DRLC | F30: LUIZ CARLOS VASCONCELLOS DE MORAES
A31: ARIEL GARBELINI VASCONCELLOS DE MORAES | D31: DEPENDENTE | E31: DRLC | F31: LUIZ CARLOS VASCONCELLOS DE MORAES
A32: EDE RODRIGUES ANCELMO | D32: DEPENDENTE | E32: DRLC | F32: LUIZ CARLOS VASCONCELLOS DE MORAES
A33: GUSTAVO MAURILIO DO NASCIMENTO | D33: DEPENDENTE | E33: DRLC | F33: LUIZ CARLOS VASCONCELLOS DE MORAES
A34: JOAO PAULO VASCONCELOS DE MORAES | D34: DEPENDENTE | E34: DRLC | F34: LUIZ CARLOS VASCONCELLOS DE MORAES
A35: LUIZ CARLOS VASCONCELLOS DE MORAES | B35: LUCAVASCO@GMAIL.COM | D35: TITULAR | E35: DRLC | F35: LUIZ CARLOS VASCONCELLOS DE MORAES
A36: SANDRA MARA GARBELINI | D36: DEPENDENTE | E36: DRLC | F36: LUIZ CARLOS VASCONCELLOS DE MORAES
A37: DURVAL SELVA VALENCA | B37: DURVALVALENCA@IOR.COM.BR | C37: 14479 | D37: TITULAR | E37: DSV | F37: DURVAL SELVA VALENCA
A38: MARCOS DE OLIVEIRA GUSMAO | B38: MOGUSMAO68@GMAIL.COM | C38: 24972 | D38: DEPENDENTE | E38: DSV_MOG | F38: DURVAL SELVA VALENCA
A39: DIOGO WANDERLEY CORREIA COSTA | B39: DIOGOWA@GMAIL.COM | C39: 30393 | D39: TITULAR | E39: DWC | F39: DIOGO WANDERLEY CORREIA COSTA
A40: EMMANUEL BENEDITO NEVES ANDRADE FILHO | B40: AEFILHOBIG@GMAIL.COM | C40: 25061 | D40: TITULAR | E40: EAF | F40: Emmanuel benedito Neves Andrade Filho
...

Sheet Perfil de Risco
A1: Cola Asset Allocation (NÃO MEXA) | B1: 2 | C1: 3
A2: 0.015 | B2: Conservador | C2: 0.0675
A3: 0.03 | B3: Moderado | C3: 0.0825
A4: 0.05 | B4: Arrojado | C4: 0.1025
A5: 0.08 | B5: Agressivo | C5: 0.1325
